Workbook

Sheet Summary
A1: LME_052 — Sea of Okhotsk
A2: Ecopath model: 52_1_Sea_of_Okhotsk_NE_(1980)
A3: NE means new detailed Ecopath model, not northeastern. Whole Okhotsk Sea coverage; numerical configuration caveats remain. 52_1_Sea_of_Okhotsk_NE_(1980)
A5: region type | B5: LME
A6: latitude | B6: 55.9495
A7: longitude | B7: 149.68977
A8: catch years | B8: 1950-2019
A9: taxa in catch | B9: 151
A10: taxa apportioned across groups | B10: 11
A11: taxa unresolved | B11: 54
A12: catch tonnage on a named group, % | B12: 97.3
A13: SPPR methods | B13: 20
A14: methods flagged as unusable | B14: 7
A15: headline method below | B15: Ulanowicz_TE
A17: year | B17: catch_tonnes | C17: ppr_simple | D17: ppr_Ulanowicz_TE | E17: ppr_simple / NPP % | F17: ppr_Ulanowicz_TE / NPP %
A18: 1950 | B18: 737435.34 | C18: 5.3844723e+08 | D18: 6.450285e+08
A19: 1951 | B19: 893045.88 | C19: 8.2486898e+08 | D19: 7.0899973e+08
A20: 1952 | B20: 827838.83 | C20: 6.486404e+08 | D20: 6.8473353e+08
A21: 1953 | B21: 907159.02 | C21: 8.5493846e+08 | D21: 7.348127e+08
A22: 1954 | B22: 898364.68 | C22: 7.2652593e+08 | D22: 8.8945751e+08
A23: 1955 | B23: 1062537.4 | C23: 8.8697267e+08 | D23: 1.0210798e+09
A24: 1956 | B24: 1145961.5 | C24: 9.0960922e+08 | D24: 1.107504e+09
A25: 1957 | B25: 1333954.1 | C25: 1.0340751e+09 | D25: 1.191874e+09
A26: 1958 | B26: 1068756.5 | C26: 4.9879411e+08 | D26: 9.3476713e+08
A27: 1959 | B27: 1012507.7 | C27: 5.4931683e+08 | D27: 9.484696e+08
A28: 1960 | B28: 887212.23 | C28: 4.6600869e+08 | D28: 1.0139656e+09
A29: 1961 | B29: 1004505.4 | C29: 5.1706994e+08 | D29: 1.1715037e+09
... A65: 1997 | B65: 6673942.7 | C65: 3.3865026e+09 | D65: 6.2104862e+09
A66: 1998 | B66: 5959517 | C66: 3.0258874e+09 | D66: 5.6551516e+09 | E66: 101.5284 | F66: 189.7488
A67: 1999 | B67: 5321931.6 | C67: 2.8691295e+09 | D67: 5.1081115e+09 | E67: 101.023 | F67: 179.8584
A68: 2000 | B68: 4591441.1 | C68: 2.5058168e+09 | D68: 4.3557532e+09 | E68: 93.6038 | F68: 162.7075
A69: 2001 | B69: 4591638 | C69: 2.545972e+09 | D69: 4.4250771e+09
A70: 2002 | B70: 3211633.1 | C70: 1.9159734e+09 | D70: 3.0504588e+09
A71: 2003 | B71: 4030219.5 | C71: 2.3074682e+09 | D71: 3.9712853e+09
A72: 2004 | B72: 3258717.7 | C72: 1.8784148e+09 | D72: 3.3693665e+09
A73: 2005 | B73: 3579903.5 | C73: 2.2340697e+09 | D73: 3.5526824e+09
A74: 2006 | B74: 3656771.5 | C74: 2.2156421e+09 | D74: 3.537082e+09
A75: 2007 | B75: 4021913.8 | C75: 2.5135903e+09 | D75: 3.9014498e+09
A76: 2008 | B76: 3614587.8 | C76: 2.1967392e+09 | D76: 3.7816027e+09
A77: 2009 | B77: 3878004.3 | C77: 2.6889613e+09 | D77: 3.957661e+09
...

Sheet Catch
A1: taxon | B1: common_name | C1: functional_group | D1: commercial_group | E1: 1950 | F1: 1951 | G1: 1952 | H1: 1953 | I1: 1954 | J1: 1955 | K1: 1956 | L1: 1957 | M1: 1958 | N1: 1959 | O1: 1960 | P1: 1961 | Q1: 1962 | R1: 1963 | S1: 1964 | T1: 1965 | U1: 1966 | V1: 1967 | W1: 1968 | X1: 1969 | Y1: 1970 | Z1: 1971 | AA1: 1972 | AB1: 1973 | AC1: 1974 | AD1: 1975 | AE1: 1976 | AF1: 1977 | AG1: 1978 | AH1: 1979 | AI1: 1980 | AJ1: 1981 | AK1: 1982 | AL1: 1983 | AM1: 1984 | AN1: 1985 | AO1: 1986 | AP1: 1987 | AQ1: 1988 | AR1: 1989 | AS1: 1990 | AT1: 1991 | AU1: 1992 | AV1: 1993 | AW1: 1994 | AX1: 1995 | AY1: 1996 | AZ1: 1997 | BA1: 1998 | BB1: 1999 | BC1: 2000 | BD1: 2001 | BE1: 2002 | BF1: 2003 | BG1: 2004 | BH1: 2005 | BI1: 2006 | BJ1: 2007 | BK1: 2008 | BL1: 2009 | BM1: 2010 | BN1: 2011 | BO1: 2012 | BP1: 2013 | BQ1: 2014 | BR1: 2015 | BS1: 2016 | BT1: 2017 | BU1: 2018 | BV1: 2019
A2: Gadus chalcogrammus | B2: Alaska pollock | C2: Medium benthopelagics (30 - 89 cm) | D2: Cod-likes | E2: 95540.788 | F2: 102736.18 | G2: 98903.064 | H2: 99940.529 | I2: 107642.51 | J2: 125501.41 | K2: 144032.52 | L2: 186429.25 | M2: 215265.36 | N2: 229306.27 | O2: 236592.48 | P2: 243098.1 | Q2: 248199.63 | R2: 310040.64 | S2: 320803.28 | T2: 491795.65 | U2: 566878.5 | V2: 662671.66 | W2: 742626.16 | X2: 742954.84 | Y2: 819692 | Z2: 927292.32 | AA2: 882925.44 | AB2: 1387248.5 | AC2: 1474364 | AD2: 1797101.6 | AE2: 1935164.6 | AF2: 1875807.9 | AG2: 1829507.3 | AH2: 1875198.9 | AI2: 1980623.1 | AJ2: 2116768.5 | AK2: 2472298.6 | AL2: 2707742.1 | AM2: 3751466.8 | AN2: 3800889.2 | AO2: 4263695.3 | AP2: 4129739.7 | AQ2: 4152144.2 | AR2: 4684061.6 | AS2: 5277999.9 | AT2: 5097352.8 | AU2: 4846213.3 | AV2: 4097886.2 | AW2: 3484873.1 | AX2: 4381389.3 | AY2: 5302416.1 | AZ2: 4965960.3 | BA2: 4139102.4 | BB2: 3445890.5 | BC2: 2711504.2 | BD2: 2866506.8 | BE2: 1747817.2 | BF2: 2424552.7 | BG2: 1740172.5 | BH2: 1935022.3 | BI2: 2033163.9 | BJ2: 2366424.2 | BK2: 2006253 | BL2: 1988528.9 | BM2: 2327082.3 | BN2: 2396978.7 | BO2: 2418693.7 | BP2: 2310661.4 | BQ2: 2262175.5 | BR2: 2396713.1 | BS2: 2540880.6 | BT2: 2555501.8 | BU2: 2592762.7 | BV2: 2636838.8
A3: Clupea pallasii | B3: Pacific herring | C3: Medium pelagics (30 - 89 cm) | D3: Herring-likes | E3: 131876.38 | F3: 152197.14 | G3: 155153.94 | H3: 140441.2 | I3: 108994.8 | J3: 125373.86 | K3: 139456.11 | L3: 264198.09 | M3: 294103.7 | N3: 202956.94 | O3: 138713.23 | P3: 186784.82 | Q3: 144019.96 | R3: 240507.28 | S3: 297692.17 | T3: 285615.39 | U3: 289777.47 | V3: 311187.59 | W3: 370515.56 | X3: 358806.58 | Y3: 281387.98 | Z3: 247950.48 | AA3: 244556.65 | AB3: 303656.7 | AC3: 273612.16 | AD3: 300616.41 | AE3: 197585.66 | AF3: 240336.07 | AG3: 72655.393 | AH3: 86524.57 | AI3: 97640.275 | AJ3: 105735.23 | AK3: 117550.58 | AL3: 160351.02 | AM3: 187759.45 | AN3: 227493.73 | AO3: 224291.41 | AP3: 267241.04 | AQ3: 238671.35 | AR3: 163505.5 | AS3: 173784.56 | AT3: 182635.22 | AU3: 190685.11 | AV3: 188982.12 | AW3: 144289.94 | AX3: 193467.9 | AY3: 284833.24 | AZ3: 459724.95 | BA3: 554402.1 | BB3: 500867.53 | BC3: 493814.11 | BD3: 394700.92 | BE3: 285854.43 | BF3: 279218.28 | BG3: 273618.11 | BH3: 276397.74 | BI3: 299068.05 | BJ3: 237348.36 | BK3: 245162.34 | BL3: 283681.68 | BM3: 342749 | BN3: 385202.65 | BO3: 439273.53 | BP3: 462396.62 | BQ3: 448038.39 | BR3: 455349.27 | BS3: 472266.2 | BT3: 486162.7 | BU3: 468891.2 | BV3: 473415.59
A4: Marine fishes not identified | B4: Marine fishes nei | C4: Medium demersals (30 - 89 cm) | D4: Other fishes & inverts | E4: 89617.251 | F4: 96136.886 | G4: 98035.888 | H4: 110523.37 | I4: 131572.26 | J4: 150243.33 | K4: 161615.74 | L4: 159031.91 | M4: 97974.501 | N4: 88449.959 | O4: 81176.831 | P4: 91426.649 | Q4: 86844.237 | R4: 119496.49 | S4: 93201.484 | T4: 120892.88 | U4: 80582.825 | V4: 88347.558 | W4: 80485.794 | X4: 102870.54 | Y4: 92185.025 | Z4: 129150.1 | AA4: 106651.57 | AB4: 130269.31 | AC4: 128075.05 | AD4: 126405.65 | AE4: 153136.16 | AF4: 150304.54 | AG4: 100865.51 | AH4: 141341.94 | AI4: 131952.86 | AJ4: 223345.09 | AK4: 224215.64 | AL4: 226670.39 | AM4: 282705.93 | AN4: 304639.97 | AO4: 356533.03 | AP4: 319968.05 | AQ4: 332529.25 | AR4: 242372.34 | AS4: 298963.12 | AT4: 168860.56 | AU4: 305302.24 | AV4: 220879.79 | AW4: 145953.94 | AX4: 160385.19 | AY4: 168665.54 | AZ4: 169716.52 | BA4: 180937.95 | BB4: 185908.67 | BC4: 232702.89 | BD4: 236362.53 | BE4: 161788.91 | BF4: 260772.98 | BG4: 266787.95 | BH4: 278362.34 | BI4: 251538.13 | BJ4: 255510.37 | BK4: 267033.94 | BL4: 305514.43 | BM4: 326471.98 | BN4: 338597.78 | BO4: 347432.59 | BP4: 325439.21 | BQ4: 451820.36 | BR4: 335040.21 | BS4: 390215.87 | BT4: 388214.29 | BU4: 390901.4 | BV4: 375147.65
A5: Oncorhynchus gorbuscha | B5: Pink salmon | C5: Medium demersals (30 - 89 cm) | D5: Salmon, smelts, etc | E5: 72492.227 | F5: 154210.02 | G5: 98691.166 | H5: 158736.66 | I5: 104337.33 | J5: 139140.51 | K5: 134833.14 | L5: 163908 | M5: 31812.707 | N5: 42078.458 | O5: 17892.484 | P5: 24706.424 | Q5: 14792.359 | R5: 36143.732 | S5: 12621.567 | T5: 34771.697 | U5: 16748.572 | V5: 36696.52 | W5: 13569.356 | X5: 46036.968 | Y5: 15430.392 | Z5: 44525.376 | AA5: 17721.533 | AB5: 46973.787 | AC5: 25035.536 | AD5: 62410.889 | AE5: 39413.932 | AF5: 75024.061 | AG5: 39312.366 | AH5: 70019.047 | AI5: 64291.065 | AJ5: 72191.122 | AK5: 52109.261 | AL5: 95978.993 | AM5: 71834.839 | AN5: 102658.56 | AO5: 73758.786 | AP5: 119274.61 | AQ5: 80499.112 | AR5: 169417.67 | AS5: 131881.04 | AT5: 235408.25 | AU5: 139033.77 | AV5: 216872.79 | AW5: 220300.45 | AX5: 263075.67 | AY5: 221564.7 | AZ5: 290079.5 | BA5: 268021.94 | BB5: 287448.7 | BC5: 256812.38 | BD5: 273387 | BE5: 218780.68 | BF5: 258578.43 | BG5: 204110.92 | BH5: 289268.42 | BI5: 271798.04 | BJ5: 317874.02 | BK5: 253875.44 | BL5: 399207.6 | BM5: 288082.12 | BN5: 490084.93 | BO5: 398079.94 | BP5: 371946.61 | BQ5: 277629.28 | BR5: 282087.54 | BS5: 332671.45 | BT5: 279452.44 | BU5: 458957.66 | BV5: 332892.38
A6: Sardinops sagax | B6: South American pilchard | C6: Medium pelagics (30 - 89 cm) | D6: Herring-likes | E6: 7749.186 | F6: 7749.186 | G6: 7749.186 | H6: 10689.726 | I6: 7608.605 | J6: 6527.879 | K6: 6375.646 | L6: 6545.857 | M6: 4189.261 | N6: 3641.546 | O6: 2357.248 | P6: 3866.905 | Q6: 3296.059 | R6: 1649.887 | S6: 443.607 | T6: 211.304 | U6: 361.51 | V6: 465.842 | W6: 691.048 | X6: 597.227 | Y6: 462.982 | Z6: 1689.838 | AA6: 1713.938 | AB6: 8988.539 | AC6: 10593.383 | AD6: 15874.648 | AE6: 32142.549 | AF6: 42874.223 | AG6: 151508 | AH6: 210081.11 | AI6: 220096.82 | AJ6: 293213.86 | AK6: 360974.31 | AL6: 371855.88 | AM6: 487664.17 | AN6: 460654.16 | AO6: 509016.27 | AP6: 492621.96 | AQ6: 515175.45 | AR6: 541802.39 | AS6: 544391.22 | AT6: 430599.22 | AU6: 151415.52 | AV6: 55686.767 | AW6: 38199.969 | AX6: 21924.995 | AY6: 16373.96 | AZ6: 10704.199 | BA6: 6689.694 | BB6: 13607.059 | BC6: 7555.156 | BD6: 7874.29 | BE6: 4315.97 | BF6: 3640.152 | BG6: 4232.418 | BH6: 3728.897 | BI6: 4957.039 | BJ6: 5520.264 | BK6: 4116.045 | BL6: 3967.253 | BM6: 4360.83 | BN6: 8014.15 | BO6: 6528.759 | BP6: 8494.8 | BQ6: 8422.153 | BR6: 11371.39 | BS6: 16527.349 | BT6: 23529.922 | BU6: 41385.312 | BV6: 81121.585
A7: Gadus macrocephalus | B7: Pacific cod | C7: Large demersals (>=90 cm) | D7: Cod-likes | E7: 13175.96 | F7: 15274.842 | G7: 11998.432 | H7: 10838.032 | I7: 15046.711 | J7: 15430.179 | K7: 19461.699 | L7: 23323.235 | M7: 20914.421 | N7: 25834.415 | O7: 41770.5 | P7: 52934.339 | Q7: 43322.908 | R7: 29888.528 | S7: 34981.323 | T7: 30923.832 | U7: 28923.127 | V7: 31704.327 | W7: 36780.474 | X7: 46763.86 | Y7: 37870.421 | Z7: 44905.879 | AA7: 35512.27 | AB7: 44412.553 | AC7: 39900.522 | AD7: 46324.744 | AE7: 34174.555 | AF7: 40135.145 | AG7: 39238.357 | AH7: 39453.82 | AI7: 49601.46 | AJ7: 63464.642 | AK7: 90440.826 | AL7: 100010.24 | AM7: 140906.35 | AN7: 184745.63 | AO7: 173641.12 | AP7: 179749.64 | AQ7: 154572.22 | AR7: 155199.31 | AS7: 146968.54 | AT7: 130654.15 | AU7: 168588.46 | AV7: 120472.71 | AW7: 101121.12 | AX7: 123352.37 | AY7: 125380.81 | AZ7: 111125.09 | BA7: 115844.33 | BB7: 116684.99 | BC7: 84547.012 | BD7: 79117.298 | BE7: 68526.864 | BF7: 65880.17 | BG7: 69508.592 | BH7: 66116.474 | BI7: 61683.726 | BJ7: 67950.822 | BK7: 91591.616 | BL7: 81219.351 | BM7: 109865.04 | BN7: 74110.304 | BO7: 78626.547 | BP7: 79542.699 | BQ7: 77291.252 | BR7: 80347.047 | BS7: 86852.089 | BT7: 94817.969 | BU7: 111365.19 | BV7: 128809.93
A8: Oncorhynchus | B8: Salmons, trouts | C8: Large benthopelagics (>=90 cm) | D8: Salmon, smelts, etc | E8: 89427.704 | F8: 99907.868 | G8: 110388.03 | H8: 119926.34 | I8: 132880.94 | J8: 149948.8 | K8: 159992.56 | L8: 160606.47 | M8: 23565.273 | N8: 22402.247 | O8: 20719.413 | P8: 19987.214 | Q8: 18014.191 | R8: 18786.986 | S8: 16002.944 | T8: 17743.053 | U8: 16355.897 | V8: 17578.055 | W8: 15125.953 | X8: 18562.318 | Y8: 17878.626 | Z8: 19599.049 | AA8: 18397.087 | AB8: 19780.165 | AC8: 19605.002 | AD8: 22486.336 | AE8: 20293.955 | AF8: 20548.387 | AG8: 18702.118 | AH8: 22424.281 | AI8: 23400.203 | AJ8: 25557.472 | AK8: 23190.221 | AL8: 28778.119 | AM8: 27206.221 | AN8: 32699.026 | AO8: 28322.979 | AP8: 32769.45 | AQ8: 24140.399 | AR8: 39181.201 | AS8: 38758.422 | AT8: 68554.79 | AU8: 41775.209 | AV8: 57366.651 | AW8: 61739.211 | AX8: 71342.209 | AY8: 64492.781 | AZ8: 79038.591 | BA8: 74103.033 | BB8: 74954.151 | BC8: 68430.848 | BD8: 75976.774 | BE8: 64622.166 | BF8: 81767.686 | BG8: 65858.488 | BH8: 87369.261 | BI8: 91305.081 | BJ8: 103919.08 | BK8: 86574.501 | BL8: 138828.95 | BM8: 101809.58 | BN8: 35948.525 | BO8: 35200.703 | BP8: 37104.802 | BQ8: 36538.516 | BR8: 35868.014 | BS8: 24539.306 | BT8: 25528.414 | BU8: 27279.916 | BV8: 27045.261
A9: Oncorhynchus keta | B9: Chum salmon | C9: Large benthopelagics (>=90 cm) | D9: Salmon, smelts, etc | E9: 36699.518 | F9: 49719.433 | G9: 26414.38 | H9: 20350.31 | I9: 32035.315 | J9: 40762.784 | K9: 48244.901 | L9: 22830.438 | M9: 18440.105 | N9: 27591.785 | O9: 27529.949 | P9: 23943.48 | Q9: 21408.217 | R9: 26911.592 | S9: 16523.199 | T9: 20418.846 | U9: 18872.954 | V9: 15781.171 | W9: 10154.124 | X9: 5330.941 | Y9: 9164.753 | Z9: 7928.039 | AA9: 4712.584 | AB9: 3599.542 | AC9: 5825.626 | AD9: 4892.526 | AE9: 6329.587 | AF9: 9212.985 | AG9: 10444.133 | AH9: 14477.056 | AI9: 10009.805 | AJ9: 9858.893 | AK9: 9429.933 | AL9: 15404.381 | AM9: 10389.057 | AN9: 18167.067 | AO9: 19637.872 | AP9: 17437.648 | AQ9: 24812.165 | AR9: 23287.499 | AS9: 35602.393 | AT9: 27246.019 | AU9: 33789.34 | AV9: 44857.019 | AW9: 54799.485 | AX9: 58240.115 | AY9: 51580.481 | AZ9: 44765.727 | BA9: 49769.895 | BB9: 48649.478 | BC9: 55358.633 | BD9: 51475.21 | BE9: 58259.37 | BF9: 50717.543 | BG9: 48498.95 | BH9: 51211.197 | BI9: 65666.334 | BJ9: 70970.427 | BK9: 82072.517 | BL9: 113737.09 | BM9: 107979.9 | BN9: 109297.89 | BO9: 135033.32 | BP9: 143573.54 | BQ9: 187513.77 | BR9: 173656.4 | BS9: 137568.04 | BT9: 142339.43 | BU9: 144358.31 | BV9: 143367.68
A10: Pleuronectiformes | B10: Flatfishes | C10: Small to medium flatfishes (<90 cm) | D10: Flatfishes | E10: 17091.826 | F10: 18032.144 | G10: 20979.857 | H10: 27983.752 | I10: 36731.689 | J10: 61009.692 | K10: 66877.411 | L10: 63658.428 | M10: 89936.871 | N10: 77452.243 | O10: 26503.147 | P10: 20379.134 | Q10: 7974.368 | R10: 18655.329 | S10: 9023.133 | T10: 25827.339 | U10: 17149.845 | V10: 638.323 | W10: 7325.015 | X10: 744.099 | Y10: 721.476 | Z10: 23897.261 | AA10: 23229.862 | AB10: 25245.247 | AC10: 3938.526 | AD10: 4958.883 | AE10: 5639.354 | AF10: 18055.041 | AG10: 37198.656 | AH10: 20463.209 | AI10: 24278.01 | AJ10: 25131.635 | AK10: 25985.954 | AL10: 29022.902 | AM10: 33065.6 | AN10: 55700.222 | AO10: 56986.831 | AP10: 55217.151 | AQ10: 60031.683 | AR10: 55539.601 | AS10: 52656.422 | AT10: 62425.975 | AU10: 56003.952 | AV10: 43043.022 | AW10: 25974.59 | AX10: 31888.791 | AY10: 39015.502 | AZ10: 42784.56 | BA10: 52372.013 | BB10: 62724.033 | BC10: 66007.987 | BD10: 61103.868 | BE10: 50972.219 | BF10: 52569.344 | BG10: 43295.197 | BH10: 55559.011 | BI10: 43182.197 | BJ10: 46305.819 | BK10: 39812.369 | BL10: 54809.059 | BM10: 47705.157 | BN10: 25018.187 | BO10: 47299.714 | BP10: 41216.13 | BQ10: 49218.213 | BR10: 50663.101 | BS10: 51879.17 | BT10: 50753.098 | BU10: 51044.276 | BV10: 52221.897
A11: Paralithodes camtschaticus | B11: Red king crab | C11: Lobsters, crabs | D11: Crustaceans | E11: 26842.523 | F11: 40989.491 | G11: 41593.694 | H11: 34538.171 | I11: 44053.879 | J11: 53375.559 | K11: 65761.769 | L11: 61414.715 | M11: 60223.209 | N11: 60281.366 | O11: 55271.025 | P11: 54943.371 | Q11: 60081.668 | R11: 59059.371 | S11: 56703.63 | T11: 66155.541 | U11: 61140.162 | V11: 63604.918 | W11: 60951.018 | X11: 53167.22 | Y11: 44969.747 | Z11: 31254.063 | AA11: 29527.721 | AB11: 24092.573 | AC11: 26199.427 | AD11: 14074.018 | AE11: 16466.728 | AF11: 12469.102 | AG11: 12599.495 | AH11: 12935.077 | AI11: 13385.966 | AJ11: 14654.258 | AK11: 16171.193 | AL11: 17588.084 | AM11: 22003.783 | AN11: 24062.829 | AO11: 28109.354 | AP11: 29840.431 | AQ11: 34114.96 | AR11: 32532.235 | AS11: 32878.99 | AT11: 31883.765 | AU11: 32038.058 | AV11: 28633.96 | AW11: 31289.502 | AX11: 54440.426 | AY11: 40107.139 | AZ11: 28081.95 | BA11: 40456.055 | BB11: 47615.138 | BC11: 42933.154 | BD11: 27745.978 | BE11: 20567.32 | BF11: 20771.767 | BG11: 14364.293 | BH11: 6954.215 | BI11: 7176.999 | BJ11: 16313.345 | BK11: 6124.544 | BL11: 6745.493 | BM11: 3640.972 | BN11: 2907.88 | BO11: 3757.514 | BP11: 12919.144 | BQ11: 12570.409 | BR11: 12335.658 | BS11: 15260.456 | BT11: 17368.025 | BU11: 19245.384 | BV11: 19858.342
A12: Pleurogrammus azonus | B12: Okhotsk atka mackerel | C12: Medium demersals (30 - 89 cm) | D12: Scorpionfishes | E12: 26527.397 | F12: 26527.397 | G12: 26527.397 | H12: 33754.609 | I12: 24905.046 | J12: 24749.763 | K12: 27035.325 | L12: 24514.985 | M12: 13621.745 | N12: 23890.444 | O12: 26712.276 | P12: 39579.517 | Q12: 27954.875 | R12: 33568.322 | S12: 44194.415 | T12: 25835.223 | U12: 24555.595 | V12: 20780.296 | W12: 21672.063 | X12: 24764.517 | Y12: 35150.375 | Z12: 36598.128 | AA12: 43583.369 | AB12: 32185.566 | AC12: 39191.187 | AD12: 34847.08 | AE12: 54613.55 | AF12: 54718.528 | AG12: 33964.194 | AH12: 31186.864 | AI12: 30372.567 | AJ12: 31771.811 | AK12: 28128.05 | AL12: 18147.213 | AM12: 20622.193 | AN12: 21132.902 | AO12: 23503.301 | AP12: 25169.877 | AQ12: 25835.882 | AR12: 27780.972 | AS12: 31261.731 | AT12: 30262.431 | AU12: 23620.417 | AV12: 29575.629 | AW12: 32872.037 | AX12: 37953.105 | AY12: 38690.645 | AZ12: 43830.519 | BA12: 49418.945 | BB12: 36127.326 | BC12: 34916.787 | BD12: 33793.777 | BE12: 32573.443 | BF12: 35113.059 | BG12: 36975.714 | BH12: 30086.598 | BI12: 25190.884 | BJ12: 29990.005 | BK12: 35383.833 | BL12: 25841.591 | BM12: 19213.458 | BN12: 15062.419 | BO12: 16039.492 | BP12: 12921.149 | BQ12: 8286.666 | BR12: 6049.211 | BS12: 5926.269 | BT12: 5792.444 | BU12: 8683.414 | BV12: 8662.835
... A152: Isurus oxyrinchus | B152: Shortfin mako | C152: Large sharks (>=90 cm) | D152: Sharks & rays | E152: 0 | F152: 0 | G152: 0 | H152: 0 | I152: 0 | J152: 0 | K152: 0 | L152: 0 | M152: 0 | N152: 0 | O152: 0 | P152: 0 | Q152: 0 | R152: 0 | S152: 0 | T152: 0 | U152: 0 | V152: 0 | W152: 0 | X152: 0 | Y152: 0 | Z152: 0 | AA152: 0 | AB152: 0 | AC152: 0 | AD152: 0 | AE152: 0 | AF152: 0 | AG152: 0 | AH152: 0 | AI152: 0 | AJ152: 0 | AK152: 0 | AL152: 0 | AM152: 0 | AN152: 0 | AO152: 0 | AP152: 0 | AQ152: 0 | AR152: 0 | AS152: 0 | AT152: 0 | AU152: 0 | AV152: 0 | AW152: 0 | AX152: 0 | AY152: 0 | AZ152: 0 | BA152: 0 | BB152: 0 | BC152: 0 | BD152: 0 | BE152: 0 | BF152: 0 | BG152: 0 | BH152: 0 | BI152: 0 | BJ152: 0 | BK152: 0 | BL152: 0 | BM152: 0 | BN152: 0 | BO152: 0 | BP152: 0 | BQ152: 0 | BR152: 0 | BS152: 0 | BT152: 0 | BU152: 0 | BV152: 0

Sheet Taxon-Group Map
A1: Which Ecopath group each catch taxon belongs to, and on what evidence.
A2: Several groups separated by | means the taxon spans them and its catch is apportioned; the weights used are in the next two columns.
A4: taxon | B4: common_name | C4: SAU functional group | D4: SAU commercial group | E4: Ecopath group | F4: weights | G4: weight basis | H4: confidence | I4: evidence | J4: catch tonnes | K4: % of catch | L4: explanation
A5: Gadus chalcogrammus | B5: Alaska pollock | C5: Medium benthopelagics (30 - 89 cm) | D5: Cod-likes | E5: Walleye pollock | Juv. pollock | F5: 0.539 | 0.461 | G5: model_biomass | H5: medium | I5: composite_split | J5: 1.4613201e+08 | K5: 60.3008 | L5: Walleye pollock and juvenile pollock are the same taxon at different life stages in Table 1. Catch has no age split and model catch is zero throughout; use model biomass.
A6: Clupea pallasii | B6: Pacific herring | C6: Medium pelagics (30 - 89 cm) | D6: Herring-likes | E6: Pacific herring | H6: high | I6: taxonomic_containment | J6: 18753776 | K6: 7.7387 | L6: Chaikina 2020 Table 1 names Pacific herring; the catch taxon Clupea pallasii is within that taxonomic compartment (WoRMS taxonomy checked).
A7: Marine fishes not identified | B7: Marine fishes nei | C7: Medium demersals (30 - 89 cm) | D7: Other fishes & inverts | E7: Other bottom fishes | Other Gadidae | Cottidae | Pleuronectidae | F7: 0.380 | 0.474 | 0.000 | 0.146 | G7: catch_composition | H7: medium | I7: composite_split | J7: 14223073 | K7: 5.8691 | L7: SAU identifies medium demersal fish; these are the model's broad bottom-fish compartments. Named single-species pelagic stocks and mammal/invertebrate groups are excluded.
A8: Oncorhynchus gorbuscha | B8: Pink salmon | C8: Medium demersals (30 - 89 cm) | D8: Salmon, smelts, etc | E8: Salmon | H8: high | I8: taxonomic_containment | J8: 11221365 | K8: 4.6304 | L8: Pacific salmon catch within the Salmon compartment in Chaikina 2020 Table 1; no size/stage split is supplied.
A9: Sardinops sagax | B9: South American pilchard | C9: Medium pelagics (30 - 89 cm) | D9: Herring-likes | E9: Pacific Sardine | H9: medium | I9: analogue | J9: 6361027.5 | K9: 2.6249 | L9: Regional sardine-name crosswalk inferred: the paper labels Pacific Sardine without a binomial; catch uses Sardinops sagax (WoRMS accepted). Source identity cannot be proved as a species synonym from the common name alone.
A10: Gadus macrocephalus | B10: Pacific cod | C10: Large demersals (>=90 cm) | D10: Cod-likes | E10: Other Gadidae | H10: high | I10: taxonomic_containment | J10: 5161513.4 | K10: 2.1299 | L10: Chaikina 2020 Table 1 names Other Gadidae; the catch taxon Gadus macrocephalus is within that taxonomic compartment (WoRMS taxonomy checked).
A11: Oncorhynchus | B11: Salmons, trouts | C11: Large benthopelagics (>=90 cm) | D11: Salmon, smelts, etc | E11: Salmon | H11: high | I11: taxonomic_containment | J11: 3616523.5 | K11: 1.4923 | L11: Pacific salmon catch within the Salmon compartment in Chaikina 2020 Table 1; no size/stage split is supplied.
A12: Oncorhynchus keta | B12: Chum salmon | C12: Large benthopelagics (>=90 cm) | D12: Salmon, smelts, etc | E12: Salmon | H12: high | I12: taxonomic_containment | J12: 3266940.1 | K12: 1.3481 | L12: Pacific salmon catch within the Salmon compartment in Chaikina 2020 Table 1; no size/stage split is supplied.
A13: Pleuronectiformes | B13: Flatfishes | C13: Small to medium flatfishes (<90 cm) | D13: Flatfishes | E13: Pleuronectidae | Other bottom fishes | F13: 0.278 | 0.722 | G13: catch_composition | H13: medium | I13: composite_split | J13: 2647805.6 | K13: 1.0926 | L13: The order includes righteye flounders in the named family and other bottom-dwelling flatfishes in the residual bottom-fish pool; no evidence restricts all order-level catch to Pleuronectidae.
A14: Paralithodes camtschaticus | B14: Red king crab | C14: Lobsters, crabs | D14: Crustaceans | E14: Crabs and shrimps | H14: high | I14: taxonomic_containment | J14: 2194189.2 | K14: 0.9054 | L14: Chaikina 2020 Table 1 names Crabs and shrimps; the catch taxon Paralithodes camtschaticus is within that taxonomic compartment (WoRMS taxonomy checked).
A15: Pleurogrammus azonus | B15: Okhotsk atka mackerel | C15: Medium demersals (30 - 89 cm) | D15: Scorpionfishes | E15: Other bottom fishes | H15: medium | I15: habitat_size_guild | J15: 1970290.6 | K15: 0.813 | L15: Hexagrammidae, a cold-water demersal shelf fish with no dedicated group; placed in the model's residual demersal 'Other bottom fishes' group on habitat and trophic-level grounds. Reviewed against Chaikina 2020 Table 1; species membership is not tabulated.
A16: Scomber | B16: Chub mackerels | C16: Medium pelagics (30 - 89 cm) | D16: Perch-likes | E16: Unresolved | H16: unresolved | I16: none | J16: 1716358.1 | K16: 0.7082 | L16: Scombridae (mackerel genus), an epipelagic small pelagic; the Okhotsk model has no pelagic/mackerel group, only demersal/mesopelagic/benthic residual categories, so no defensible group exists. Reviewed: no documented compatible group for this catch label.
A17: Teuthida | B17: Squids | C17: Cephalopods | D17: Other fishes & inverts | E17: Squids | H17: high | I17: taxonomic_containment | J17: 1601595.2 | K17: 0.6609 | L17: Chaikina 2020 Table 1 names Squids; the catch taxon Teuthida is within that taxonomic compartment (WoRMS taxonomy checked).
A18: Eleginus gracilis | B18: Saffron cod | C18: Medium demersals (30 - 89 cm) | D18: Cod-likes | E18: Other Gadidae | H18: high | I18: taxonomic_containment | J18: 1420067.3 | K18: 0.586 | L18: Chaikina 2020 Table 1 names Other Gadidae; the catch taxon Eleginus gracilis is within that taxonomic compartment (WoRMS taxonomy checked).
A19: Ammodytes personatus | B19: Pacific sandlance | C19: Small demersals (<30 cm) | D19: Perch-likes | E19: Ammodytidae | H19: high | I19: taxonomic_containment | J19: 1413151.6 | K19: 0.5831 | L19: Chaikina 2020 Table 1 names Ammodytidae; the catch taxon Ammodytes personatus is within that taxonomic compartment (WoRMS taxonomy checked).
A20: Todarodes pacificus | B20: Japanese flying squid | C20: Cephalopods | D20: Other fishes & inverts | E20: Squids | H20: high | I20: taxonomic_containment | J20: 1397772.7 | K20: 0.5768 | L20: Chaikina 2020 Table 1 names Squids; the catch taxon Todarodes pacificus is within that taxonomic compartment (WoRMS taxonomy checked).
A21: Mollusca | B21: Clams, seasnails, squids, octopuses | C21: Other demersal invertebrates | D21: Molluscs | E21: 2nd level benthos | Carnivorous invertebrates | Squids | F21: 0.291 | 0.080 | 0.629 | G21: catch_composition | H21: low | I21: composite_split | J21: 1330721.2 | K21: 0.5491 | L21: Molluscs span basal benthic bivalves/grazers, predatory benthic molluscs and the named squid group; model species lists are absent, so this coarse allocation remains provisional.
A22: Cololabis saira | B22: Pacific saury | C22: Medium pelagics (30 - 89 cm) | D22: Other fishes & inverts | E22: Unresolved | H22: unresolved | I22: none | J22: 1247074 | K22: 0.5146 | L22: Scomberesocidae (Pacific saury), a small epipelagic fish; the Okhotsk model has no pelagic-fish group to place it in. Reviewed: no documented compatible group for this catch label.
A23: Pleurogrammus monopterygius | B23: Atka mackerel | C23: Medium demersals (30 - 89 cm) | D23: Scorpionfishes | E23: Other bottom fishes | H23: medium | I23: habitat_size_guild | J23: 1245166.9 | K23: 0.5138 | L23: Hexagrammidae, same family as Pleurogrammus azonus above; placed in the residual demersal 'Other bottom fishes' group on habitat/trophic grounds. Reviewed against Chaikina 2020 Table 1; species membership is not tabulated.
A24: Oncorhynchus nerka | B24: Sockeye salmon | C24: Medium pelagics (30 - 89 cm) | D24: Salmon, smelts, etc | E24: Salmon | H24: high | I24: taxonomic_containment | J24: 1182462.3 | K24: 0.4879 | L24: Pacific salmon catch within the Salmon compartment in Chaikina 2020 Table 1; no size/stage split is supplied.
A25: Pleuronectidae | B25: Righteye flounders | C25: Small to medium flatfishes (<90 cm) | D25: Flatfishes | E25: Pleuronectidae | H25: high | I25: taxonomic_containment | J25: 1084818.7 | K25: 0.4476 | L25: Chaikina 2020 Table 1 names Pleuronectidae; the catch taxon Pleuronectidae is within that taxonomic compartment (WoRMS taxonomy checked).
A26: Mallotus villosus | B26: Capelin | C26: Small pelagics (<30 cm) | D26: Salmon, smelts, etc | E26: Capelin | H26: high | I26: taxonomic_containment | J26: 1077371.3 | K26: 0.4446 | L26: Chaikina 2020 Table 1 names Capelin; the catch taxon Mallotus villosus is within that taxonomic compartment (WoRMS taxonomy checked).
A27: Miscellaneous marine crustaceans | B27: Marine crabs, shrimps, lobsters nei | C27: Shrimps | D27: Crustaceans | E27: Crabs and shrimps | H27: high | I27: taxonomic_containment | J27: 935887.17 | K27: 0.3862 | L27: Chaikina 2020 Table 1 names Crabs and shrimps; the catch taxon Miscellaneous marine crustaceans is within that taxonomic compartment (WoRMS taxonomy checked).
A28: Scomber japonicus | B28: Pacific chub mackerel | C28: Medium pelagics (30 - 89 cm) | D28: Perch-likes | E28: Unresolved | H28: unresolved | I28: none | J28: 883031.14 | K28: 0.3644 | L28: Scombridae (chub mackerel), epipelagic; same limitation as genus Scomber -- no pelagic-fish group in the Okhotsk model. Reviewed: no documented compatible group for this catch label.
A29: Pectinidae | B29: Scallops | C29: Other demersal invertebrates | D29: Molluscs | E29: 2nd level benthos | H29: medium | I29: habitat_size_guild | J29: 730793.02 | K29: 0.3016 | L29: Analyst inference: Pectinidae is a benthic suspension/deposit feeder or grazer, consistent with Chaikina 2020 Table 1 second-level benthos and its basal diet in Table 3; no species member list is supplied.
A30: Moridae | B30: Codlings, moras | C30: Medium benthopelagics (30 - 89 cm) | D30: Cod-likes | E30: Other bottom fishes | H30: medium | I30: habitat_size_guild | J30: 641456.82 | K30: 0.2647 | L30: Morids are demersal cod-like fishes outside Gadidae; use the residual bottom-fish group, not Other Gadidae.
A31: Engraulis japonicus | B31: Japanese anchovy | C31: Small pelagics (<30 cm) | D31: Anchovies | E31: Unresolved | H31: unresolved | I31: none | J31: 546075.04 | K31: 0.2253 | L31: Engraulidae (Japanese anchovy), small epipelagic; no anchovy or generic pelagic-fish group exists in the Okhotsk model. Reviewed: no documented compatible group for this catch label.
A32: Laemonema longipes | B32: Longfin codling | C32: Medium benthopelagics (30 - 89 cm) | D32: Cod-likes | E32: Other bottom fishes | H32: medium | I32: habitat_size_guild | J32: 535524.24 | K32: 0.221 | L32: Laemonema longipes is a demersal morid; the model has a residual bottom-fish group and no separate Moridae.
A33: Chionoecetes | B33: Tanner, snow crabs | C33: Lobsters, crabs | D33: Crustaceans | E33: Crabs and shrimps | H33: high | I33: taxonomic_containment | J33: 513134.3 | K33: 0.2117 | L33: Chaikina 2020 Table 1 names Crabs and shrimps; the catch taxon Chionoecetes is within that taxonomic compartment (WoRMS taxonomy checked).
... A50: Pandalus borealis | B50: Northern prawn | C50: Shrimps | D50: Crustaceans | E50: Crabs and shrimps | H50: high | I50: taxonomic_containment | J50: 178082.58 | K50: 0.0735 | L50: Chaikina 2020 Table 1 names Crabs and shrimps; the catch taxon Pandalus borealis is within that taxonomic compartment (WoRMS taxonomy checked).
A51: Cephalopoda | B51: Squids, cuttlefishes, octopuses | C51: Cephalopods | D51: Other fishes & inverts | E51: Squids | Carnivorous invertebrates | F51: 0.887 | 0.113 | G51: catch_composition | H51: low | I51: composite_split | J51: 165448.29 | K51: 0.0683 | L51: Cephalopods include the named squids and benthic octopods provisionally assigned to the carnivorous-invertebrate pool; source has no octopod list.
A52: Trachurus japonicus | B52: Japanese jack mackerel | C52: Medium demersals (30 - 89 cm) | D52: Perch-likes | E52: Unresolved | H52: unresolved | I52: none | J52: 160436.36 | K52: 0.0662 | L52: Japanese jack mackerel, family Carangidae, epipelagic; no pelagic-fish group in the Okhotsk model. Reviewed: no documented compatible group for this catch label.
A53: Mizuhopecten yessoensis | B53: Yesso scallop | C53: Other demersal invertebrates | D53: Molluscs | E53: 2nd level benthos | H53: medium | I53: habitat_size_guild | J53: 146408.23 | K53: 0.0604 | L53: Analyst inference: Mizuhopecten yessoensis is a benthic suspension/deposit feeder or grazer, consistent with Chaikina 2020 Table 1 second-level benthos and its basal diet in Table 3; no species member list is supplied.
A54: Octopodidae | B54: Octopuses | C54: Cephalopods | D54: Other fishes & inverts | E54: Carnivorous invertebrates | H54: low | I54: analogue | J54: 145261.18 | K54: 0.0599 | L54: Octopods are benthic carnivorous invertebrates; placement is an ecological analogue because the source does not name their species.
A55: Sciaenidae | B55: Drums, croakers | C55: Medium demersals (30 - 89 cm) | D55: Perch-likes | E55: Unresolved | H55: unresolved | I55: none | J55: 115312.67 | K55: 0.0476 | L55: Drums/croakers, a warm-temperate demersal family; no matching group in the Okhotsk model. Reviewed: no documented compatible group for this catch label.
A56: Carangidae | B56: Jacks, pompanos | C56: Medium pelagics (30 - 89 cm) | D56: Perch-likes | E56: Unresolved | H56: unresolved | I56: none | J56: 113522.54 | K56: 0.0468 | L56: Jacks/pompanos, epipelagic; no pelagic-fish group in the Okhotsk model. Reviewed: no documented compatible group for this catch label.
A57: Sebastes | B57: Redfishes | C57: Large reef assoc. fish (>=90 cm) | D57: Scorpionfishes | E57: Other bottom fishes | H57: medium | I57: habitat_size_guild | J57: 97536.089 | K57: 0.0402 | L57: Rockfish genus (Sebastidae); same reasoning as Sebastidae -- placed in residual 'Other bottom fishes'. Reviewed against Chaikina 2020 Table 1; species membership is not tabulated.
...

Sheet Final mappings
A1: Final taxon-to-group mappings, identified separately for each Ecopath model
A2: One row per taxon/group assignment; numeric weights are the exact values used to calculate SPPR.
A3: Unresolved taxa retain a row with a blank weight. Catch tonnes repeat across a taxon's assignments; do not sum these rows.
A4: unit_id | B4: model_id | C4: taxon | D4: common_name | E4: SAU functional group | F4: SAU commercial group | G4: group | H4: weight | I4: weight_basis | J4: confidence | K4: evidence | L4: explanation | M4: catch_tonnes
A5: LME_052 | B5: 52_1_Sea_of_Okhotsk_NE_(1980) | C5: Gadus chalcogrammus | D5: Alaska pollock | E5: Medium benthopelagics (30 - 89 cm) | F5: Cod-likes | G5: Walleye pollock | H5: 0.53874619 | I5: model_biomass | J5: medium | K5: composite_split | L5: Walleye pollock and juvenile pollock are the same taxon at different life stages in Table 1. Catch has no age split and model catch is zero throughout; use model biomass. | M5: 1.4613201e+08
A6: LME_052 | B6: 52_1_Sea_of_Okhotsk_NE_(1980) | C6: Gadus chalcogrammus | D6: Alaska pollock | E6: Medium benthopelagics (30 - 89 cm) | F6: Cod-likes | G6: Juv. pollock | H6: 0.46125381 | I6: model_biomass | J6: medium | K6: composite_split | L6: Walleye pollock and juvenile pollock are the same taxon at different life stages in Table 1. Catch has no age split and model catch is zero throughout; use model biomass. | M6: 1.4613201e+08
A7: LME_052 | B7: 52_1_Sea_of_Okhotsk_NE_(1980) | C7: Clupea pallasii | D7: Pacific herring | E7: Medium pelagics (30 - 89 cm) | F7: Herring-likes | G7: Pacific herring | H7: 1 | I7: single | J7: high | K7: taxonomic_containment | L7: Chaikina 2020 Table 1 names Pacific herring; the catch taxon Clupea pallasii is within that taxonomic compartment (WoRMS taxonomy checked). | M7: 18753776
A8: LME_052 | B8: 52_1_Sea_of_Okhotsk_NE_(1980) | C8: Marine fishes not identified | D8: Marine fishes nei | E8: Medium demersals (30 - 89 cm) | F8: Other fishes & inverts | G8: Other bottom fishes | H8: 0.37968164 | I8: catch_composition | J8: medium | K8: composite_split | L8: SAU identifies medium demersal fish; these are the model's broad bottom-fish compartments. Named single-species pelagic stocks and mammal/invertebrate groups are excluded. | M8: 14223073
A9: LME_052 | B9: 52_1_Sea_of_Okhotsk_NE_(1980) | C9: Marine fishes not identified | D9: Marine fishes nei | E9: Medium demersals (30 - 89 cm) | F9: Other fishes & inverts | G9: Other Gadidae | H9: 0.47417246 | I9: catch_composition | J9: medium | K9: composite_split | L9: SAU identifies medium demersal fish; these are the model's broad bottom-fish compartments. Named single-species pelagic stocks and mammal/invertebrate groups are excluded. | M9: 14223073
A10: LME_052 | B10: 52_1_Sea_of_Okhotsk_NE_(1980) | C10: Marine fishes not identified | D10: Marine fishes nei | E10: Medium demersals (30 - 89 cm) | F10: Other fishes & inverts | G10: Cottidae | H10: 0 | I10: catch_composition | J10: medium | K10: composite_split | L10: SAU identifies medium demersal fish; these are the model's broad bottom-fish compartments. Named single-species pelagic stocks and mammal/invertebrate groups are excluded. | M10: 14223073
A11: LME_052 | B11: 52_1_Sea_of_Okhotsk_NE_(1980) | C11: Marine fishes not identified | D11: Marine fishes nei | E11: Medium demersals (30 - 89 cm) | F11: Other fishes & inverts | G11: Pleuronectidae | H11: 0.1461459 | I11: catch_composition | J11: medium | K11: composite_split | L11: SAU identifies medium demersal fish; these are the model's broad bottom-fish compartments. Named single-species pelagic stocks and mammal/invertebrate groups are excluded. | M11: 14223073
A12: LME_052 | B12: 52_1_Sea_of_Okhotsk_NE_(1980) | C12: Oncorhynchus gorbuscha | D12: Pink salmon | E12: Medium demersals (30 - 89 cm) | F12: Salmon, smelts, etc | G12: Salmon | H12: 1 | I12: single | J12: high | K12: taxonomic_containment | L12: Pacific salmon catch within the Salmon compartment in Chaikina 2020 Table 1; no size/stage split is supplied. | M12: 11221365
A13: LME_052 | B13: 52_1_Sea_of_Okhotsk_NE_(1980) | C13: Sardinops sagax | D13: South American pilchard | E13: Medium pelagics (30 - 89 cm) | F13: Herring-likes | G13: Pacific Sardine | H13: 1 | I13: single | J13: medium | K13: analogue | L13: Regional sardine-name crosswalk inferred: the paper labels Pacific Sardine without a binomial; catch uses Sardinops sagax (WoRMS accepted). Source identity cannot be proved as a species synonym from the common name alone. | M13: 6361027.5
A14: LME_052 | B14: 52_1_Sea_of_Okhotsk_NE_(1980) | C14: Gadus macrocephalus | D14: Pacific cod | E14: Large demersals (>=90 cm) | F14: Cod-likes | G14: Other Gadidae | H14: 1 | I14: single | J14: high | K14: taxonomic_containment | L14: Chaikina 2020 Table 1 names Other Gadidae; the catch taxon Gadus macrocephalus is within that taxonomic compartment (WoRMS taxonomy checked). | M14: 5161513.4
A15: LME_052 | B15: 52_1_Sea_of_Okhotsk_NE_(1980) | C15: Oncorhynchus | D15: Salmons, trouts | E15: Large benthopelagics (>=90 cm) | F15: Salmon, smelts, etc | G15: Salmon | H15: 1 | I15: single | J15: high | K15: taxonomic_containment | L15: Pacific salmon catch within the Salmon compartment in Chaikina 2020 Table 1; no size/stage split is supplied. | M15: 3616523.5
A16: LME_052 | B16: 52_1_Sea_of_Okhotsk_NE_(1980) | C16: Oncorhynchus keta | D16: Chum salmon | E16: Large benthopelagics (>=90 cm) | F16: Salmon, smelts, etc | G16: Salmon | H16: 1 | I16: single | J16: high | K16: taxonomic_containment | L16: Pacific salmon catch within the Salmon compartment in Chaikina 2020 Table 1; no size/stage split is supplied. | M16: 3266940.1
... A20: LME_052 | B20: 52_1_Sea_of_Okhotsk_NE_(1980) | C20: Pleurogrammus azonus | D20: Okhotsk atka mackerel | E20: Medium demersals (30 - 89 cm) | F20: Scorpionfishes | G20: Other bottom fishes | H20: 1 | I20: single | J20: medium | K20: habitat_size_guild | L20: Hexagrammidae, a cold-water demersal shelf fish with no dedicated group; placed in the model's residual demersal 'Other bottom fishes' group on habitat and trophic-level grounds. Reviewed against Chaikina 2020 Table 1; species membership is not tabulated. | M20: 1970290.6
A21: LME_052 | B21: 52_1_Sea_of_Okhotsk_NE_(1980) | C21: Scomber | D21: Chub mackerels | E21: Medium pelagics (30 - 89 cm) | F21: Perch-likes | G21: Unresolved | J21: unresolved | K21: none | L21: Scombridae (mackerel genus), an epipelagic small pelagic; the Okhotsk model has no pelagic/mackerel group, only demersal/mesopelagic/benthic residual categories, so no defensible group exists. Reviewed: no documented compatible group for this catch label. | M21: 1716358.1
A22: LME_052 | B22: 52_1_Sea_of_Okhotsk_NE_(1980) | C22: Teuthida | D22: Squids | E22: Cephalopods | F22: Other fishes & inverts | G22: Squids | H22: 1 | I22: single | J22: high | K22: taxonomic_containment | L22: Chaikina 2020 Table 1 names Squids; the catch taxon Teuthida is within that taxonomic compartment (WoRMS taxonomy checked). | M22: 1601595.2
A23: LME_052 | B23: 52_1_Sea_of_Okhotsk_NE_(1980) | C23: Eleginus gracilis | D23: Saffron cod | E23: Medium demersals (30 - 89 cm) | F23: Cod-likes | G23: Other Gadidae | H23: 1 | I23: single | J23: high | K23: taxonomic_containment | L23: Chaikina 2020 Table 1 names Other Gadidae; the catch taxon Eleginus gracilis is within that taxonomic compartment (WoRMS taxonomy checked). | M23: 1420067.3
A24: LME_052 | B24: 52_1_Sea_of_Okhotsk_NE_(1980) | C24: Ammodytes personatus | D24: Pacific sandlance | E24: Small demersals (<30 cm) | F24: Perch-likes | G24: Ammodytidae | H24: 1 | I24: single | J24: high | K24: taxonomic_containment | L24: Chaikina 2020 Table 1 names Ammodytidae; the catch taxon Ammodytes personatus is within that taxonomic compartment (WoRMS taxonomy checked). | M24: 1413151.6
A25: LME_052 | B25: 52_1_Sea_of_Okhotsk_NE_(1980) | C25: Todarodes pacificus | D25: Japanese flying squid | E25: Cephalopods | F25: Other fishes & inverts | G25: Squids | H25: 1 | I25: single | J25: high | K25: taxonomic_containment | L25: Chaikina 2020 Table 1 names Squids; the catch taxon Todarodes pacificus is within that taxonomic compartment (WoRMS taxonomy checked). | M25: 1397772.7
A26: LME_052 | B26: 52_1_Sea_of_Okhotsk_NE_(1980) | C26: Mollusca | D26: Clams, seasnails, squids, octopuses | E26: Other demersal invertebrates | F26: Molluscs | G26: 2nd level benthos | H26: 0.29075018 | I26: catch_composition | J26: low | K26: composite_split | L26: Molluscs span basal benthic bivalves/grazers, predatory benthic molluscs and the named squid group; model species lists are absent, so this coarse allocation remains provisional. | M26: 1330721.2
A27: LME_052 | B27: 52_1_Sea_of_Okhotsk_NE_(1980) | C27: Mollusca | D27: Clams, seasnails, squids, octopuses | E27: Other demersal invertebrates | F27: Molluscs | G27: Carnivorous invertebrates | H27: 0.080174035 | I27: catch_composition | J27: low | K27: composite_split | L27: Molluscs span basal benthic bivalves/grazers, predatory benthic molluscs and the named squid group; model species lists are absent, so this coarse allocation remains provisional. | M27: 1330721.2
A28: LME_052 | B28: 52_1_Sea_of_Okhotsk_NE_(1980) | C28: Mollusca | D28: Clams, seasnails, squids, octopuses | E28: Other demersal invertebrates | F28: Molluscs | G28: Squids | H28: 0.62907578 | I28: catch_composition | J28: low | K28: composite_split | L28: Molluscs span basal benthic bivalves/grazers, predatory benthic molluscs and the named squid group; model species lists are absent, so this coarse allocation remains provisional. | M28: 1330721.2
A29: LME_052 | B29: 52_1_Sea_of_Okhotsk_NE_(1980) | C29: Cololabis saira | D29: Pacific saury | E29: Medium pelagics (30 - 89 cm) | F29: Other fishes & inverts | G29: Unresolved | J29: unresolved | K29: none | L29: Scomberesocidae (Pacific saury), a small epipelagic fish; the Okhotsk model has no pelagic-fish group to place it in. Reviewed: no documented compatible group for this catch label. | M29: 1247074
A30: LME_052 | B30: 52_1_Sea_of_Okhotsk_NE_(1980) | C30: Pleurogrammus monopterygius | D30: Atka mackerel | E30: Medium demersals (30 - 89 cm) | F30: Scorpionfishes | G30: Other bottom fishes | H30: 1 | I30: single | J30: medium | K30: habitat_size_guild | L30: Hexagrammidae, same family as Pleurogrammus azonus above; placed in the residual demersal 'Other bottom fishes' group on habitat/trophic grounds. Reviewed against Chaikina 2020 Table 1; species membership is not tabulated. | M30: 1245166.9
A31: LME_052 | B31: 52_1_Sea_of_Okhotsk_NE_(1980) | C31: Oncorhynchus nerka | D31: Sockeye salmon | E31: Medium pelagics (30 - 89 cm) | F31: Salmon, smelts, etc | G31: Salmon | H31: 1 | I31: single | J31: high | K31: taxonomic_containment | L31: Pacific salmon catch within the Salmon compartment in Chaikina 2020 Table 1; no size/stage split is supplied. | M31: 1182462.3
A32: LME_052 | B32: 52_1_Sea_of_Okhotsk_NE_(1980) | C32: Pleuronectidae | D32: Righteye flounders | E32: Small to medium flatfishes (<90 cm) | F32: Flatfishes | G32: Pleuronectidae | H32: 1 | I32: single | J32: high | K32: taxonomic_containment | L32: Chaikina 2020 Table 1 names Pleuronectidae; the catch taxon Pleuronectidae is within that taxonomic compartment (WoRMS taxonomy checked). | M32: 1084818.7
A33: LME_052 | B33: 52_1_Sea_of_Okhotsk_NE_(1980) | C33: Mallotus villosus | D33: Capelin | E33: Small pelagics (<30 cm) | F33: Salmon, smelts, etc | G33: Capelin | H33: 1 | I33: single | J33: high | K33: taxonomic_containment | L33: Chaikina 2020 Table 1 names Capelin; the catch taxon Mallotus villosus is within that taxonomic compartment (WoRMS taxonomy checked). | M33: 1077371.3
A34: LME_052 | B34: 52_1_Sea_of_Okhotsk_NE_(1980) | C34: Miscellaneous marine crustaceans | D34: Marine crabs, shrimps, lobsters nei | E34: Shrimps | F34: Crustaceans | G34: Crabs and shrimps | H34: 1 | I34: single | J34: high | K34: taxonomic_containment | L34: Chaikina 2020 Table 1 names Crabs and shrimps; the catch taxon Miscellaneous marine crustaceans is within that taxonomic compartment (WoRMS taxonomy checked). | M34: 935887.17
A35: LME_052 | B35: 52_1_Sea_of_Okhotsk_NE_(1980) | C35: Scomber japonicus | D35: Pacific chub mackerel | E35: Medium pelagics (30 - 89 cm) | F35: Perch-likes | G35: Unresolved | J35: unresolved | K35: none | L35: Scombridae (chub mackerel), epipelagic; same limitation as genus Scomber -- no pelagic-fish group in the Okhotsk model. Reviewed: no documented compatible group for this catch label. | M35: 883031.14
A36: LME_052 | B36: 52_1_Sea_of_Okhotsk_NE_(1980) | C36: Pectinidae | D36: Scallops | E36: Other demersal invertebrates | F36: Molluscs | G36: 2nd level benthos | H36: 1 | I36: single | J36: medium | K36: habitat_size_guild | L36: Analyst inference: Pectinidae is a benthic suspension/deposit feeder or grazer, consistent with Chaikina 2020 Table 1 second-level benthos and its basal diet in Table 3; no species member list is supplied. | M36: 730793.02
A37: LME_052 | B37: 52_1_Sea_of_Okhotsk_NE_(1980) | C37: Moridae | D37: Codlings, moras | E37: Medium benthopelagics (30 - 89 cm) | F37: Cod-likes | G37: Other bottom fishes | H37: 1 | I37: single | J37: medium | K37: habitat_size_guild | L37: Morids are demersal cod-like fishes outside Gadidae; use the residual bottom-fish group, not Other Gadidae. | M37: 641456.82
A38: LME_052 | B38: 52_1_Sea_of_Okhotsk_NE_(1980) | C38: Engraulis japonicus | D38: Japanese anchovy | E38: Small pelagics (<30 cm) | F38: Anchovies | G38: Unresolved | J38: unresolved | K38: none | L38: Engraulidae (Japanese anchovy), small epipelagic; no anchovy or generic pelagic-fish group exists in the Okhotsk model. Reviewed: no documented compatible group for this catch label. | M38: 546075.04
A39: LME_052 | B39: 52_1_Sea_of_Okhotsk_NE_(1980) | C39: Laemonema longipes | D39: Longfin codling | E39: Medium benthopelagics (30 - 89 cm) | F39: Cod-likes | G39: Other bottom fishes | H39: 1 | I39: single | J39: medium | K39: habitat_size_guild | L39: Laemonema longipes is a demersal morid; the model has a residual bottom-fish group and no separate Moridae. | M39: 535524.24
A40: LME_052 | B40: 52_1_Sea_of_Okhotsk_NE_(1980) | C40: Chionoecetes | D40: Tanner, snow crabs | E40: Lobsters, crabs | F40: Crustaceans | G40: Crabs and shrimps | H40: 1 | I40: single | J40: high | K40: taxonomic_containment | L40: Chaikina 2020 Table 1 names Crabs and shrimps; the catch taxon Chionoecetes is within that taxonomic compartment (WoRMS taxonomy checked). | M40: 513134.3
A41: LME_052 | B41: 52_1_Sea_of_Okhotsk_NE_(1980) | C41: Oncorhynchus kisutch | D41: Coho salmon | E41: Large demersals (>=90 cm) | F41: Salmon, smelts, etc | G41: Salmon | H41: 1 | I41: single | J41: high | K41: taxonomic_containment | L41: Pacific salmon catch within the Salmon compartment in Chaikina 2020 Table 1; no size/stage split is supplied. | M41: 418738.45
A42: LME_052 | B42: 52_1_Sea_of_Okhotsk_NE_(1980) | C42: Chionoecetes opilio | D42: Snow crab | E42: Lobsters, crabs | F42: Crustaceans | G42: Crabs and shrimps | H42: 1 | I42: single | J42: high | K42: taxonomic_containment | L42: Chaikina 2020 Table 1 names Crabs and shrimps; the catch taxon Chionoecetes opilio is within that taxonomic compartment (WoRMS taxonomy checked). | M42: 409348.48
A43: LME_052 | B43: 52_1_Sea_of_Okhotsk_NE_(1980) | C43: Bivalvia | D43: Clams | E43: Other demersal invertebrates | F43: Molluscs | G43: 2nd level benthos | H43: 1 | I43: single | J43: medium | K43: habitat_size_guild | L43: Analyst inference: Bivalvia is a benthic suspension/deposit feeder or grazer, consistent with Chaikina 2020 Table 1 second-level benthos and its basal diet in Table 3; no species member list is supplied. | M43: 391148.83
...

Sheet SPPR
A1: Specific PPR per taxon — LME_052, model 52_1_Sea_of_Okhotsk_NE_(1980)
A2: sppr_simple is the trophic-chain estimate (1/TE)^(TL-1) at TE=0.1, applied to the taxon's own trophic level and needing no model.
A3: All basal sources, including imports. Blank means unavailable, not zero. sppr_simple is an unpartitioned reference.
A4: taxon | B4: trophic_level | C4: sppr_simple | D4: Ecopath group | E4: SPPR_1986 | F4: SPPR_1995_TE0.1 | G4: SPPR_1995_TEmean | H4: Ulanowicz_globalTEmean | I4: Ulanowicz_TE | J4: EwE_TE_noEE | K4: EwE_TE_EE | L4: SPPR_2015 | M4: new_TE_noEEfix | N4: new_TE_EEfix | O4: new_GE | P4: new_WithEgestion | Q4: sym_TE_asPP | R4: sym_TE_asDC | S4: sym_GE_asPP | T4: sym_GE_asDC | U4: sym_WithEgestion_asPP | V4: sym_WithEgestion_asDC | W4: MC_new_GE | X4: MC_new_TE_EEfix
A5: Gadus chalcogrammus | B5: 3.57 | C5: 371.53523 | D5: Walleye pollock | Juv. pollock | E5: 0 | F5: 456.53204 | G5: 83.5192 | H5: 140.25751 | I5: 874.70191 | J5: 877.26275 | K5: 875.94423 | L5: 2360.7769 | M5: 2360.7769 | N5: 2398.3729 | O5: 1280.3485 | P5: 394.59866 | Q5: 2398.3729 | R5: 2360.7769 | S5: 1280.3485 | T5: 1280.3485 | U5: 394.59866 | V5: 394.59866 | W5: 1718.5175 | X5: 2542.6197
A6: Clupea pallasii | B6: 3.16 | C6: 144.54398 | D6: Pacific herring | E6: 0 | F6: 614.06139 | G6: 103.48137 | H6: 102.76213 | I6: 206.63307 | J6: 206.63307 | K6: 166.75288 | L6: 674.69506 | M6: 674.69506 | N6: 685.23715 | O6: 543.54058 | P6: 184.06733 | Q6: 685.23715 | R6: 674.69506 | S6: 543.54058 | T6: 543.54058 | U6: 184.06733 | V6: 184.06733 | W6: 701.57933 | X6: 748.50266
A7: Marine fishes not identified | B7: 3.28 | C7: 190.54607 | D7: Other bottom fishes | Other Gadidae | Cottidae | Pleuronectidae | E7: 0 | F7: 543.74153 | G7: 93.693872 | H7: 233.02492 | I7: 3717.0376 | J7: 4576.9557 | K7: 1766.4783 | L7: -220473.71 | M7: -220473.71 | N7: -224113.07 | O7: 9426.4298 | P7: 1064.6545 | Q7: -224113.07 | R7: -220473.71 | S7: 9426.4298 | T7: 9426.4298 | U7: 1064.6545 | V7: 1064.6545 | W7: 33749.646 | X7: 782832.19
A8: Oncorhynchus gorbuscha | B8: 4.49 | C8: 3090.2954 | D8: Salmon | E8: 0 | F8: 537.79367 | G8: 94.024526 | H8: 104.59847 | I8: 157.17606 | J8: 157.62073 | K8: 47.759081 | L8: 685.40699 | M8: 685.40699 | N8: 696.7193 | O8: 75.247908 | P8: 24.548027 | Q8: 696.7193 | R8: 685.40699 | S8: 75.247908 | T8: 75.247908 | U8: 24.548027 | V8: 24.548027 | W8: 98.758639 | X8: 768.31503
A9: Sardinops sagax | B9: 2.84 | C9: 69.183097 | D9: Pacific Sardine | E9: 0 | F9: 14.256076 | G9: 6.82216 | H9: 9.974089 | I9: 16.077349 | J9: 16.077349 | K9: 13.054808 | L9: 22.182506 | M9: 22.182506 | N9: 22.399947 | O9: 18.034849 | P9: 10.353095 | Q9: 22.399947 | R9: 22.182506 | S9: 18.034849 | T9: 18.034849 | U9: 10.353095 | V9: 10.353095 | W9: 20.670316 | X9: 23.720116
A10: Gadus macrocephalus | B10: 4.16 | C10: 1445.4398 | D10: Other Gadidae | E10: 0 | F10: 707.65637 | G10: 114.65268 | H10: 277.54291 | I10: 7317.5268 | J10: 9118.6472 | K10: 3191.5265 | L10: -469569.2 | M10: -469569.2 | N10: -477319.41 | O10: 17690.132 | P10: 1835.9744 | Q10: -477319.41 | R10: -469569.2 | S10: 17690.132 | T10: 17690.132 | U10: 1835.9744 | V10: 1835.9744 | W10: 68000.609 | X10: 1645094.3
A11: Oncorhynchus | B11: 3.95 | C11: 891.25094 | D11: Salmon | E11: 0 | F11: 537.79367 | G11: 94.024526 | H11: 104.59847 | I11: 157.17606 | J11: 157.62073 | K11: 47.759081 | L11: 685.40699 | M11: 685.40699 | N11: 696.7193 | O11: 75.247908 | P11: 24.548027 | Q11: 696.7193 | R11: 685.40699 | S11: 75.247908 | T11: 75.247908 | U11: 24.548027 | V11: 24.548027 | W11: 98.758639 | X11: 768.31503
A12: Oncorhynchus keta | B12: 3.74 | C12: 549.54087 | D12: Salmon | E12: 0 | F12: 537.79367 | G12: 94.024526 | H12: 104.59847 | I12: 157.17606 | J12: 157.62073 | K12: 47.759081 | L12: 685.40699 | M12: 685.40699 | N12: 696.7193 | O12: 75.247908 | P12: 24.548027 | Q12: 696.7193 | R12: 685.40699 | S12: 75.247908 | T12: 75.247908 | U12: 24.548027 | V12: 24.548027 | W12: 98.758639 | X12: 768.31503
A13: Pleuronectiformes | B13: 3.57 | C13: 371.53523 | D13: Pleuronectidae | Other bottom fishes | E13: 0 | F13: 395.929 | G13: 74.793967 | H13: 192.88018 | I13: 470.24514 | J13: 481.42075 | K13: 481.42075 | L13: 4151.7018 | M13: 4151.7018 | N13: 4219.3591 | O13: 1974.5187 | P13: 369.10587 | Q13: 4219.3591 | R13: 4151.7018 | S13: 1974.5187 | T13: 1974.5187 | U13: 369.10587 | V13: 369.10587 | W13: 2863.352 | X13: 5275.0222
A14: Paralithodes camtschaticus | B14: 3.7 | C14: 501.18723 | D14: Crabs and shrimps | E14: 0 | F14: 95.896642 | G14: 27.047208 | H14: 56.071592 | I14: 87.690287 | J14: 88.352076 | K14: 88.352076 | L14: 181.73531 | M14: 181.73531 | N14: 185.1516 | O14: 112.94091 | P14: 44.389715 | Q14: 185.1516 | R14: 181.73531 | S14: 112.94091 | T14: 112.94091 | U14: 44.389715 | V14: 44.389715 | W14: 155.52695 | X14: 203.43301
A15: Pleurogrammus azonus | B15: 3.6 | C15: 398.10717 | D15: Other bottom fishes | E15: 0 | F15: 458.54947 | G15: 83.794097 | H15: 218.42356 | I15: 526.49216 | J15: 541.53312 | K15: 541.53312 | L15: 4898.3287 | M15: 4898.3287 | N15: 4977.9813 | O15: 2326.1304 | P15: 441.45148 | Q15: 4977.9813 | R15: 4898.3287 | S15: 2326.1304 | T15: 2326.1304 | U15: 441.45148 | V15: 441.45148 | W15: 3363.7874 | X15: 6233.0353
A16: Scomber | B16: 3.65 | C16: 446.68359 | D16: Unresolved
A17: Teuthida | B17: 4.13 | C17: 1348.9629 | D17: Squids | E17: 0 | F17: 957.31008 | G17: 142.63165 | H17: 119.67903 | I17: 66.859093 | J17: 71.95407 | K17: 34.034275 | L17: 245.67107 | M17: 245.67107 | N17: 249.51887 | O17: 112.24683 | P17: 37.014939 | Q17: 249.51887 | R17: 245.67107 | S17: 112.24683 | T17: 112.24683 | U17: 37.014939 | V17: 37.014939 | W17: 147.58128 | X17: 273.21898
A18: Eleginus gracilis | B18: 4.1 | C18: 1258.9254 | D18: Other Gadidae | E18: 0 | F18: 707.65637 | G18: 114.65268 | H18: 277.54291 | I18: 7317.5268 | J18: 9118.6472 | K18: 3191.5265 | L18: -469569.2 | M18: -469569.2 | N18: -477319.41 | O18: 17690.132 | P18: 1835.9744 | Q18: -477319.41 | R18: -469569.2 | S18: 17690.132 | T18: 17690.132 | U18: 1835.9744 | V18: 1835.9744 | W18: 68000.609 | X18: 1645094.3
A19: Ammodytes personatus | B19: 3 | C19: 100 | D19: Ammodytidae | E19: 0 | F19: 100.46158 | G19: 27.971595 | H19: 31.859625 | I19: 94.463189 | J19: 94.463189 | K19: 47.9873 | L19: 92.596847 | M19: 92.596847 | N19: 94.628894 | O19: 29.973178 | P19: 17.402106 | Q19: 94.628894 | R19: 92.596847 | S19: 29.973178 | T19: 29.973178 | U19: 17.402106 | V19: 17.402106 | W19: 36.807626 | X19: 94.424628
A20: Todarodes pacificus | B20: 4.28 | C20: 1905.4607 | D20: Squids | E20: 0 | F20: 957.31008 | G20: 142.63165 | H20: 119.67903 | I20: 66.859093 | J20: 71.95407 | K20: 34.034275 | L20: 245.67107 | M20: 245.67107 | N20: 249.51887 | O20: 112.24683 | P20: 37.014939 | Q20: 249.51887 | R20: 245.67107 | S20: 112.24683 | T20: 112.24683 | U20: 37.014939 | V20: 37.014939 | W20: 147.58128 | X20: 273.21898
A21: Mollusca | B21: 2.1 | C21: 12.589254 | D21: 2nd level benthos | Carnivorous invertebrates | Squids | E21: 0 | F21: 613.14549 | G21: 93.496428 | H21: 79.05749 | I21: 46.128964 | J21: 49.33409 | K21: 24.34442 | L21: 158.38368 | M21: 158.38368 | N21: 160.88952 | O21: 72.751657 | P21: 24.743479 | Q21: 160.88952 | R21: 158.38368 | S21: 72.751657 | T21: 72.751657 | U21: 24.743479 | V21: 24.743479 | W21: 95.4643 | X21: 175.92399
A22: Cololabis saira | B22: 3.71 | C22: 512.86138 | D22: Unresolved
A23: Pleurogrammus monopterygius | B23: 3.38 | C23: 239.88329 | D23: Other bottom fishes | E23: 0 | F23: 458.54947 | G23: 83.794097 | H23: 218.42356 | I23: 526.49216 | J23: 541.53312 | K23: 541.53312 | L23: 4898.3287 | M23: 4898.3287 | N23: 4977.9813 | O23: 2326.1304 | P23: 441.45148 | Q23: 4977.9813 | R23: 4898.3287 | S23: 2326.1304 | T23: 2326.1304 | U23: 441.45148 | V23: 441.45148 | W23: 3363.7874 | X23: 6233.0353
A24: Oncorhynchus nerka | B24: 3.54 | C24: 346.73685 | D24: Salmon | E24: 0 | F24: 537.79367 | G24: 94.024526 | H24: 104.59847 | I24: 157.17606 | J24: 157.62073 | K24: 47.759081 | L24: 685.40699 | M24: 685.40699 | N24: 696.7193 | O24: 75.247908 | P24: 24.548027 | Q24: 696.7193 | R24: 685.40699 | S24: 75.247908 | T24: 75.247908 | U24: 24.548027 | V24: 24.548027 | W24: 98.758639 | X24: 768.31503
A25: Pleuronectidae | B25: 3.49 | C25: 309.02954 | D25: Pleuronectidae | E25: 0 | F25: 233.24334 | G25: 51.41196 | H25: 126.51942 | I25: 324.11748 | J25: 325.25104 | K25: 325.25104 | L25: 2211.9929 | M25: 2211.9929 | N25: 2248.4867 | O25: 1061.0447 | P25: 181.15464 | Q25: 2248.4867 | R25: 2211.9929 | S25: 1061.0447 | T25: 1061.0447 | U25: 181.15464 | V25: 181.15464 | W25: 1563.2393 | X25: 2786.1398
A26: Mallotus villosus | B26: 3.15 | C26: 141.25375 | D26: Capelin | E26: 0 | F26: 260.61536 | G26: 55.704276 | H26: 66.983902 | I26: 104.24605 | J26: 104.24605 | K26: 83.501085 | L26: 284.82933 | M26: 284.82933 | N26: 289.28334 | O26: 227.72965 | P26: 82.514502 | Q26: 289.28334 | R26: 284.82933 | S26: 227.72965 | T26: 227.72965 | U26: 82.514502 | V26: 82.514502 | W26: 299.60564 | X26: 310.17827
A27: Miscellaneous marine crustaceans | B27: 2.7 | C27: 50.118723 | D27: Crabs and shrimps | E27: 0 | F27: 95.896642 | G27: 27.047208 | H27: 56.071592 | I27: 87.690287 | J27: 88.352076 | K27: 88.352076 | L27: 181.73531 | M27: 181.73531 | N27: 185.1516 | O27: 112.94091 | P27: 44.389715 | Q27: 185.1516 | R27: 181.73531 | S27: 112.94091 | T27: 112.94091 | U27: 44.389715 | V27: 44.389715 | W27: 155.52695 | X27: 203.43301
A28: Scomber japonicus | B28: 3.38 | C28: 239.88329 | D28: Unresolved
A29: Pectinidae | B29: 2 | C29: 10 | D29: 2nd level benthos | E29: 0 | F29: 10 | G29: 5.280025 | H29: 5.280025 | I29: 4.25396 | J29: 4.25396 | K29: 2.190789 | L29: 4.011903 | M29: 4.011903 | N29: 4.101044 | O29: 2.575732 | P29: 2.017588 | Q29: 4.101044 | R29: 4.011903 | S29: 2.575732 | T29: 2.575732 | U29: 2.017588 | V29: 2.017588 | W29: 3.13337 | X29: 4.076903
A30: Moridae | B30: 3.87 | C30: 741.31024 | D30: Other bottom fishes | E30: 0 | F30: 458.54947 | G30: 83.794097 | H30: 218.42356 | I30: 526.49216 | J30: 541.53312 | K30: 541.53312 | L30: 4898.3287 | M30: 4898.3287 | N30: 4977.9813 | O30: 2326.1304 | P30: 441.45148 | Q30: 4977.9813 | R30: 4898.3287 | S30: 2326.1304 | T30: 2326.1304 | U30: 441.45148 | V30: 441.45148 | W30: 3363.7874 | X30: 6233.0353
A31: Engraulis japonicus | B31: 3.14 | C31: 138.03843 | D31: Unresolved
A32: Laemonema longipes | B32: 3.24 | C32: 173.78008 | D32: Other bottom fishes | E32: 0 | F32: 458.54947 | G32: 83.794097 | H32: 218.42356 | I32: 526.49216 | J32: 541.53312 | K32: 541.53312 | L32: 4898.3287 | M32: 4898.3287 | N32: 4977.9813 | O32: 2326.1304 | P32: 441.45148 | Q32: 4977.9813 | R32: 4898.3287 | S32: 2326.1304 | T32: 2326.1304 | U32: 441.45148 | V32: 441.45148 | W32: 3363.7874 | X32: 6233.0353
A33: Chionoecetes | B33: 2.3 | C33: 19.952623 | D33: Crabs and shrimps | E33: 0 | F33: 95.896642 | G33: 27.047208 | H33: 56.071592 | I33: 87.690287 | J33: 88.352076 | K33: 88.352076 | L33: 181.73531 | M33: 181.73531 | N33: 185.1516 | O33: 112.94091 | P33: 44.389715 | Q33: 185.1516 | R33: 181.73531 | S33: 112.94091 | T33: 112.94091 | U33: 44.389715 | V33: 44.389715 | W33: 155.52695 | X33: 203.43301
A34: Oncorhynchus kisutch | B34: 4.22 | C34: 1659.5869 | D34: Salmon | E34: 0 | F34: 537.79367 | G34: 94.024526 | H34: 104.59847 | I34: 157.17606 | J34: 157.62073 | K34: 47.759081 | L34: 685.40699 | M34: 685.40699 | N34: 696.7193 | O34: 75.247908 | P34: 24.548027 | Q34: 696.7193 | R34: 685.40699 | S34: 75.247908 | T34: 75.247908 | U34: 24.548027 | V34: 24.548027 | W34: 98.758639 | X34: 768.31503
