Workbook

Sheet Summary
A1: LME_028 — Guinea Current
A2: Ecopath model: 28_646_Guinea_(1998)
A3: Geographic transfer: model covers the coast of the country Guinea (111,932 km²), not the whole Guinea Current LME. Regional overlap requires validation. 28_646_Guinea_(1998)
A5: region type | B5: LME
A6: latitude | B6: 5.11506
A7: longitude | B7: -1.37888
A8: catch years | B8: 1950-2019
A9: taxa in catch | B9: 375
A10: taxa apportioned across groups | B10: 43
A11: taxa unresolved | B11: 83
A12: catch tonnage on a named group, % | B12: 98.6
A13: SPPR methods | B13: 22
A14: methods flagged as unusable | B14: 7
A15: headline method below | B15: Ulanowicz_TE
A17: year | B17: catch_tonnes | C17: ppr_simple | D17: ppr_Ulanowicz_TE | E17: ppr_simple / NPP % | F17: ppr_Ulanowicz_TE / NPP %
A18: 1950 | B18: 482564.66 | C18: 1.5777897e+08 | D18: 1.205628e+09
A19: 1951 | B19: 503621.55 | C19: 1.6497001e+08 | D19: 1.2454888e+09
A20: 1952 | B20: 510959.06 | C20: 1.6542396e+08 | D20: 1.2916733e+09
A21: 1953 | B21: 548137.05 | C21: 1.7822319e+08 | D21: 1.3562832e+09
A22: 1954 | B22: 559611.56 | C22: 1.7913348e+08 | D22: 1.3771465e+09
A23: 1955 | B23: 557412.78 | C23: 1.7903778e+08 | D23: 1.3709389e+09
A24: 1956 | B24: 630556.77 | C24: 2.0785974e+08 | D24: 1.6325255e+09
A25: 1957 | B25: 712735.51 | C25: 3.0515436e+08 | D25: 1.772489e+09
A26: 1958 | B26: 720211.23 | C26: 2.945763e+08 | D26: 1.902362e+09
A27: 1959 | B27: 820932.82 | C27: 3.8845973e+08 | D27: 2.3005981e+09
A28: 1960 | B28: 850142.78 | C28: 4.3350172e+08 | D28: 2.530761e+09
A29: 1961 | B29: 921744.67 | C29: 4.6538133e+08 | D29: 2.5046515e+09
... A65: 1997 | B65: 3136676.1 | C65: 1.3687115e+09 | D65: 9.9918207e+09
A66: 1998 | B66: 3192647.4 | C66: 1.4374273e+09 | D66: 9.9268014e+09 | E66: 22.1635 | F66: 153.06
A67: 1999 | B67: 3303199.2 | C67: 1.5584064e+09 | D67: 1.1208286e+10 | E67: 24.4393 | F67: 175.7711
A68: 2000 | B68: 3557082 | C68: 1.5640069e+09 | D68: 1.0618239e+10 | E68: 23.6375 | F68: 160.4778
A69: 2001 | B69: 3477624.7 | C69: 1.5642809e+09 | D69: 1.064354e+10 | E69: 24.262 | F69: 165.0811
A70: 2002 | B70: 3487727.2 | C70: 1.5126009e+09 | D70: 1.1006008e+10 | E70: 22.5102 | F70: 163.7892
A71: 2003 | B71: 3376002.4 | C71: 1.5143905e+09 | D71: 1.0464722e+10 | E71: 24.9169 | F71: 172.1802
A72: 2004 | B72: 3376872.5 | C72: 1.5855307e+09 | D72: 1.0991196e+10 | E72: 26.7382 | F72: 185.354
A73: 2005 | B73: 3300627.6 | C73: 1.5669877e+09 | D73: 1.1723747e+10 | E73: 26.4205 | F73: 197.6702
A74: 2006 | B74: 3300934.6 | C74: 1.5049472e+09 | D74: 1.0390151e+10 | E74: 25.1576 | F74: 173.6878
A75: 2007 | B75: 3375789.9 | C75: 1.5729334e+09 | D75: 1.1031253e+10 | E75: 26.7224 | F75: 187.4091
A76: 2008 | B76: 3504109.7 | C76: 1.6883616e+09 | D76: 1.1997445e+10 | E76: 28.558 | F76: 202.932
A77: 2009 | B77: 3395430.4 | C77: 1.6931501e+09 | D77: 1.2450847e+10 | E77: 28.2479 | F77: 207.7257
...

Sheet Catch
A1: taxon | B1: common_name | C1: functional_group | D1: commercial_group | E1: 1950 | F1: 1951 | G1: 1952 | H1: 1953 | I1: 1954 | J1: 1955 | K1: 1956 | L1: 1957 | M1: 1958 | N1: 1959 | O1: 1960 | P1: 1961 | Q1: 1962 | R1: 1963 | S1: 1964 | T1: 1965 | U1: 1966 | V1: 1967 | W1: 1968 | X1: 1969 | Y1: 1970 | Z1: 1971 | AA1: 1972 | AB1: 1973 | AC1: 1974 | AD1: 1975 | AE1: 1976 | AF1: 1977 | AG1: 1978 | AH1: 1979 | AI1: 1980 | AJ1: 1981 | AK1: 1982 | AL1: 1983 | AM1: 1984 | AN1: 1985 | AO1: 1986 | AP1: 1987 | AQ1: 1988 | AR1: 1989 | AS1: 1990 | AT1: 1991 | AU1: 1992 | AV1: 1993 | AW1: 1994 | AX1: 1995 | AY1: 1996 | AZ1: 1997 | BA1: 1998 | BB1: 1999 | BC1: 2000 | BD1: 2001 | BE1: 2002 | BF1: 2003 | BG1: 2004 | BH1: 2005 | BI1: 2006 | BJ1: 2007 | BK1: 2008 | BL1: 2009 | BM1: 2010 | BN1: 2011 | BO1: 2012 | BP1: 2013 | BQ1: 2014 | BR1: 2015 | BS1: 2016 | BT1: 2017 | BU1: 2018 | BV1: 2019
A2: Marine fishes not identified | B2: Marine fishes nei | C2: Medium demersals (30 - 89 cm) | D2: Other fishes & inverts | E2: 129544.9 | F2: 135885.34 | G2: 142536.15 | H2: 149698.47 | I2: 156766.5 | J2: 142418.38 | K2: 176406.64 | L2: 191451.55 | M2: 189089.39 | N2: 236429.46 | O2: 233056.15 | P2: 227157.91 | Q2: 226239.71 | R2: 246613.09 | S2: 274130.95 | T2: 292383.09 | U2: 311556.49 | V2: 321198.91 | W2: 342659.16 | X2: 355872.68 | Y2: 383325.16 | Z2: 429736.09 | AA2: 435187.87 | AB2: 457367.85 | AC2: 480949.03 | AD2: 506181.58 | AE2: 599245.1 | AF2: 663201.05 | AG2: 673631.13 | AH2: 649164.54 | AI2: 787605.7 | AJ2: 842972.65 | AK2: 799485.52 | AL2: 804953.4 | AM2: 864268.98 | AN2: 909114.61 | AO2: 1052089.5 | AP2: 1155071.7 | AQ2: 1117918.9 | AR2: 1185644.5 | AS2: 1131457.8 | AT2: 929454.64 | AU2: 864736.63 | AV2: 940415.76 | AW2: 965417.85 | AX2: 963355.27 | AY2: 999147.77 | AZ2: 1115269.2 | BA2: 1096263.7 | BB2: 1166649 | BC2: 1325115.7 | BD2: 1282738 | BE2: 1298793.9 | BF2: 1155217.5 | BG2: 1131700.1 | BH2: 1092579.4 | BI2: 1060241.1 | BJ2: 1105984.6 | BK2: 1079714.9 | BL2: 1019118.4 | BM2: 1062162.5 | BN2: 1238146.5 | BO2: 973016.84 | BP2: 1298368.4 | BQ2: 1356509.9 | BR2: 1379820.4 | BS2: 1420277.7 | BT2: 1393418.2 | BU2: 1448199.1 | BV2: 1534001.6
A3: Ethmalosa fimbriata | B3: Bonga shad | C3: Medium pelagics (30 - 89 cm) | D3: Herring-likes | E3: 93103.949 | F3: 95381.169 | G3: 97418.859 | H3: 100050.18 | I3: 104756.15 | J3: 109269.28 | K3: 109138.33 | L3: 113234.68 | M3: 118823.98 | N3: 119968.34 | O3: 123140.67 | P3: 135933.9 | Q3: 138930.35 | R3: 141429.57 | S3: 148356.63 | T3: 147444.14 | U3: 157590.6 | V3: 157852.79 | W3: 163189.05 | X3: 154952.39 | Y3: 160831.34 | Z3: 164590.98 | AA3: 174122.27 | AB3: 181066.12 | AC3: 183926.46 | AD3: 194805.4 | AE3: 182121.53 | AF3: 195204.37 | AG3: 202685.64 | AH3: 212463.38 | AI3: 240696.12 | AJ3: 241736.58 | AK3: 244255.5 | AL3: 256509.88 | AM3: 248688.71 | AN3: 261117.06 | AO3: 246497.52 | AP3: 265772.22 | AQ3: 265921.54 | AR3: 267831.98 | AS3: 234262.07 | AT3: 221124.62 | AU3: 247990.74 | AV3: 231282.77 | AW3: 243237.71 | AX3: 235654.94 | AY3: 214393.94 | AZ3: 247583.72 | BA3: 237651.95 | BB3: 227055.34 | BC3: 232729.8 | BD3: 267900.46 | BE3: 299719.74 | BF3: 308904.42 | BG3: 299341.88 | BH3: 286054.98 | BI3: 319661.06 | BJ3: 326158.68 | BK3: 336004.27 | BL3: 347368.37 | BM3: 343136.71 | BN3: 332154.2 | BO3: 360762.77 | BP3: 377558.05 | BQ3: 372104.77 | BR3: 366431.84 | BS3: 341636.07 | BT3: 420919.16 | BU3: 429887.79 | BV3: 430372.01
A4: Sardinella | B4: Sardinellas | C4: Small pelagics (<30 cm) | D4: Herring-likes | E4: 44658.75 | F4: 45305.825 | G4: 50681.438 | H4: 53400.561 | I4: 59094.802 | J4: 61592.327 | K4: 63537.791 | L4: 65500.098 | M4: 68378.078 | N4: 73325.65 | O4: 65488.294 | P4: 70707.996 | Q4: 74502.915 | R4: 65121.587 | S4: 90792.829 | T4: 68105.705 | U4: 77847.155 | V4: 99257.004 | W4: 76788.563 | X4: 90099.352 | Y4: 110692.42 | Z4: 136816.12 | AA4: 188762.25 | AB4: 156875.55 | AC4: 121217.28 | AD4: 130316.81 | AE4: 121455.23 | AF4: 135195.13 | AG4: 164832.59 | AH4: 101449.73 | AI4: 99754.633 | AJ4: 103425.91 | AK4: 94764.881 | AL4: 100517 | AM4: 90207.096 | AN4: 87438.486 | AO4: 95469.095 | AP4: 96206.951 | AQ4: 95021.333 | AR4: 91369.934 | AS4: 117830.05 | AT4: 176124.3 | AU4: 143302.27 | AV4: 106725.74 | AW4: 112931.63 | AX4: 191345.36 | AY4: 214925.28 | AZ4: 221826.73 | BA4: 222877.43 | BB4: 195525.44 | BC4: 193952.8 | BD4: 178177.31 | BE4: 180611.22 | BF4: 174405.81 | BG4: 162928.41 | BH4: 153811.35 | BI4: 175118.33 | BJ4: 193450.68 | BK4: 189450.54 | BL4: 198422.75 | BM4: 210053.52 | BN4: 211785.55 | BO4: 208095.49 | BP4: 180186.55 | BQ4: 210834.19 | BR4: 142805.97 | BS4: 109645.2 | BT4: 194243.05 | BU4: 187100.62 | BV4: 179011.43
A5: Engraulis encrasicolus | B5: European anchovy | C5: Small pelagics (<30 cm) | D5: Anchovies | E5: 7808.755 | F5: 8039.089 | G5: 8256.854 | H5: 8323.496 | I5: 8550.719 | J5: 8835.409 | K5: 9550.548 | L5: 9962.032 | M5: 9836.524 | N5: 10776.544 | O5: 10042.985 | P5: 10555.872 | Q5: 10869.108 | R5: 10088.914 | S5: 15216.769 | T5: 8656.867 | U5: 8191.68 | V5: 10698.966 | W5: 11056.605 | X5: 17345.362 | Y5: 27209.204 | Z5: 47164.584 | AA5: 35622.692 | AB5: 65808.513 | AC5: 83086.963 | AD5: 94874.189 | AE5: 87357.114 | AF5: 113603.8 | AG5: 142026.21 | AH5: 53891.062 | AI5: 143110.8 | AJ5: 173994.49 | AK5: 144188.98 | AL5: 125729.78 | AM5: 113741.7 | AN5: 97372.105 | AO5: 92073.712 | AP5: 176482.04 | AQ5: 180469.08 | AR5: 164605.32 | AS5: 201676.78 | AT5: 169764.26 | AU5: 176931.74 | AV5: 170956.5 | AW5: 144598.56 | AX5: 159510.42 | AY5: 187460.12 | AZ5: 171455.43 | BA5: 139103.07 | BB5: 133567.61 | BC5: 177147.1 | BD5: 153014.12 | BE5: 152775.33 | BF5: 176555.9 | BG5: 118785.2 | BH5: 95539.062 | BI5: 110064.33 | BJ5: 82537.364 | BK5: 103938.38 | BL5: 126514.51 | BM5: 116946.09 | BN5: 107128.52 | BO5: 90881.102 | BP5: 48581.229 | BQ5: 55384.157 | BR5: 56929.912 | BS5: 67039.269 | BT5: 90940.845 | BU5: 117155.04 | BV5: 101730.96
A6: Pseudotolithus | B6: African croakers | C6: Large demersals (>=90 cm) | D6: Perch-likes | E6: 9403.594 | F6: 9646.083 | G6: 11432.638 | H6: 12050.124 | I6: 13270.444 | J6: 13905.025 | K6: 15829.158 | L6: 17352.157 | M6: 18369.885 | N6: 19218.039 | O6: 20849.976 | P6: 23559.909 | Q6: 24929.74 | R6: 30270.659 | S6: 30858.944 | T6: 34762.753 | U6: 37167.128 | V6: 34145.188 | W6: 34602.434 | X6: 34750.52 | Y6: 36509.74 | Z6: 53250.981 | AA6: 51169.762 | AB6: 50874.485 | AC6: 51163.031 | AD6: 53823.307 | AE6: 54490.246 | AF6: 57975.462 | AG6: 62032.009 | AH6: 62512.926 | AI6: 57358.233 | AJ6: 58655.308 | AK6: 61333.993 | AL6: 64909.873 | AM6: 68835.842 | AN6: 84472.449 | AO6: 85321.035 | AP6: 70604.312 | AQ6: 87412.799 | AR6: 103296.65 | AS6: 91317.052 | AT6: 106181.18 | AU6: 103246.13 | AV6: 118872.75 | AW6: 119667.23 | AX6: 103157.93 | AY6: 106062.73 | AZ6: 93686.885 | BA6: 91196.434 | BB6: 95401.043 | BC6: 177154.57 | BD6: 179255.12 | BE6: 181135.92 | BF6: 178943.79 | BG6: 176458.64 | BH6: 174366.32 | BI6: 163223.31 | BJ6: 158761.45 | BK6: 153647.76 | BL6: 144230.35 | BM6: 138737.57 | BN6: 150997.08 | BO6: 119078.39 | BP6: 108435.08 | BQ6: 122926.48 | BR6: 156667.1 | BS6: 143295.23 | BT6: 149223.4 | BU6: 157337.7 | BV6: 157757.92
A7: Sardinella aurita | B7: Round sardinella | C7: Small pelagics (<30 cm) | D7: Herring-likes | E7: 28110.347 | F7: 30043.708 | G7: 26637.786 | H7: 32417.786 | I7: 31141.293 | J7: 30378.473 | K7: 37743.153 | L7: 39403.038 | M7: 38580.175 | N7: 37094.287 | O7: 35224.423 | P7: 46152.578 | Q7: 46746.93 | R7: 59325.06 | S7: 49436.34 | T7: 42197.884 | U7: 45861.763 | V7: 39706.046 | W7: 31982.56 | X7: 40085.303 | Y7: 29600.647 | Z7: 32579.123 | AA7: 30149.817 | AB7: 15231.883 | AC7: 13224.21 | AD7: 20623.907 | AE7: 30930 | AF7: 35769.513 | AG7: 41214.707 | AH7: 46480.463 | AI7: 60976.869 | AJ7: 57334.519 | AK7: 68155.82 | AL7: 94446.263 | AM7: 67061.584 | AN7: 116991.1 | AO7: 130232.69 | AP7: 136769.39 | AQ7: 133830.08 | AR7: 127832.7 | AS7: 103498.44 | AT7: 125662.84 | AU7: 178410.93 | AV7: 128154.62 | AW7: 100621.28 | AX7: 101899.19 | AY7: 169872.8 | AZ7: 87337.2 | BA7: 99983.839 | BB7: 111408.59 | BC7: 149953.13 | BD7: 109816.06 | BE7: 91910.14 | BF7: 105576.15 | BG7: 114593.69 | BH7: 105090.09 | BI7: 99937.348 | BJ7: 72485.448 | BK7: 57404.213 | BL7: 46078.9 | BM7: 63363.865 | BN7: 56139.665 | BO7: 63225.108 | BP7: 70179.183 | BQ7: 82185.118 | BR7: 67401.68 | BS7: 86483.982 | BT7: 95217.625 | BU7: 75683.026 | BV7: 68993.489
A8: Cephalopoda | B8: Squids, cuttlefishes, octopuses | C8: Cephalopods | D8: Other fishes & inverts | E8: 12470.615 | F8: 12897.987 | G8: 13353.765 | H8: 13910.615 | I8: 14332.164 | J8: 14785.447 | K8: 15140.992 | L8: 15648.886 | M8: 16102.892 | N8: 16557.744 | O8: 16955.602 | P8: 17409.985 | Q8: 17382.96 | R8: 17456.858 | S8: 17463.541 | T8: 17536.049 | U8: 17584.972 | V8: 17963.553 | W8: 18421.943 | X8: 18904.101 | Y8: 19404.651 | Z8: 19932.173 | AA8: 21403.254 | AB8: 25839.924 | AC8: 27908.79 | AD8: 27159.229 | AE8: 32292.785 | AF8: 47108.876 | AG8: 67944.916 | AH8: 68149.857 | AI8: 76704.769 | AJ8: 65779.231 | AK8: 67605.085 | AL8: 71842.294 | AM8: 68621.567 | AN8: 49416.921 | AO8: 56753.621 | AP8: 65587.508 | AQ8: 58412.691 | AR8: 38823.933 | AS8: 87349.736 | AT8: 88300.98 | AU8: 79950.053 | AV8: 76921.718 | AW8: 76045.04 | AX8: 95102.434 | AY8: 89401.423 | AZ8: 141601.91 | BA8: 153586.01 | BB8: 117202.69 | BC8: 145972.38 | BD8: 134999.19 | BE8: 122519.56 | BF8: 129442.68 | BG8: 118367.72 | BH8: 137972.9 | BI8: 152817.51 | BJ8: 153694.18 | BK8: 153207.97 | BL8: 151406.35 | BM8: 149654.4 | BN8: 92547.659 | BO8: 88549.441 | BP8: 84576.423 | BQ8: 86765.711 | BR8: 88482.632 | BS8: 93411.955 | BT8: 104863.55 | BU8: 115524.65 | BV8: 123598.05
A9: Brachydeuterus auritus | B9: Bigeye grunt | C9: Small demersals (<30 cm) | D9: Perch-likes | E9: 5029.515 | F9: 5115.217 | G9: 5572.808 | H9: 5773.311 | I9: 7947.116 | J9: 8624.217 | K9: 9784.083 | L9: 11687.802 | M9: 13915.037 | N9: 10633.605 | O9: 14217.319 | P9: 16697.368 | Q9: 19477.463 | R9: 21682.793 | S9: 21113.885 | T9: 29042.874 | U9: 28178.98 | V9: 24014.532 | W9: 22976.902 | X9: 29866.543 | Y9: 28753.46 | Z9: 33933.118 | AA9: 39935.091 | AB9: 38145.273 | AC9: 38373.377 | AD9: 37926.715 | AE9: 42239.982 | AF9: 50248.888 | AG9: 54035.05 | AH9: 49717.332 | AI9: 48049.823 | AJ9: 56636.642 | AK9: 59990.286 | AL9: 52400.006 | AM9: 56223.774 | AN9: 54146.783 | AO9: 68473.544 | AP9: 63609.903 | AQ9: 60129.233 | AR9: 57203.405 | AS9: 74630.812 | AT9: 63655.618 | AU9: 54212.546 | AV9: 51677.141 | AW9: 61353.933 | AX9: 58249.374 | AY9: 56245.307 | AZ9: 65006.581 | BA9: 53764.603 | BB9: 57142.971 | BC9: 61287.79 | BD9: 55516.732 | BE9: 51404.959 | BF9: 48534.742 | BG9: 66423.675 | BH9: 60353.875 | BI9: 57939.268 | BJ9: 60640.444 | BK9: 58491.043 | BL9: 52963.621 | BM9: 58164.13 | BN9: 75097.32 | BO9: 52678.532 | BP9: 48227.445 | BQ9: 57538.24 | BR9: 79605.095 | BS9: 76943.496 | BT9: 73063.392 | BU9: 84724.059 | BV9: 102356.77
A10: Trachurus | B10: Jacks, horse mackerels | C10: Medium pelagics (30 - 89 cm) | D10: Perch-likes | E10: 198.066 | F10: 196.61 | G10: 200.654 | H10: 240.655 | I10: 236.436 | J10: 229.642 | K10: 315.068 | L10: 334.882 | M10: 728.046 | N10: 653.175 | O10: 7405.265 | P10: 27050.335 | Q10: 24186.73 | R10: 21091.812 | S10: 20885.49 | T10: 14489.449 | U10: 7335.636 | V10: 16331.603 | W10: 17710.337 | X10: 21422.565 | Y10: 27728.221 | Z10: 48146.106 | AA10: 45334.095 | AB10: 39759.327 | AC10: 48263.742 | AD10: 52263.658 | AE10: 67264.447 | AF10: 75806.418 | AG10: 55864.717 | AH10: 50659.298 | AI10: 101318.36 | AJ10: 85381.025 | AK10: 100272.16 | AL10: 82839.201 | AM10: 57466.021 | AN10: 60708.269 | AO10: 70299.348 | AP10: 87844.337 | AQ10: 51096.78 | AR10: 45042.306 | AS10: 27251.897 | AT10: 22306.774 | AU10: 15949.068 | AV10: 12328.362 | AW10: 10107.17 | AX10: 21437.598 | AY10: 15801.42 | AZ10: 21054.503 | BA10: 28558.32 | BB10: 18521.49 | BC10: 37028.52 | BD10: 30525.136 | BE10: 22379.454 | BF10: 23227.882 | BG10: 39974.06 | BH10: 53695.264 | BI10: 77344.817 | BJ10: 104767.06 | BK10: 144044.28 | BL10: 128688.42 | BM10: 195347.01 | BN10: 99644.104 | BO10: 49590.014 | BP10: 46311.074 | BQ10: 56227.719 | BR10: 48595.697 | BS10: 67099.392 | BT10: 61818.033 | BU10: 71003.865 | BV10: 84019.575
A11: Sardinella maderensis | B11: Madeiran sardinella | C11: Medium pelagics (30 - 89 cm) | D11: Herring-likes | E11: 9454.907 | F11: 9888.645 | G11: 10272.701 | H11: 10975.005 | I11: 11144.413 | J11: 11373.495 | K11: 13232.441 | L11: 14778.903 | M11: 16413.673 | N11: 17401.126 | O11: 18838.843 | P11: 21231.094 | Q11: 23299.655 | R11: 26063.959 | S11: 33164.904 | T11: 39227.54 | U11: 45024.174 | V11: 20262.098 | W11: 20891.792 | X11: 20795.693 | Y11: 36849.373 | Z11: 52485.267 | AA11: 49584.54 | AB11: 58986.777 | AC11: 69251.726 | AD11: 87461.383 | AE11: 75548.104 | AF11: 61884.838 | AG11: 35225.423 | AH11: 56678.023 | AI11: 49165.426 | AJ11: 51336.473 | AK11: 44708.224 | AL11: 38096.171 | AM11: 41809.646 | AN11: 50089.333 | AO11: 42784.032 | AP11: 55619.647 | AQ11: 33352.666 | AR11: 37652.842 | AS11: 41420.465 | AT11: 38091.468 | AU11: 31229.602 | AV11: 33801.773 | AW11: 32149.585 | AX11: 29703.608 | AY11: 31780.886 | AZ11: 41049.645 | BA11: 46030.975 | BB11: 41803.55 | BC11: 40451.605 | BD11: 43608.408 | BE11: 45580.241 | BF11: 41631.388 | BG11: 64305.121 | BH11: 44865.941 | BI11: 52772.582 | BJ11: 43690.698 | BK11: 55501.29 | BL11: 36372.334 | BM11: 43211.869 | BN11: 49715.365 | BO11: 42113.166 | BP11: 39669.489 | BQ11: 38491.453 | BR11: 45584.319 | BS11: 38497.948 | BT11: 52613.453 | BU11: 55109.322 | BV11: 48855.377
A12: Katsuwonus pelamis | B12: Skipjack tuna | C12: Large pelagics (>=90 cm) | D12: Tuna & billfishes | E12: 8.862 | F12: 8.918 | G12: 8.974 | H12: 265.875 | I12: 283.778 | J12: 9.206 | K12: 9.247 | L12: 12.014 | M12: 9.407 | N12: 9.537 | O12: 30.604 | P12: 13.679 | Q12: 1418.858 | R12: 4135.642 | S12: 3820.353 | T12: 9306.166 | U12: 8256.715 | V12: 8313.337 | W12: 21735.906 | X12: 13007.081 | Y12: 28277.379 | Z12: 34739.506 | AA12: 32186.937 | AB12: 21265.935 | AC12: 43308.822 | AD12: 20010.953 | AE12: 30265.335 | AF12: 42130.279 | AG12: 55134.57 | AH12: 36024.515 | AI12: 51284.5 | AJ12: 54560.758 | AK12: 49262.969 | AL12: 53442.065 | AM12: 19834.872 | AN12: 15854.236 | AO12: 20873.553 | AP12: 23029.455 | AQ12: 29630.666 | AR12: 28990.915 | AS12: 36300.315 | AT12: 52862.884 | AU12: 37289.494 | AV12: 47301.67 | AW12: 37696.242 | AX12: 37455.572 | AY12: 43906.749 | AZ12: 33006.446 | BA12: 37996.191 | BB12: 53964.388 | BC12: 47255.074 | BD12: 48926.086 | BE12: 36154.464 | BF12: 42541.253 | BG12: 49776.336 | BH12: 44706.975 | BI12: 33385.244 | BJ12: 41835.299 | BK12: 48770.295 | BL12: 56301.452 | BM12: 61623.329 | BN12: 78167.944 | BO12: 81627.127 | BP12: 75016.785 | BQ12: 55356.633 | BR12: 73322.383 | BS12: 78982.474 | BT12: 71258.282 | BU12: 75037.405 | BV12: 71353.809
... A376: Somniosus rostratus | B376: Little sleeper shark | C376: Large sharks (>=90 cm) | D376: Sharks & rays | E376: 0 | F376: 0 | G376: 0 | H376: 0 | I376: 0 | J376: 0 | K376: 0 | L376: 0 | M376: 0 | N376: 0 | O376: 0 | P376: 0 | Q376: 0 | R376: 0 | S376: 0 | T376: 0 | U376: 0 | V376: 0 | W376: 0 | X376: 0 | Y376: 0 | Z376: 0 | AA376: 0 | AB376: 0 | AC376: 0 | AD376: 0 | AE376: 0 | AF376: 0 | AG376: 0 | AH376: 0 | AI376: 0 | AJ376: 0 | AK376: 0 | AL376: 0 | AM376: 0 | AN376: 0 | AO376: 0 | AP376: 0 | AQ376: 0 | AR376: 0 | AS376: 0 | AT376: 0 | AU376: 0 | AV376: 0 | AW376: 0 | AX376: 0 | AY376: 0 | AZ376: 0 | BA376: 0 | BB376: 0 | BC376: 0 | BD376: 0 | BE376: 0 | BF376: 0 | BG376: 0 | BH376: 0 | BI376: 0 | BJ376: 0 | BK376: 0 | BL376: 0 | BM376: 0.004 | BN376: 0 | BO376: 0 | BP376: 0 | BQ376: 0 | BR376: 0 | BS376: 0 | BT376: 0 | BU376: 0 | BV376: 0

Sheet Taxon-Group Map
A1: Which Ecopath group each catch taxon belongs to, and on what evidence.
A2: Several groups separated by | means the taxon spans them and its catch is apportioned; the weights used are in the next two columns.
A4: taxon | B4: common_name | C4: SAU functional group | D4: SAU commercial group | E4: Ecopath group | F4: weights | G4: weight basis | H4: confidence | I4: evidence | J4: catch tonnes | K4: % of catch | L4: explanation
A5: Marine fishes not identified | B5: Marine fishes nei | C5: Medium demersals (30 - 89 cm) | D5: Other fishes & inverts | E5: Côtier L pred | Côtier M pred | Côtier M inv | Côtier S pred | Côtier S inv | Dem L pred | Dem L inv | Dem M pred | Dem M inv | Dem S pred | Dem S inv | F5: 0.239 | 0.000 | 0.231 | 0.051 | 0.264 | 0.047 | 0.006 | 0.012 | 0.149 | 0.000 | 0.001 | G5: catch_composition | H5: low | I5: composite_split | J5: 54105502 | K5: 32.2723 | L5: Medium-demersal unidentified catch is restricted to broad coastal (<40 m) and shelf demersal (20-200 m) fish guilds, with adjacent sizes. Named single-stock groups, pelagic pools and bathyal pools are excluded. Source p.128 describes overlapping coastal/shelf habitats; this is a wide estimated allocation.
A6: Ethmalosa fimbriata | B6: Bonga shad | C6: Medium pelagics (30 - 89 cm) | D6: Herring-likes | E6: Ethmalose | H6: high | I6: explicit_member | J6: 16059854 | K6: 9.5792 | L6: Guénette & Diallo 2004 Table 6 p.131 explicitly lists this taxon in the named group(s); printed and accepted names checked against WoRMS.
A7: Sardinella | B7: Sardinellas | C7: Small pelagics (<30 cm) | D7: Herring-likes | E7: Côtier pel S inv | H7: medium | I7: taxonomic_containment | J7: 9023480.2 | K7: 5.3822 | L7: Genus-level catch spans exactly the Table 6 groups containing its documented species. No habitat class overrides those placements.
A8: Engraulis encrasicolus | B8: European anchovy | C8: Small pelagics (<30 cm) | D8: Anchovies | E8: Côtier pel S inv | H8: high | I8: explicit_member | J8: 6169688.3 | K8: 3.68 | L8: Guénette & Diallo 2004 Table 6 p.131 explicitly lists this taxon in the named group(s); printed and accepted names checked against WoRMS.
A9: Pseudotolithus | B9: African croakers | C9: Large demersals (>=90 cm) | D9: Perch-likes | E9: Bars | H9: medium | I9: taxonomic_containment | J9: 5842799.4 | K9: 3.4851 | L9: Genus-level catch spans exactly the Table 6 groups containing its documented species. No habitat class overrides those placements.
A10: Sardinella aurita | B10: Round sardinella | C10: Small pelagics (<30 cm) | D10: Herring-likes | E10: Côtier pel S inv | H10: high | I10: explicit_member | J10: 4946271.9 | K10: 2.9503 | L10: Guénette & Diallo 2004 Table 6 p.131 explicitly lists this taxon in the named group(s); printed and accepted names checked against WoRMS.
A11: Cephalopoda | B11: Squids, cuttlefishes, octopuses | C11: Cephalopods | D11: Other fishes & inverts | E11: Céphalopodes | H11: high | I11: taxonomic_containment | J11: 4732809.6 | K11: 2.823 | L11: Source p.125 explicitly includes commercial and noncommercial octopus, cuttlefish and squid in the single cephalopod group.
A12: Brachydeuterus auritus | B12: Bigeye grunt | C12: Small demersals (<30 cm) | D12: Perch-likes | E12: Côtier S inv | H12: high | I12: explicit_member | J12: 3179416.6 | K12: 1.8964 | L12: Guénette & Diallo 2004 Table 6 p.131 explicitly lists this taxon in the named group(s); printed and accepted names checked against WoRMS.
A13: Trachurus | B13: Jacks, horse mackerels | C13: Medium pelagics (30 - 89 cm) | D13: Perch-likes | E13: Pel S inv | H13: medium | I13: taxonomic_containment | J13: 3069248.3 | K13: 1.8307 | L13: Genus-level catch spans exactly the Table 6 groups containing its documented species. No habitat class overrides those placements.
A14: Sardinella maderensis | B14: Madeiran sardinella | C14: Medium pelagics (30 - 89 cm) | D14: Herring-likes | E14: Côtier pel S inv | H14: high | I14: explicit_member | J14: 2712007.9 | K14: 1.6176 | L14: Guénette & Diallo 2004 Table 6 p.131 explicitly lists this taxon in the named group(s); printed and accepted names checked against WoRMS.
A15: Katsuwonus pelamis | B15: Skipjack tuna | C15: Large pelagics (>=90 cm) | D15: Tuna & billfishes | E15: Thons majeurs | H15: high | I15: explicit_member | J15: 2349951 | K15: 1.4017 | L15: Guénette & Diallo 2004 Table 6 p.131 explicitly lists this taxon in the named group(s); printed and accepted names checked against WoRMS.
A16: Thunnus albacares | B16: Yellowfin tuna | C16: Large pelagics (>=90 cm) | D16: Tuna & billfishes | E16: Thons majeurs | H16: high | I16: explicit_member | J16: 2303135.3 | K16: 1.3738 | L16: Guénette & Diallo 2004 Table 6 p.131 explicitly lists this taxon in the named group(s); printed and accepted names checked against WoRMS.
A17: Galeoides decadactylus | B17: Lesser African threadfin | C17: Medium demersals (30 - 89 cm) | D17: Perch-likes | E17: Petit capitaine | H17: high | I17: explicit_member | J17: 1937563.2 | K17: 1.1557 | L17: Guénette & Diallo 2004 Table 6 p.131 explicitly lists this taxon in the named group(s); printed and accepted names checked against WoRMS.
... A19: Sphyraena | B19: Barracudas, sennets | C19: Large pelagics (>=90 cm) | D19: Perch-likes | E19: Côtier pel L pred | H19: medium | I19: taxonomic_containment | J19: 1518406.7 | K19: 0.9057 | L19: Genus-level catch spans exactly the Table 6 groups containing its documented species. No habitat class overrides those placements.
A20: Clupeiformes | B20: Herrings, shads, anchovies | C20: Small pelagics (<30 cm) | D20: Other fishes & inverts | E20: Côtier pel S inv | Ethmalose | F20: 0.601 | 0.399 | G20: catch_composition | H20: medium | I20: composite_split | J20: 1518026.5 | K20: 0.9055 | L20: Anchovies, herrings/sardinellas and bonga occur in the coastal small-pelagic and named Ethmalose compartments in Table 6.
A21: Carangidae | B21: Jacks, pompanos | C21: Medium pelagics (30 - 89 cm) | D21: Perch-likes | E21: Côtier M pred | Côtier pel L pred | Pel L pred | Pel S inv | F21: 0.000 | 0.579 | 0.010 | 0.411 | G21: catch_composition | H21: medium | I21: composite_split | J21: 1450867.1 | K21: 0.8654 | L21: Family catch spans the union of all Table 6 member groups belonging to Carangidae under WoRMS. Every candidate is supported by a source member; source placement outranks SAU habitat class.
A22: Trichiurus lepturus | B22: Largehead hairtail | C22: Large benthopelagics (>=90 cm) | D22: Perch-likes | E22: Côtier L pred | H22: high | I22: explicit_member | J22: 1439530.7 | K22: 0.8586 | L22: Guénette & Diallo 2004 Table 6 p.131 explicitly lists this taxon in the named group(s); printed and accepted names checked against WoRMS.
A23: Sciaenidae | B23: Drums, croakers | C23: Medium demersals (30 - 89 cm) | D23: Perch-likes | E23: Bars | Côtier L pred | Côtier S pred | Dem L pred | Dem L inv | F23: 0.651 | 0.243 | 0.052 | 0.048 | 0.006 | G23: catch_composition | H23: medium | I23: composite_split | J23: 1420361.1 | K23: 0.8472 | L23: Table 6 explicitly separates Pseudotolithus (Bars), Argyrosomus (coastal large predators), Pteroscion (coastal small predators), Umbrina ronchus (demersal large predators), and U. canariensis (demersal large invertebrate feeders).
A24: Chloroscombrus chrysurus | B24: Atlantic bumper | C24: Medium pelagics (30 - 89 cm) | D24: Perch-likes | E24: Côtier pel L pred | H24: high | I24: explicit_member | J24: 1394161.2 | K24: 0.8316 | L24: Guénette & Diallo 2004 Table 6 p.131 explicitly lists this taxon in the named group(s); printed and accepted names checked against WoRMS.
A25: Sarotherodon melanotheron | B25: Blackchin tilapia | C25: Small demersals (<30 cm) | D25: Perch-likes | E25: Unresolved | H25: unresolved | I25: none | J25: 1133300.5 | K25: 0.676 | L25: Freshwater/brackish-water catch has no documented cichlid/cyprinid group in the offshore-Guinea source. Extending the named Mulets pool would require diet and habitat evidence for this taxon.
A26: Sepia | B26: Sepia cuttlefishes | C26: Cephalopods | D26: Other fishes & inverts | E26: Céphalopodes | H26: high | I26: taxonomic_containment | J26: 1128579.1 | K26: 0.6732 | L26: Source p.125 explicitly includes all cephalopods, including octopus, cuttlefish and squid.
A27: Clupeidae | B27: Herrings, sardines, menhadens | C27: Small pelagics (<30 cm) | D27: Herring-likes | E27: Côtier pel S inv | Ethmalose | F27: 0.601 | 0.399 | G27: catch_composition | H27: medium | I27: composite_split | J27: 1104199.7 | K27: 0.6586 | L27: Historical herring-family catch includes sardinellas and bonga. Table 6 separates Sardinella/Ilisha from Ethmalosa; current family-rank changes do not erase that commercial scope.
A28: Scombridae | B28: Mackerels, tunas, bonitos | C28: Medium pelagics (30 - 89 cm) | D28: Perch-likes | E28: Thons majeurs | Thons mineurs | Pel S inv | F28: 0.473 | 0.159 | 0.368 | G28: catch_composition | H28: medium | I28: composite_split | J28: 1005227.9 | K28: 0.5996 | L28: Table 6 places Thunnus/Katsuwonus in major tunas, other tuna/bonito and Spanish mackerel taxa in minor tunas, and Scomber in small offshore pelagics.
A29: Elasmobranchii | B29: Sharks, rays, skates | C29: Large sharks (>=90 cm) | D29: Sharks & rays | E29: Sélaciens L prof | Sélaciens L côtiers | Sélaciens M prof | Sélaciens M côtiers | F29: 0.731 | 0.091 | 0.172 | 0.006 | G29: catch_composition | H29: medium | I29: composite_split | J29: 911158.71 | K29: 0.5435 | L29: The class-level catch spans all four documented shark/ray size and depth groups in Table 6.
A30: Polydactylus quadrifilis | B30: Giant African threadfin | C30: Large demersals (>=90 cm) | D30: Perch-likes | E30: Gros capitaine | H30: high | I30: explicit_member | J30: 805152.37 | K30: 0.4802 | L30: Guénette & Diallo 2004 Table 6 p.131 explicitly lists this taxon in the named group(s); printed and accepted names checked against WoRMS.
A31: Thunnus obesus | B31: Bigeye tuna | C31: Large pelagics (>=90 cm) | D31: Tuna & billfishes | E31: Thons majeurs | H31: high | I31: explicit_member | J31: 788871.31 | K31: 0.4705 | L31: Guénette & Diallo 2004 Table 6 p.131 explicitly lists this taxon in the named group(s); printed and accepted names checked against WoRMS.
A32: Mugilidae | B32: Mullets, grey mullets | C32: Medium reef assoc. fish (30 - 89 cm) | D32: Perch-likes | E32: Dem M inv | Mulets | F32: 0.927 | 0.073 | G32: catch_composition | H32: medium | I32: composite_split | J32: 785745.88 | K32: 0.4687 | L32: Family catch spans the union of all Table 6 member groups belonging to Mugilidae under WoRMS. Every candidate is supported by a source member; source placement outranks SAU habitat class.
A33: Polynemidae | B33: Threadfins | C33: Small demersals (<30 cm) | D33: Perch-likes | E33: Gros capitaine | Petit capitaine | Capitaine royal | F33: 0.259 | 0.622 | 0.119 | G33: catch_composition | H33: medium | I33: composite_split | J33: 771085.96 | K33: 0.4599 | L33: Table 6 and Table 14 place the threadfins in three named capitaine stocks; source membership outranks the catch small-demersal label. Use period-wide identified-catch composition rather than Table 14's 1980s-specific assumed proportions.
A34: Balistidae | B34: Triggerfishes | C34: Medium reef assoc. fish (30 - 89 cm) | D34: Other fishes & inverts | E34: Dem M inv | H34: medium | I34: taxonomic_containment | J34: 736703.4 | K34: 0.4394 | L34: Family catch spans the union of all Table 6 member groups belonging to Balistidae under WoRMS. Every candidate is supported by a source member; source placement outranks SAU habitat class.
A35: Nematocarcinus africanus | B35: African spider shrimp | C35: Shrimps | D35: Crustaceans | E35: Crustacés | H35: high | I35: taxonomic_containment | J35: 736231.04 | K35: 0.4391 | L35: WoRMS crustacean taxonomy and SAU shrimp/crab/lobster class agree with the source Crustacés definition on p.125.
A36: Haemulidae | B36: Grunts, sweetlips, bonnetmouths | C36: Medium demersals (30 - 89 cm) | D36: Perch-likes | E36: Côtier M inv | Côtier S inv | Dem M inv | F36: 0.359 | 0.410 | 0.231 | G36: catch_composition | H36: medium | I36: composite_split | J36: 731597.71 | K36: 0.4364 | L36: Family catch spans the union of all Table 6 member groups belonging to Haemulidae under WoRMS. Every candidate is supported by a source member; source placement outranks SAU habitat class.
A37: Cynoglossus | B37: Tonguesoles | C37: Small to medium flatfishes (<90 cm) | D37: Flatfishes | E37: Côtier M inv | H37: medium | I37: taxonomic_containment | J37: 718318.29 | K37: 0.4285 | L37: Genus-level catch spans exactly the Table 6 groups containing its documented species. No habitat class overrides those placements.
A38: Ilisha africana | B38: West African ilisha | C38: Medium pelagics (30 - 89 cm) | D38: Herring-likes | E38: Côtier pel S inv | H38: high | I38: explicit_member | J38: 715365.88 | K38: 0.4267 | L38: Guénette & Diallo 2004 Table 6 p.131 explicitly lists this taxon in the named group(s); printed and accepted names checked against WoRMS.
A39: Lutjanidae | B39: Snappers | C39: Medium reef assoc. fish (30 - 89 cm) | D39: Perch-likes | E39: Côtier L pred | H39: medium | I39: taxonomic_containment | J39: 701348.54 | K39: 0.4183 | L39: Family catch spans the union of all Table 6 member groups belonging to Lutjanidae under WoRMS. Every candidate is supported by a source member; source placement outranks SAU habitat class.
A40: Cynoglossus monodi | B40: Guinean tonguesole | C40: Small to medium flatfishes (<90 cm) | D40: Flatfishes | E40: Côtier M inv | H40: high | I40: explicit_member | J40: 697298.16 | K40: 0.4159 | L40: Guénette & Diallo 2004 Table 6 p.131 explicitly lists this taxon in the named group(s); printed and accepted names checked against WoRMS.
A41: Rachycentron canadum | B41: Cobia | C41: Large pelagics (>=90 cm) | D41: Perch-likes | E41: Côtier pel L pred | H41: high | I41: explicit_member | J41: 677083.23 | K41: 0.4039 | L41: Guénette & Diallo 2004 Table 6 p.131 explicitly lists this taxon in the named group(s); printed and accepted names checked against WoRMS.
A42: Perciformes | B42: Perch-likes | C42: Medium demersals (30 - 89 cm) | D42: Perch-likes | E42: Côtier L pred | Côtier M pred | Disques | Côtier M inv | Côtier S pred | Côtier S inv | Dem L pred | Dem L inv | Dem M pred | Dem M inv | Dem S pred | Dem S inv | F42: 0.234 | 0.000 | 0.021 | 0.227 | 0.049 | 0.259 | 0.046 | 0.006 | 0.011 | 0.146 | 0.000 | 0.001 | G42: catch_composition | H42: low | I42: composite_split | J42: 663130.92 | K42: 0.3955 | L42: Historical perch-like catch in the medium-demersal class spans coastal/shelf guilds with Table 6 perch-like representatives. Ariid catfish and mullet stocks are excluded. Each remaining generic group contains a documented perch-like member; no named single-stock group is added.
...

Sheet Final mappings
A1: Final taxon-to-group mappings, identified separately for each Ecopath model
A2: One row per taxon/group assignment; numeric weights are the exact values used to calculate SPPR.
A3: Unresolved taxa retain a row with a blank weight. Catch tonnes repeat across a taxon's assignments; do not sum these rows.
A4: unit_id | B4: model_id | C4: taxon | D4: common_name | E4: SAU functional group | F4: SAU commercial group | G4: group | H4: weight | I4: weight_basis | J4: confidence | K4: evidence | L4: explanation | M4: catch_tonnes
A5: LME_028 | B5: 28_646_Guinea_(1998) | C5: Marine fishes not identified | D5: Marine fishes nei | E5: Medium demersals (30 - 89 cm) | F5: Other fishes & inverts | G5: Côtier L pred | H5: 0.23885844 | I5: catch_composition | J5: low | K5: composite_split | L5: Medium-demersal unidentified catch is restricted to broad coastal (<40 m) and shelf demersal (20-200 m) fish guilds, with adjacent sizes. Named single-stock groups, pelagic pools and bathyal pools are excluded. Source p.128 describes overlapping coastal/shelf habitats; this is a wide estimated allocation. | M5: 54105502
A6: LME_028 | B6: 28_646_Guinea_(1998) | C6: Marine fishes not identified | D6: Marine fishes nei | E6: Medium demersals (30 - 89 cm) | F6: Other fishes & inverts | G6: Côtier M pred | H6: 4.1966571e-05 | I6: catch_composition | J6: low | K6: composite_split | L6: Medium-demersal unidentified catch is restricted to broad coastal (<40 m) and shelf demersal (20-200 m) fish guilds, with adjacent sizes. Named single-stock groups, pelagic pools and bathyal pools are excluded. Source p.128 describes overlapping coastal/shelf habitats; this is a wide estimated allocation. | M6: 54105502
A7: LME_028 | B7: 28_646_Guinea_(1998) | C7: Marine fishes not identified | D7: Marine fishes nei | E7: Medium demersals (30 - 89 cm) | F7: Other fishes & inverts | G7: Côtier M inv | H7: 0.2316287 | I7: catch_composition | J7: low | K7: composite_split | L7: Medium-demersal unidentified catch is restricted to broad coastal (<40 m) and shelf demersal (20-200 m) fish guilds, with adjacent sizes. Named single-stock groups, pelagic pools and bathyal pools are excluded. Source p.128 describes overlapping coastal/shelf habitats; this is a wide estimated allocation. | M7: 54105502
A8: LME_028 | B8: 28_646_Guinea_(1998) | C8: Marine fishes not identified | D8: Marine fishes nei | E8: Medium demersals (30 - 89 cm) | F8: Other fishes & inverts | G8: Côtier S pred | H8: 0.050709663 | I8: catch_composition | J8: low | K8: composite_split | L8: Medium-demersal unidentified catch is restricted to broad coastal (<40 m) and shelf demersal (20-200 m) fish guilds, with adjacent sizes. Named single-stock groups, pelagic pools and bathyal pools are excluded. Source p.128 describes overlapping coastal/shelf habitats; this is a wide estimated allocation. | M8: 54105502
A9: LME_028 | B9: 28_646_Guinea_(1998) | C9: Marine fishes not identified | D9: Marine fishes nei | E9: Medium demersals (30 - 89 cm) | F9: Other fishes & inverts | G9: Côtier S inv | H9: 0.26434562 | I9: catch_composition | J9: low | K9: composite_split | L9: Medium-demersal unidentified catch is restricted to broad coastal (<40 m) and shelf demersal (20-200 m) fish guilds, with adjacent sizes. Named single-stock groups, pelagic pools and bathyal pools are excluded. Source p.128 describes overlapping coastal/shelf habitats; this is a wide estimated allocation. | M9: 54105502
A10: LME_028 | B10: 28_646_Guinea_(1998) | C10: Marine fishes not identified | D10: Marine fishes nei | E10: Medium demersals (30 - 89 cm) | F10: Other fishes & inverts | G10: Dem L pred | H10: 0.046638601 | I10: catch_composition | J10: low | K10: composite_split | L10: Medium-demersal unidentified catch is restricted to broad coastal (<40 m) and shelf demersal (20-200 m) fish guilds, with adjacent sizes. Named single-stock groups, pelagic pools and bathyal pools are excluded. Source p.128 describes overlapping coastal/shelf habitats; this is a wide estimated allocation. | M10: 54105502
A11: LME_028 | B11: 28_646_Guinea_(1998) | C11: Marine fishes not identified | D11: Marine fishes nei | E11: Medium demersals (30 - 89 cm) | F11: Other fishes & inverts | G11: Dem L inv | H11: 0.0062167124 | I11: catch_composition | J11: low | K11: composite_split | L11: Medium-demersal unidentified catch is restricted to broad coastal (<40 m) and shelf demersal (20-200 m) fish guilds, with adjacent sizes. Named single-stock groups, pelagic pools and bathyal pools are excluded. Source p.128 describes overlapping coastal/shelf habitats; this is a wide estimated allocation. | M11: 54105502
A12: LME_028 | B12: 28_646_Guinea_(1998) | C12: Marine fishes not identified | D12: Marine fishes nei | E12: Medium demersals (30 - 89 cm) | F12: Other fishes & inverts | G12: Dem M pred | H12: 0.011789032 | I12: catch_composition | J12: low | K12: composite_split | L12: Medium-demersal unidentified catch is restricted to broad coastal (<40 m) and shelf demersal (20-200 m) fish guilds, with adjacent sizes. Named single-stock groups, pelagic pools and bathyal pools are excluded. Source p.128 describes overlapping coastal/shelf habitats; this is a wide estimated allocation. | M12: 54105502
A13: LME_028 | B13: 28_646_Guinea_(1998) | C13: Marine fishes not identified | D13: Marine fishes nei | E13: Medium demersals (30 - 89 cm) | F13: Other fishes & inverts | G13: Dem M inv | H13: 0.14890924 | I13: catch_composition | J13: low | K13: composite_split | L13: Medium-demersal unidentified catch is restricted to broad coastal (<40 m) and shelf demersal (20-200 m) fish guilds, with adjacent sizes. Named single-stock groups, pelagic pools and bathyal pools are excluded. Source p.128 describes overlapping coastal/shelf habitats; this is a wide estimated allocation. | M13: 54105502
A14: LME_028 | B14: 28_646_Guinea_(1998) | C14: Marine fishes not identified | D14: Marine fishes nei | E14: Medium demersals (30 - 89 cm) | F14: Other fishes & inverts | G14: Dem S pred | H14: 2.4192106e-05 | I14: catch_composition | J14: low | K14: composite_split | L14: Medium-demersal unidentified catch is restricted to broad coastal (<40 m) and shelf demersal (20-200 m) fish guilds, with adjacent sizes. Named single-stock groups, pelagic pools and bathyal pools are excluded. Source p.128 describes overlapping coastal/shelf habitats; this is a wide estimated allocation. | M14: 54105502
A15: LME_028 | B15: 28_646_Guinea_(1998) | C15: Marine fishes not identified | D15: Marine fishes nei | E15: Medium demersals (30 - 89 cm) | F15: Other fishes & inverts | G15: Dem S inv | H15: 0.0008378251 | I15: catch_composition | J15: low | K15: composite_split | L15: Medium-demersal unidentified catch is restricted to broad coastal (<40 m) and shelf demersal (20-200 m) fish guilds, with adjacent sizes. Named single-stock groups, pelagic pools and bathyal pools are excluded. Source p.128 describes overlapping coastal/shelf habitats; this is a wide estimated allocation. | M15: 54105502
A16: LME_028 | B16: 28_646_Guinea_(1998) | C16: Ethmalosa fimbriata | D16: Bonga shad | E16: Medium pelagics (30 - 89 cm) | F16: Herring-likes | G16: Ethmalose | H16: 1 | I16: single | J16: high | K16: explicit_member | L16: Guénette & Diallo 2004 Table 6 p.131 explicitly lists this taxon in the named group(s); printed and accepted names checked against WoRMS. | M16: 16059854
... A42: LME_028 | B42: 28_646_Guinea_(1998) | C42: Chloroscombrus chrysurus | D42: Atlantic bumper | E42: Medium pelagics (30 - 89 cm) | F42: Perch-likes | G42: Côtier pel L pred | H42: 1 | I42: single | J42: high | K42: explicit_member | L42: Guénette & Diallo 2004 Table 6 p.131 explicitly lists this taxon in the named group(s); printed and accepted names checked against WoRMS. | M42: 1394161.2
A43: LME_028 | B43: 28_646_Guinea_(1998) | C43: Sarotherodon melanotheron | D43: Blackchin tilapia | E43: Small demersals (<30 cm) | F43: Perch-likes | G43: Unresolved | J43: unresolved | K43: none | L43: Freshwater/brackish-water catch has no documented cichlid/cyprinid group in the offshore-Guinea source. Extending the named Mulets pool would require diet and habitat evidence for this taxon. | M43: 1133300.5
A44: LME_028 | B44: 28_646_Guinea_(1998) | C44: Sepia | D44: Sepia cuttlefishes | E44: Cephalopods | F44: Other fishes & inverts | G44: Céphalopodes | H44: 1 | I44: single | J44: high | K44: taxonomic_containment | L44: Source p.125 explicitly includes all cephalopods, including octopus, cuttlefish and squid. | M44: 1128579.1
A45: LME_028 | B45: 28_646_Guinea_(1998) | C45: Clupeidae | D45: Herrings, sardines, menhadens | E45: Small pelagics (<30 cm) | F45: Herring-likes | G45: Côtier pel S inv | H45: 0.60118214 | I45: catch_composition | J45: medium | K45: composite_split | L45: Historical herring-family catch includes sardinellas and bonga. Table 6 separates Sardinella/Ilisha from Ethmalosa; current family-rank changes do not erase that commercial scope. | M45: 1104199.7
A46: LME_028 | B46: 28_646_Guinea_(1998) | C46: Clupeidae | D46: Herrings, sardines, menhadens | E46: Small pelagics (<30 cm) | F46: Herring-likes | G46: Ethmalose | H46: 0.39881786 | I46: catch_composition | J46: medium | K46: composite_split | L46: Historical herring-family catch includes sardinellas and bonga. Table 6 separates Sardinella/Ilisha from Ethmalosa; current family-rank changes do not erase that commercial scope. | M46: 1104199.7
A47: LME_028 | B47: 28_646_Guinea_(1998) | C47: Scombridae | D47: Mackerels, tunas, bonitos | E47: Medium pelagics (30 - 89 cm) | F47: Perch-likes | G47: Thons majeurs | H47: 0.47297039 | I47: catch_composition | J47: medium | K47: composite_split | L47: Table 6 places Thunnus/Katsuwonus in major tunas, other tuna/bonito and Spanish mackerel taxa in minor tunas, and Scomber in small offshore pelagics. | M47: 1005227.9
A48: LME_028 | B48: 28_646_Guinea_(1998) | C48: Scombridae | D48: Mackerels, tunas, bonitos | E48: Medium pelagics (30 - 89 cm) | F48: Perch-likes | G48: Thons mineurs | H48: 0.158603 | I48: catch_composition | J48: medium | K48: composite_split | L48: Table 6 places Thunnus/Katsuwonus in major tunas, other tuna/bonito and Spanish mackerel taxa in minor tunas, and Scomber in small offshore pelagics. | M48: 1005227.9
A49: LME_028 | B49: 28_646_Guinea_(1998) | C49: Scombridae | D49: Mackerels, tunas, bonitos | E49: Medium pelagics (30 - 89 cm) | F49: Perch-likes | G49: Pel S inv | H49: 0.36842661 | I49: catch_composition | J49: medium | K49: composite_split | L49: Table 6 places Thunnus/Katsuwonus in major tunas, other tuna/bonito and Spanish mackerel taxa in minor tunas, and Scomber in small offshore pelagics. | M49: 1005227.9
A50: LME_028 | B50: 28_646_Guinea_(1998) | C50: Elasmobranchii | D50: Sharks, rays, skates | E50: Large sharks (>=90 cm) | F50: Sharks & rays | G50: Sélaciens L prof | H50: 0.73111135 | I50: catch_composition | J50: medium | K50: composite_split | L50: The class-level catch spans all four documented shark/ray size and depth groups in Table 6. | M50: 911158.71
A51: LME_028 | B51: 28_646_Guinea_(1998) | C51: Elasmobranchii | D51: Sharks, rays, skates | E51: Large sharks (>=90 cm) | F51: Sharks & rays | G51: Sélaciens L côtiers | H51: 0.090693635 | I51: catch_composition | J51: medium | K51: composite_split | L51: The class-level catch spans all four documented shark/ray size and depth groups in Table 6. | M51: 911158.71
A52: LME_028 | B52: 28_646_Guinea_(1998) | C52: Elasmobranchii | D52: Sharks, rays, skates | E52: Large sharks (>=90 cm) | F52: Sharks & rays | G52: Sélaciens M prof | H52: 0.17180123 | I52: catch_composition | J52: medium | K52: composite_split | L52: The class-level catch spans all four documented shark/ray size and depth groups in Table 6. | M52: 911158.71
A53: LME_028 | B53: 28_646_Guinea_(1998) | C53: Elasmobranchii | D53: Sharks, rays, skates | E53: Large sharks (>=90 cm) | F53: Sharks & rays | G53: Sélaciens M côtiers | H53: 0.0063937807 | I53: catch_composition | J53: medium | K53: composite_split | L53: The class-level catch spans all four documented shark/ray size and depth groups in Table 6. | M53: 911158.71
A54: LME_028 | B54: 28_646_Guinea_(1998) | C54: Polydactylus quadrifilis | D54: Giant African threadfin | E54: Large demersals (>=90 cm) | F54: Perch-likes | G54: Gros capitaine | H54: 1 | I54: single | J54: high | K54: explicit_member | L54: Guénette & Diallo 2004 Table 6 p.131 explicitly lists this taxon in the named group(s); printed and accepted names checked against WoRMS. | M54: 805152.37
A55: LME_028 | B55: 28_646_Guinea_(1998) | C55: Thunnus obesus | D55: Bigeye tuna | E55: Large pelagics (>=90 cm) | F55: Tuna & billfishes | G55: Thons majeurs | H55: 1 | I55: single | J55: high | K55: explicit_member | L55: Guénette & Diallo 2004 Table 6 p.131 explicitly lists this taxon in the named group(s); printed and accepted names checked against WoRMS. | M55: 788871.31
... A111: LME_028 | B111: 28_646_Guinea_(1998) | C111: Pteroscion peli | D111: Boe drum | E111: Medium benthopelagics (30 - 89 cm) | F111: Perch-likes | G111: Côtier S pred | H111: 1 | I111: single | J111: high | K111: explicit_member | L111: Guénette & Diallo 2004 Table 6 p.131 explicitly lists this taxon in the named group(s); printed and accepted names checked against WoRMS. | M111: 422411.1
A112: LME_028 | B112: 28_646_Guinea_(1998) | C112: Sarotherodon galilaeus | D112: Mango tilapia | E112: Large reef assoc. fish (>=90 cm) | F112: Perch-likes | G112: Unresolved | J112: unresolved | K112: none | L112: Freshwater/brackish-water catch has no documented cichlid/cyprinid group in the offshore-Guinea source. Extending the named Mulets pool would require diet and habitat evidence for this taxon. | M112: 405273.31
A113: LME_028 | B113: 28_646_Guinea_(1998) | C113: Pseudotolithus senegalensis | D113: Cassava croaker | E113: Large demersals (>=90 cm) | F113: Perch-likes | G113: Bars | H113: 1 | I113: single | J113: high | K113: explicit_member | L113: Guénette & Diallo 2004 Table 6 p.131 explicitly lists this taxon in the named group(s); printed and accepted names checked against WoRMS. | M113: 403396.24
A114: LME_028 | B114: 28_646_Guinea_(1998) | C114: Parapenaeus longirostris | D114: Deepwater rose shrimp | E114: Shrimps | F114: Crustaceans | G114: Crustacés | H114: 1 | I114: single | J114: high | K114: taxonomic_containment | L114: WoRMS crustacean taxonomy and SAU shrimp/crab/lobster class agree with the source Crustacés definition on p.125. | M114: 400810.41
A115: LME_028 | B115: 28_646_Guinea_(1998) | C115: Caranx hippos | D115: Crevalle jack | E115: Large reef assoc. fish (>=90 cm) | F115: Perch-likes | G115: Côtier pel L pred | H115: 1 | I115: single | J115: high | K115: explicit_member | L115: Guénette & Diallo 2004 Table 6 p.131 explicitly lists this taxon in the named group(s); printed and accepted names checked against WoRMS. | M115: 391862.7
A116: LME_028 | B116: 28_646_Guinea_(1998) | C116: Marine pelagic fishes not identified | D116: Pelagic fishes | E116: Medium pelagics (30 - 89 cm) | F116: Other fishes & inverts | G116: Côtier pel L pred | H116: 0.18925749 | I116: catch_composition | J116: low | K116: composite_split | L116: Pelagic nei is restricted to broad coastal and offshore pelagic pools. Named tuna/ethmalose stocks and bottom/bathyal groups are excluded. | M116: 388990.86
A117: LME_028 | B117: 28_646_Guinea_(1998) | C117: Marine pelagic fishes not identified | D117: Pelagic fishes | E117: Medium pelagics (30 - 89 cm) | F117: Other fishes & inverts | G117: Côtier pel S inv | H117: 0.67317977 | I117: catch_composition | J117: low | K117: composite_split | L117: Pelagic nei is restricted to broad coastal and offshore pelagic pools. Named tuna/ethmalose stocks and bottom/bathyal groups are excluded. | M117: 388990.86
A118: LME_028 | B118: 28_646_Guinea_(1998) | C118: Marine pelagic fishes not identified | D118: Pelagic fishes | E118: Medium pelagics (30 - 89 cm) | F118: Other fishes & inverts | G118: Pel L pred | H118: 0.003204333 | I118: catch_composition | J118: low | K118: composite_split | L118: Pelagic nei is restricted to broad coastal and offshore pelagic pools. Named tuna/ethmalose stocks and bottom/bathyal groups are excluded. | M118: 388990.86
A119: LME_028 | B119: 28_646_Guinea_(1998) | C119: Marine pelagic fishes not identified | D119: Pelagic fishes | E119: Medium pelagics (30 - 89 cm) | F119: Other fishes & inverts | G119: Pel S inv | H119: 0.13435841 | I119: catch_composition | J119: low | K119: composite_split | L119: Pelagic nei is restricted to broad coastal and offshore pelagic pools. Named tuna/ethmalose stocks and bottom/bathyal groups are excluded. | M119: 388990.86
A120: LME_028 | B120: 28_646_Guinea_(1998) | C120: Pentheroscion mbizi | D120: Mbizi croaker | E120: Medium demersals (30 - 89 cm) | F120: Perch-likes | G120: Unresolved | J120: unresolved | K120: none | L120: This taxon is absent from Table 6 and lacks a unique documented guild/depth placement. A family or genus analogue may span several groups; habitat class alone cannot select the feeding guild. | M120: 372671.57
...

Sheet SPPR
A1: Specific PPR per taxon — LME_028, model 28_646_Guinea_(1998)
A2: sppr_simple is the trophic-chain estimate (1/TE)^(TL-1) at TE=0.1, applied to the taxon's own trophic level and needing no model.
A3: All basal sources, including imports. Blank means unavailable, not zero. sppr_simple is an unpartitioned reference.
A4: taxon | B4: trophic_level | C4: sppr_simple | D4: Ecopath group | E4: SPPR_1986 | F4: SPPR_1995_TE0.1 | G4: SPPR_1995_TEmean | H4: Ulanowicz_globalTEmean | I4: Ulanowicz_TE | J4: EwE_TE_noEE | K4: EwE_TE_EE | L4: SPPR_2015 | M4: new_TE_noEEfix | N4: new_TE_EEfix | O4: new_GE | P4: new_WithEgestion | Q4: sym_TE_asPP | R4: sym_TE_asDC | S4: sym_GE_asPP | T4: sym_GE_asDC | U4: sym_WithEgestion_asPP | V4: sym_WithEgestion_asDC | W4: MC_new_GE | X4: MC_new_TE_EEfix | Y4: SPPR_1995_TEmean_catch | Z4: Ulanowicz_globalTEmean_catch
A5: Marine fishes not identified | B5: 3.28 | C5: 190.54607 | D5: Côtier L pred | Côtier M pred | Côtier M inv | Côtier S pred | Côtier S inv | Dem L pred | Dem L inv | Dem M pred | Dem M inv | Dem S pred | Dem S inv | E5: 163.76577 | F5: 357.27432 | G5: 340.93336 | H5: 2733.0289 | I5: 1872.0884 | J5: 2944.6808 | K5: 2569.8387 | L5: 5569.7199 | M5: 5569.7199 | N5: 5569.7199 | O5: 2133.113 | P5: 753.31459 | Q5: 5569.7199 | R5: -19300.865 | S5: 2133.113 | T5: 2134.8825 | U5: 753.31459 | V5: -115006.95 | W5: 2350.8878 | X5: 6003.2923 | Y5: 209.62671 | Z5: 1161.3812
A6: Ethmalosa fimbriata | B6: 2.5 | C6: 31.622777 | D6: Ethmalose | E6: 163.76577 | F6: 32.757151 | G6: 31.91145 | H6: 65.818434 | I6: 85.31189 | J6: 85.31189 | K6: 81.046295 | L6: 91.491097 | M6: 91.491097 | N6: 91.491097 | O6: 73.367465 | P6: 43.161455 | Q6: 91.491097 | R6: 91.491097 | S6: 73.367465 | T6: 73.377987 | U6: 43.161455 | V6: -338.70528 | W6: 77.445951 | X6: 95.672556 | Y6: 24.291412 | Z6: 44.953839
A7: Sardinella | B7: 2.77 | C7: 58.884366 | D7: Côtier pel S inv | E7: 163.76577 | F7: 63.371783 | G7: 61.431046 | H7: 318.70905 | I7: 117.87126 | J7: 118.15177 | K7: 106.83023 | L7: 182.67852 | M7: 182.67852 | N7: 182.67852 | O7: 118.78705 | P7: 55.817264 | Q7: 182.67852 | R7: 182.67857 | S7: 118.78705 | T7: 118.80517 | U7: 55.817264 | V7: -489.07736 | W7: 128.84765 | X7: 189.69072 | Y7: 44.410268 | Z7: 180.28213
A8: Engraulis encrasicolus | B8: 3.11 | C8: 128.82495 | D8: Côtier pel S inv | E8: 163.76577 | F8: 63.371783 | G8: 61.431046 | H8: 318.70905 | I8: 117.87126 | J8: 118.15177 | K8: 106.83023 | L8: 182.67852 | M8: 182.67852 | N8: 182.67852 | O8: 118.78705 | P8: 55.817264 | Q8: 182.67852 | R8: 182.67857 | S8: 118.78705 | T8: 118.80517 | U8: 55.817264 | V8: -489.07736 | W8: 128.84765 | X8: 189.69072 | Y8: 44.410268 | Z8: 180.28213
A9: Pseudotolithus | B9: 3.79 | C9: 616.595 | D9: Bars | E9: 163.76577 | F9: 765.12621 | G9: 727.97256 | H9: 3298.268 | I9: 1392.3666 | J9: 1698.4222 | K9: 1593.2962 | L9: 2935.678 | M9: 2935.678 | N9: 2935.678 | O9: 1750.5603 | P9: 663.60855 | Q9: 2935.678 | R9: -12167.664 | S9: 1750.5603 | T9: 1751.3114 | U9: 663.60855 | V9: -129143.72 | W9: 1958.6858 | X9: 3084.9171 | Y9: 433.12482 | Z9: 1494.315
A10: Sardinella aurita | B10: 3.4 | C10: 251.18864 | D10: Côtier pel S inv | E10: 163.76577 | F10: 63.371783 | G10: 61.431046 | H10: 318.70905 | I10: 117.87126 | J10: 118.15177 | K10: 106.83023 | L10: 182.67852 | M10: 182.67852 | N10: 182.67852 | O10: 118.78705 | P10: 55.817264 | Q10: 182.67852 | R10: 182.67857 | S10: 118.78705 | T10: 118.80517 | U10: 55.817264 | V10: -489.07736 | W10: 128.84765 | X10: 189.69072 | Y10: 44.410268 | Z10: 180.28213
A11: Cephalopoda | B11: 3.81 | C11: 645.65423 | D11: Céphalopodes | E11: 163.76577 | F11: 822.92693 | G11: 782.5392 | H11: 2911.8736 | I11: 776.13375 | J11: 776.13375 | K11: 737.32706 | L11: 1169.0624 | M11: 1169.0624 | N11: 1169.0624 | O11: 633.53273 | P11: 262.848 | Q11: 1169.0624 | R11: 1169.1261 | S11: 633.53273 | T11: 633.69043 | U11: 262.848 | V11: -2693.9774 | W11: 696.07488 | X11: 1245.601 | Y11: 462.94661 | Z11: 1388.4758
A12: Brachydeuterus auritus | B12: 3.03 | C12: 107.15193 | D12: Côtier S inv | E12: 163.76577 | F12: 79.510256 | G12: 76.944312 | H12: 373.18042 | I12: 228.22673 | J12: 228.83034 | K12: 223.01936 | L12: 302.46033 | M12: 302.46033 | N12: 302.46033 | O12: 244.22608 | P12: 127.65942 | Q12: 302.46033 | R12: 303.40073 | S12: 244.22608 | T12: 245.02594 | U12: 127.65942 | V12: -1352.0642 | W12: 266.01382 | X12: 316.47961 | Y12: 54.647132 | Z12: 203.05019
A13: Trachurus | B13: 3.69 | C13: 489.77882 | D13: Pel S inv | E13: 163.76577 | F13: 157.97086 | G13: 152.0881 | H13: 577.27166 | I13: 239.81024 | J13: 250.6317 | K13: 247.59703 | L13: 317.63086 | M13: 317.63086 | N13: 317.63086 | O13: 109.89232 | P13: 46.754763 | Q13: 317.63086 | R13: 317.63245 | S13: 109.89232 | T13: 109.90468 | U13: 46.754763 | V13: -281.1473 | W13: 116.06651 | X13: 339.62288 | Y13: 102.36962 | Z13: 312.79001
A14: Sardinella maderensis | B14: 3.2 | C14: 158.48932 | D14: Côtier pel S inv | E14: 163.76577 | F14: 63.371783 | G14: 61.431046 | H14: 318.70905 | I14: 117.87126 | J14: 118.15177 | K14: 106.83023 | L14: 182.67852 | M14: 182.67852 | N14: 182.67852 | O14: 118.78705 | P14: 55.817264 | Q14: 182.67852 | R14: 182.67857 | S14: 118.78705 | T14: 118.80517 | U14: 55.817264 | V14: -489.07736 | W14: 128.84765 | X14: 189.69072 | Y14: 44.410268 | Z14: 180.28213
A15: Katsuwonus pelamis | B15: 4.43 | C15: 2691.5348 | D15: Thons majeurs | E15: 163.76577 | F15: 2736.4228 | G15: 2578.7911 | H15: 17894.358 | I15: 8524.6617 | J15: 8877.0948 | K15: 4438.5474 | L15: 13559.459 | M15: 13559.459 | N15: 13559.459 | O15: 3620.8764 | P15: 1183.5978 | Q15: 13559.459 | R15: -35797.7 | S15: 3620.8764 | T15: 3622.2343 | U15: 1183.5978 | V15: -69439.827 | W15: 4014.2071 | X15: 14860.336 | Y15: 1388.7868 | Z15: 6982.2622
A16: Thunnus albacares | B16: 4.41 | C16: 2570.3958 | D16: Thons majeurs | E16: 163.76577 | F16: 2736.4228 | G16: 2578.7911 | H16: 17894.358 | I16: 8524.6617 | J16: 8877.0948 | K16: 4438.5474 | L16: 13559.459 | M16: 13559.459 | N16: 13559.459 | O16: 3620.8764 | P16: 1183.5978 | Q16: 13559.459 | R16: -35797.7 | S16: 3620.8764 | T16: 3622.2343 | U16: 1183.5978 | V16: -69439.827 | W16: 4014.2071 | X16: 14860.336 | Y16: 1388.7868 | Z16: 6982.2622
... A24: Chloroscombrus chrysurus | B24: 3.54 | C24: 346.73685 | D24: Côtier pel L pred | E24: 163.76577 | F24: 1052.5579 | G24: 999.05539 | H24: 11777.424 | I24: 6532.7765 | J24: 7781.6303 | K24: 7457.9507 | L24: 14096.896 | M24: 14096.896 | N24: 14096.896 | O24: 6109.5785 | P24: 1921.9564 | Q24: 14096.896 | R24: -57719.913 | S24: 6109.5785 | T24: 6113.693 | U24: 1921.9564 | V24: -289813.59 | W24: 6783.1589 | X24: 15274.307 | Y24: 579.77062 | Z24: 4535.5492
A25: Sarotherodon melanotheron | B25: 2.23 | C25: 16.982437 | D25: Unresolved
A26: Sepia | B26: 3.69 | C26: 489.77882 | D26: Céphalopodes | E26: 163.76577 | F26: 822.92693 | G26: 782.5392 | H26: 2911.8736 | I26: 776.13375 | J26: 776.13375 | K26: 737.32706 | L26: 1169.0624 | M26: 1169.0624 | N26: 1169.0624 | O26: 633.53273 | P26: 262.848 | Q26: 1169.0624 | R26: 1169.1261 | S26: 633.53273 | T26: 633.69043 | U26: 262.848 | V26: -2693.9774 | W26: 696.07488 | X26: 1245.601 | Y26: 462.94661 | Z26: 1388.4758
A27: Clupeidae | B27: 3.16 | C27: 144.54398 | D27: Côtier pel S inv | Ethmalose | E27: 163.76577 | F27: 51.162121 | G27: 49.658104 | H27: 217.85175 | I27: 104.886 | J27: 105.05464 | K27: 96.547134 | L27: 146.31135 | M27: 146.31135 | N27: 146.31135 | O27: 100.67291 | P27: 50.769901 | Q27: 146.31135 | R27: 146.31138 | S27: 100.67291 | T27: 100.688 | U27: 50.769901 | V27: -429.10629 | W27: 108.34773 | X27: 152.19459 | Y27: 36.386509 | Z27: 126.31079
A28: Scombridae | B28: 4.26 | C28: 1819.7009 | D28: Thons majeurs | Thons mineurs | Pel S inv | E28: 163.76577 | F28: 1573.7995 | G28: 1485.3816 | H28: 10141.899 | I28: 4590.5367 | J28: 4766.4054 | K28: 2464.48 | L28: 7208.8607 | M28: 7208.8607 | N28: 7208.8607 | O28: 1977.2569 | P28: 659.01846 | Q28: 7208.8607 | R28: -16135.456 | S28: 1977.2569 | T28: 1978.0136 | U28: 659.01846 | V28: -33765.373 | W28: 2187.8562 | X28: 7875.2841 | Y28: 813.5835 | Z28: 4029.8871
A29: Elasmobranchii | B29: 4.05 | C29: 1122.0185 | D29: Sélaciens L prof | Sélaciens L côtiers | Sélaciens M prof | Sélaciens M côtiers | E29: 163.76577 | F29: 2769.4595 | G29: 2609.2348 | H29: 29837.846 | I29: 101657.72 | J29: 104398.13 | K29: 54134.586 | L29: 481965.93 | M29: 481965.93 | N29: 481965.93 | O29: 42015.217 | P29: 10784.021 | Q29: 481965.93 | R29: -1054779 | S29: 42015.217 | T29: 42036.176 | U29: 10784.021 | V29: -804951.62 | W29: 47810.819 | X29: 582150.57 | Y29: 1401.4805 | Z29: 10590.21
A30: Polydactylus quadrifilis | B30: 4.01 | C30: 1023.293 | D30: Gros capitaine | E30: 163.76577 | F30: 1068.4537 | G30: 1014.0292 | H30: 8964.8175 | I30: 3381.1375 | J30: 3383.3127 | K30: 3347.1221 | L30: 4619.757 | M30: 4619.757 | N30: 4619.757 | O30: 3278.3664 | P30: 1130.3298 | Q30: 4619.757 | R30: -489404.94 | S30: 3278.3664 | T30: 3280.8043 | U30: 1130.3298 | V30: -1276978.3 | W30: 3567.7246 | X30: 4954.2336 | Y30: 587.77086 | Z30: 3503.6101
