Workbook

Sheet Summary
A1: LME_047 — East China Sea
A2: Ecopath model: 47_1_East_China_Sea_(1997)
A3: `47_1_East_China_Sea_(1997)` — mapping notes
A5: region type | B5: LME
A6: latitude | B6: 29.9554
A7: longitude | B7: 123.82371
A8: catch years | B8: 1950-2019
A9: taxa in catch | B9: 276
A10: taxa apportioned across groups | B10: 21
A11: taxa unresolved | B11: 2
A12: catch tonnage on a named group, % | B12: 100
A13: SPPR methods | B13: 20
A14: methods flagged as unusable | B14: 1
A15: headline method below | B15: new_TE_EEfix
A17: year | B17: catch_tonnes | C17: ppr_simple | D17: ppr_new_TE_EEfix | E17: ppr_simple / NPP % | F17: ppr_new_TE_EEfix / NPP %
A18: 1950 | B18: 1156011.3 | C18: 6.4809035e+08 | D18: 7.2277718e+08 | E18: 283.1457 | F18: 315.7758
A19: 1951 | B19: 1258211.8 | C19: 7.2409106e+08 | D19: 7.5135326e+08 | E19: 316.3498 | F19: 328.2605
A20: 1952 | B20: 1335173 | C20: 8.0191284e+08 | D20: 7.7421917e+08 | E20: 350.3496 | F20: 338.2504
A21: 1953 | B21: 1363247.8 | C21: 7.9965053e+08 | D21: 8.6007575e+08 | E21: 349.3612 | F21: 375.7605
A22: 1954 | B22: 1465827 | C22: 8.8618455e+08 | D22: 9.0070358e+08 | E22: 387.1672 | F22: 393.5105
A23: 1955 | B23: 1544889.2 | C23: 9.86329e+08 | D23: 9.661806e+08 | E23: 430.9196 | F23: 422.1169
A24: 1956 | B24: 1691946.8 | C24: 1.0846661e+09 | D24: 9.3655886e+08 | E24: 473.8823 | F24: 409.1754
A25: 1957 | B25: 1797170.3 | C25: 1.1569409e+09 | D25: 8.8700072e+08 | E25: 505.4586 | F25: 387.5238
A26: 1958 | B26: 1846967.4 | C26: 1.1885565e+09 | D26: 8.32406e+08 | E26: 519.2712 | F26: 363.6718
A27: 1959 | B27: 1838622.5 | C27: 1.2421763e+09 | D27: 9.570996e+08 | E27: 542.6973 | F27: 418.1495
A28: 1960 | B28: 1887277.9 | C28: 1.2555335e+09 | D28: 1.0649319e+09 | E28: 548.533 | F28: 465.2606
A29: 1961 | B29: 1971222.4 | C29: 1.3086496e+09 | D29: 9.6837406e+08 | E29: 571.739 | F29: 423.0752
... A87: 2019 | B87: 5649830 | C87: 3.3966449e+09 | D87: 1.7370378e+09 | E87: 1483.9681 | F87: 758.8985

Sheet Catch
A1: taxon | B1: common_name | C1: functional_group | D1: commercial_group | E1: 1950 | F1: 1951 | G1: 1952 | H1: 1953 | I1: 1954 | J1: 1955 | K1: 1956 | L1: 1957 | M1: 1958 | N1: 1959 | O1: 1960 | P1: 1961 | Q1: 1962 | R1: 1963 | S1: 1964 | T1: 1965 | U1: 1966 | V1: 1967 | W1: 1968 | X1: 1969 | Y1: 1970 | Z1: 1971 | AA1: 1972 | AB1: 1973 | AC1: 1974 | AD1: 1975 | AE1: 1976 | AF1: 1977 | AG1: 1978 | AH1: 1979 | AI1: 1980 | AJ1: 1981 | AK1: 1982 | AL1: 1983 | AM1: 1984 | AN1: 1985 | AO1: 1986 | AP1: 1987 | AQ1: 1988 | AR1: 1989 | AS1: 1990 | AT1: 1991 | AU1: 1992 | AV1: 1993 | AW1: 1994 | AX1: 1995 | AY1: 1996 | AZ1: 1997 | BA1: 1998 | BB1: 1999 | BC1: 2000 | BD1: 2001 | BE1: 2002 | BF1: 2003 | BG1: 2004 | BH1: 2005 | BI1: 2006 | BJ1: 2007 | BK1: 2008 | BL1: 2009 | BM1: 2010 | BN1: 2011 | BO1: 2012 | BP1: 2013 | BQ1: 2014 | BR1: 2015 | BS1: 2016 | BT1: 2017 | BU1: 2018 | BV1: 2019
A2: Marine fishes not identified | B2: Marine fishes nei | C2: Medium demersals (30 - 89 cm) | D2: Other fishes & inverts | E2: 176494.05 | F2: 196371.8 | G2: 198518.45 | H2: 194040.93 | I2: 213793.25 | J2: 218882.06 | K2: 231549.29 | L2: 233103.99 | M2: 262233.58 | N2: 241327.77 | O2: 293976.65 | P2: 239439.43 | Q2: 275200.18 | R2: 268973.12 | S2: 273057.45 | T2: 286361.66 | U2: 322645.06 | V2: 308373.09 | W2: 320571.3 | X2: 364804.93 | Y2: 425916.34 | Z2: 438710.33 | AA2: 474943.28 | AB2: 553095.57 | AC2: 570224.88 | AD2: 528388.77 | AE2: 517133.56 | AF2: 545306.05 | AG2: 543126.79 | AH2: 565154.12 | AI2: 544569.81 | AJ2: 602708.39 | AK2: 576580.7 | AL2: 576418.59 | AM2: 657428.44 | AN2: 690329.21 | AO2: 672109.68 | AP2: 728773.43 | AQ2: 801387.99 | AR2: 788541.78 | AS2: 794007.84 | AT2: 709687.69 | AU2: 705060.75 | AV2: 738879.24 | AW2: 678744.11 | AX2: 679500.34 | AY2: 695061.07 | AZ2: 716139.9 | BA2: 722022.93 | BB2: 592334.24 | BC2: 619571.59 | BD2: 643013.96 | BE2: 608769.04 | BF2: 674485.31 | BG2: 642639.2 | BH2: 634064.84 | BI2: 596851.06 | BJ2: 603426 | BK2: 605685.97 | BL2: 665597.45 | BM2: 636944.51 | BN2: 656654.34 | BO2: 695083.84 | BP2: 738023.46 | BQ2: 724713.75 | BR2: 558243.16 | BS2: 598738.77 | BT2: 601125.44 | BU2: 595034.76 | BV2: 541116.4
A3: Sardinops sagax | B3: South American pilchard | C3: Medium pelagics (30 - 89 cm) | D3: Herring-likes | E3: 82828.7 | F3: 82949.259 | G3: 82949.407 | H3: 114372.18 | I3: 81347.218 | J3: 69953.169 | K3: 68416.658 | L3: 70871.155 | M3: 45649.957 | N3: 40524.186 | O3: 25929.977 | P3: 42527.573 | Q3: 35959.88 | R3: 18045.408 | S3: 4808.703 | T3: 2280.33 | U3: 3880.897 | V3: 4947.796 | W3: 7564.157 | X3: 6592.494 | Y3: 5260.983 | Z3: 19672.489 | AA3: 20228.327 | AB3: 107925.17 | AC3: 126566.05 | AD3: 192038.1 | AE3: 392400.25 | AF3: 537639.08 | AG3: 625394.13 | AH3: 686172.93 | AI3: 817677.42 | AJ3: 1162458.9 | AK3: 1242937.9 | AL3: 1440713.8 | AM3: 1623521.5 | AN3: 1463598.9 | AO3: 1627857.3 | AP3: 1689759.2 | AQ3: 1729243.9 | AR3: 1581099.7 | AS3: 1419197.5 | AT3: 1143543 | AU3: 831501.65 | AV3: 643257.29 | AW3: 458904.05 | AX3: 254430.65 | AY3: 141910.2 | AZ3: 140565.68 | BA3: 97386.09 | BB3: 171699.21 | BC3: 96712.603 | BD3: 106973.3 | BE3: 70543.49 | BF3: 65995.626 | BG3: 71511.148 | BH3: 63395.085 | BI3: 82369.725 | BJ3: 89235.323 | BK3: 66199.837 | BL3: 66238.134 | BM3: 71564.269 | BN3: 117599.25 | BO3: 99926.953 | BP3: 133707.03 | BQ3: 130271.22 | BR3: 172748.14 | BS3: 197778.63 | BT3: 240215.38 | BU3: 244802.83 | BV3: 443565.53
A4: Trichiurus lepturus | B4: Largehead hairtail | C4: Large benthopelagics (>=90 cm) | D4: Perch-likes | E4: 51674.38 | F4: 66707.218 | G4: 78655.272 | H4: 77362.723 | I4: 92426.842 | J4: 98990.516 | K4: 119226.23 | L4: 114153.48 | M4: 113550.46 | N4: 120130.37 | O4: 125849.52 | P4: 124068.96 | Q4: 133589.49 | R4: 130131.28 | S4: 134441.92 | T4: 144480.38 | U4: 147436.62 | V4: 166745.72 | W4: 153066.89 | X4: 165049.5 | Y4: 162926.35 | Z4: 175657.43 | AA4: 221990.13 | AB4: 241881.36 | AC4: 259921.46 | AD4: 209245.55 | AE4: 178664.66 | AF4: 174337.57 | AG4: 176429.82 | AH4: 197647.21 | AI4: 204317.89 | AJ4: 239112.26 | AK4: 222326.62 | AL4: 226739.93 | AM4: 222583.44 | AN4: 205523.28 | AO4: 198029 | AP4: 194220.41 | AQ4: 184992.95 | AR4: 222279.29 | AS4: 236536.41 | AT4: 254676 | AU4: 266049.19 | AV4: 266851.96 | AW4: 374415.02 | AX4: 472178.34 | AY4: 465766.47 | AZ4: 388622.18 | BA4: 464974.95 | BB4: 467768.73 | BC4: 490085.82 | BD4: 479397.6 | BE4: 465337.58 | BF4: 435093.7 | BG4: 502591.28 | BH4: 458811.54 | BI4: 505072.53 | BJ4: 479304.05 | BK4: 494018.88 | BL4: 447103.43 | BM4: 436401.03 | BN4: 443577.32 | BO4: 432013.06 | BP4: 407412.43 | BQ4: 469404.85 | BR4: 407385.91 | BS4: 380356.92 | BT4: 383495.88 | BU4: 360539.11 | BV4: 355462.83
A5: Engraulis japonicus | B5: Japanese anchovy | C5: Small pelagics (<30 cm) | D5: Anchovies | E5: 68666.841 | F5: 70339.747 | G5: 70221.201 | H5: 64335.752 | I5: 81198.438 | J5: 68449.353 | K5: 101179.79 | L5: 124988.7 | M5: 123256.31 | N5: 107479.68 | O5: 105345.85 | P5: 111684.09 | Q5: 110770.16 | R5: 96659.202 | S5: 91814.444 | T5: 129819.16 | U5: 134047.71 | V5: 128539.17 | W5: 120817.41 | X5: 148636.94 | Y5: 119932.37 | Z5: 122370.9 | AA5: 143940.75 | AB5: 131747.65 | AC5: 152342.06 | AD5: 143408.05 | AE5: 114903.05 | AF5: 131183.49 | AG5: 125610.96 | AH5: 110880.33 | AI5: 119939.7 | AJ5: 129454.33 | AK5: 129492.81 | AL5: 118977.48 | AM5: 135911.3 | AN5: 125356.26 | AO5: 156358.93 | AP5: 118428.01 | AQ5: 108266.42 | AR5: 113831.15 | AS5: 179894.05 | AT5: 204167.04 | AU5: 220958.51 | AV5: 343345.06 | AW5: 278269.72 | AX5: 326309.52 | AY5: 359156.05 | AZ5: 492905.32 | BA5: 598584.89 | BB5: 515548.89 | BC5: 479829.1 | BD5: 526497.62 | BE5: 522443.4 | BF5: 579987.66 | BG5: 500593.27 | BH5: 468468.95 | BI5: 476594.8 | BJ5: 437457.12 | BK5: 407916.13 | BL5: 335614.17 | BM5: 380873.96 | BN5: 430920.11 | BO5: 410171.62 | BP5: 412306.53 | BQ5: 439769.59 | BR5: 418118.8 | BS5: 347006.38 | BT5: 339275.89 | BU5: 307509.22 | BV5: 454179.67
A6: Scomber japonicus | B6: Pacific chub mackerel | C6: Medium pelagics (30 - 89 cm) | D6: Perch-likes | E6: 26008.19 | F6: 35885.509 | G6: 42679.311 | H6: 42570.537 | I6: 50357.668 | J6: 52011.506 | K6: 54536.827 | L6: 51609.288 | M6: 48816.742 | N6: 49865.27 | O6: 49746.793 | P6: 49144.321 | Q6: 51949.193 | R6: 54560.91 | S6: 56265.181 | T6: 60240.039 | U6: 56586.432 | V6: 55927.331 | W6: 70136.658 | X6: 85233.513 | Y6: 135621.14 | Z6: 62840.461 | AA6: 87911.931 | AB6: 87950.079 | AC6: 97703.036 | AD6: 79988.502 | AE6: 91059.24 | AF6: 129456.61 | AG6: 202219.9 | AH6: 123865.54 | AI6: 82203.058 | AJ6: 106929.51 | AK6: 121609.07 | AL6: 164085.5 | AM6: 143037.51 | AN6: 111695.65 | AO6: 152974.8 | AP6: 173773.59 | AQ6: 244972.44 | AR6: 227655.75 | AS6: 177066.25 | AT6: 191397.58 | AU6: 209681.86 | AV6: 248877.73 | AW6: 309883.13 | AX6: 324967.74 | AY6: 386849.98 | AZ6: 296985.96 | BA6: 269104.27 | BB6: 269344.99 | BC6: 222777.5 | BD6: 267702.08 | BE6: 260127.08 | BF6: 263278.67 | BG6: 305376.09 | BH6: 301099.92 | BI6: 272052.36 | BJ6: 252348.54 | BK6: 398073.08 | BL6: 278695.23 | BM6: 301839.33 | BN6: 372193.91 | BO6: 333885.38 | BP6: 316307.46 | BQ6: 314266.04 | BR6: 316374.37 | BS6: 305168.04 | BT6: 298729.16 | BU6: 314239.31 | BV6: 427018.3
A7: Scomber | B7: Chub mackerels | C7: Medium pelagics (30 - 89 cm) | D7: Perch-likes | E7: 37898.322 | F7: 37771.519 | G7: 37771.519 | H7: 44658.694 | I7: 57437.123 | J7: 46420.594 | K7: 54455.127 | L7: 58969.854 | M7: 58870.532 | N7: 63367.363 | O7: 73406.229 | P7: 72229.5 | Q7: 87599.252 | R7: 100792.35 | S7: 108567.01 | T7: 143035.47 | U7: 134490.9 | V7: 146326.66 | W7: 213708.12 | X7: 214646.61 | Y7: 270582.73 | Z7: 260363.6 | AA7: 248629.1 | AB7: 237329.57 | AC7: 278134.79 | AD7: 276252.18 | AE7: 204853.44 | AF7: 283490.75 | AG7: 339643.22 | AH7: 295921.6 | AI7: 270988.93 | AJ7: 191432.36 | AK7: 151898.49 | AL7: 170511.06 | AM7: 173110.66 | AN7: 163826.44 | AO7: 200092.19 | AP7: 149784.29 | AQ7: 144450.18 | AR7: 125686.18 | AS7: 75788.357 | AT7: 69766.157 | AU7: 65572.081 | AV7: 152216.46 | AW7: 142270.17 | AX7: 107608.7 | AY7: 170138.52 | AZ7: 186211.73 | BA7: 115784.49 | BB7: 89146.972 | BC7: 80210.999 | BD7: 87119.426 | BE7: 67390.975 | BF7: 77869.663 | BG7: 78013.566 | BH7: 137600.29 | BI7: 143562.51 | BJ7: 104598.73 | BK7: 117989.73 | BL7: 107695.19 | BM7: 111855.83 | BN7: 91069.707 | BO7: 116711.85 | BP7: 96168.039 | BQ7: 122696.87 | BR7: 129881.43 | BS7: 123856.77 | BT7: 124085.68 | BU7: 125437.51 | BV7: 108540.06
A8: Cololabis saira | B8: Pacific saury | C8: Medium pelagics (30 - 89 cm) | D8: Other fishes & inverts | E8: 49840.984 | F8: 50814.226 | G8: 51711.462 | H8: 55627.608 | I8: 67058.122 | J8: 102555.45 | K8: 80314.567 | L8: 103950.31 | M8: 130433.57 | N8: 129657.82 | O8: 70664.473 | P8: 113766.24 | Q8: 124982.28 | R8: 84696.704 | S8: 63951.568 | T8: 73397.86 | U8: 80167.466 | V8: 68679.808 | W8: 54557.196 | X8: 43185.498 | Y8: 39514.769 | Z8: 65244.564 | AA8: 71513.954 | AB8: 105269.58 | AC8: 58407.385 | AD8: 67449.389 | AE8: 55334.091 | AF8: 68859.302 | AG8: 87267.616 | AH8: 71095.965 | AI8: 51539.779 | AJ8: 47857.516 | AK8: 56025.726 | AL8: 59103.979 | AM8: 58266.859 | AN8: 65118.703 | AO8: 63350.948 | AP8: 57477.586 | AQ8: 72148.788 | AR8: 80355.389 | AS8: 131763.25 | AT8: 114376.9 | AU8: 141423.02 | AV8: 152754.35 | AW8: 111389.09 | AX8: 117608.87 | AY8: 100472.2 | AZ8: 176330.73 | BA8: 80958.901 | BB8: 83976.937 | BC8: 130595.38 | BD8: 153068.84 | BE8: 164501.04 | BF8: 165710.51 | BG8: 121448.57 | BH8: 183003.82 | BI8: 126343.72 | BJ8: 145337.3 | BK8: 212633.82 | BL8: 217553.13 | BM8: 223247.06 | BN8: 223987.77 | BO8: 284696.67 | BP8: 261365.28 | BQ8: 338713.17 | BR8: 239258.55 | BS8: 278787.48 | BT8: 244436.09 | BU8: 271009.53 | BV8: 230694.46
A9: Mollusca | B9: Clams, seasnails, squids, octopuses | C9: Other demersal invertebrates | D9: Molluscs | E9: 20581.01 | F9: 25497.968 | G9: 26664.466 | H9: 25041.941 | I9: 29233.834 | J9: 29567.877 | K9: 48927.176 | L9: 33777.302 | M9: 43010.087 | N9: 40751.18 | O9: 36390.899 | P9: 44453.584 | Q9: 48058.738 | R9: 47140.594 | S9: 51416.687 | T9: 48046.597 | U9: 43834.091 | V9: 40181.184 | W9: 45056.569 | X9: 42840.478 | Y9: 47964.754 | Z9: 40244.144 | AA9: 40581.635 | AB9: 55137.012 | AC9: 52935.933 | AD9: 79601.169 | AE9: 92239.477 | AF9: 95839.498 | AG9: 32973.966 | AH9: 30725.474 | AI9: 29233.571 | AJ9: 29279.546 | AK9: 43938.886 | AL9: 95890.11 | AM9: 89619.333 | AN9: 108195.21 | AO9: 151500.64 | AP9: 184135.77 | AQ9: 205332.29 | AR9: 130049.5 | AS9: 140313.7 | AT9: 141146.15 | AU9: 194462.8 | AV9: 230941.79 | AW9: 273516.13 | AX9: 320190.5 | AY9: 227393.01 | AZ9: 334622.2 | BA9: 317864.53 | BB9: 287467.11 | BC9: 274429.74 | BD9: 284462.94 | BE9: 277527.63 | BF9: 164480.71 | BG9: 172110.61 | BH9: 179949.15 | BI9: 184261.74 | BJ9: 177816.02 | BK9: 154455.47 | BL9: 158774.53 | BM9: 147551.87 | BN9: 140916.46 | BO9: 137977.24 | BP9: 132323.79 | BQ9: 7329.996 | BR9: 7704.832 | BS9: 7057.501 | BT9: 6592.958 | BU9: 6364.885 | BV9: 5752.097
A10: Miscellaneous marine crustaceans | B10: Marine crabs, shrimps, lobsters nei | C10: Shrimps | D10: Crustaceans | E10: 21959.409 | F10: 30161.437 | G10: 36615.293 | H10: 36949.668 | I10: 43970.702 | J10: 47325.655 | K10: 54116.592 | L10: 53407.994 | M10: 53146.835 | N10: 55874.109 | O10: 55889.298 | P10: 58077.552 | Q10: 59703.466 | R10: 59216.874 | S10: 60698.035 | T10: 63029.116 | U10: 63001.849 | V10: 65155.928 | W10: 67677.338 | X10: 66440.984 | Y10: 60732.58 | Z10: 65490.026 | AA10: 63097.271 | AB10: 99681.509 | AC10: 103242.66 | AD10: 100526.91 | AE10: 80668.935 | AF10: 77663.501 | AG10: 81863.694 | AH10: 77217.263 | AI10: 76800.877 | AJ10: 74530.823 | AK10: 92492.051 | AL10: 95328.907 | AM10: 115940.51 | AN10: 114619.14 | AO10: 113093.28 | AP10: 105334.91 | AQ10: 118603.58 | AR10: 127110.94 | AS10: 128916.92 | AT10: 135824.33 | AU10: 142809.44 | AV10: 204473.86 | AW10: 209898.35 | AX10: 228629.37 | AY10: 232248.26 | AZ10: 281884.05 | BA10: 289322.36 | BB10: 245119.24 | BC10: 255343.19 | BD10: 279011.34 | BE10: 265038.21 | BF10: 28691.934 | BG10: 25013.27 | BH10: 17153.329 | BI10: 17517.951 | BJ10: 16481.271 | BK10: 10352.021 | BL10: 9251.04 | BM10: 10638.847 | BN10: 9637.589 | BO10: 8140.514 | BP10: 8427.117 | BQ10: 136592.36 | BR10: 133275.33 | BS10: 112135.59 | BT10: 108262.29 | BU10: 108114.66 | BV10: 102287.54
A11: Larimichthys polyactis | B11: Yellow croaker | C11: Medium benthopelagics (30 - 89 cm) | D11: Perch-likes | E11: 19778.652 | F11: 23494.688 | G11: 25859.233 | H11: 23781.531 | I11: 22152.256 | J11: 18815.763 | K11: 28859.321 | L11: 29272.621 | M11: 24842.861 | N11: 25453.665 | O11: 24463.396 | P11: 25083.342 | Q11: 25015.449 | R11: 25300.562 | S11: 36342.599 | T11: 33461.411 | U11: 35455.047 | V11: 31633.6 | W11: 36886.393 | X11: 29882.182 | Y11: 35538.785 | Z11: 35315.03 | AA11: 26579.326 | AB11: 35547.283 | AC11: 24998.44 | AD11: 19474.889 | AE11: 22449.438 | AF11: 13310.427 | AG11: 30060.628 | AH11: 42038.247 | AI11: 53411.896 | AJ11: 45473.448 | AK11: 33784.314 | AL11: 28154.632 | AM11: 20927.665 | AN11: 29265.968 | AO11: 22637.304 | AP11: 28403.686 | AQ11: 30923.942 | AR11: 25702.467 | AS11: 32744.181 | AT11: 53171.452 | AU11: 65392.59 | AV11: 70090.277 | AW11: 92036.676 | AX11: 119053.44 | AY11: 180070.29 | AZ11: 102519.61 | BA11: 123014.02 | BB11: 142827.24 | BC11: 164434.86 | BD11: 142810.58 | BE11: 152410.91 | BF11: 160287.68 | BG11: 183919.02 | BH11: 188596.19 | BI11: 202237.27 | BJ11: 236425.73 | BK11: 245559.61 | BL11: 257805.75 | BM11: 277597.07 | BN11: 287303.28 | BO11: 277439.08 | BP11: 252898.29 | BQ11: 235240.82 | BR11: 261038.87 | BS11: 201581.28 | BT11: 197981.85 | BU11: 194842.59 | BV11: 197176.6
A12: Acetes japonicus | B12: Akiami paste shrimp | C12: Shrimps | D12: Crustaceans | E12: 12429.61 | F12: 16254.638 | G12: 18407.668 | H12: 20627.899 | I12: 21001.816 | J12: 23040.96 | K12: 26723.477 | L12: 29683.433 | M12: 25729.483 | N12: 27247.971 | O12: 24034.782 | P12: 27097.323 | Q12: 28704.229 | R12: 26161.744 | S12: 27341.706 | T12: 27900.223 | U12: 26210.845 | V12: 28926.345 | W12: 26678.608 | X12: 25652.23 | Y12: 26257.939 | Z12: 20847.712 | AA12: 25048.21 | AB12: 28356.741 | AC12: 29103.829 | AD12: 33241.091 | AE12: 33861.329 | AF12: 49400.982 | AG12: 52888.858 | AH12: 28960.421 | AI12: 37475.749 | AJ12: 43461.346 | AK12: 46883.471 | AL12: 50230.439 | AM12: 53068.3 | AN12: 60091.379 | AO12: 51820.853 | AP12: 49270.724 | AQ12: 55208.268 | AR12: 65958.236 | AS12: 65435.965 | AT12: 64764.042 | AU12: 72429.093 | AV12: 79714.357 | AW12: 94764.555 | AX12: 111107.6 | AY12: 131107.19 | AZ12: 130470.97 | BA12: 148510.98 | BB12: 148268.03 | BC12: 158870.41 | BD12: 142722.9 | BE12: 143728.8 | BF12: 156533.74 | BG12: 166880.39 | BH12: 162699.3 | BI12: 169678.15 | BJ12: 170288.28 | BK12: 153188.82 | BL12: 165071.41 | BM12: 157627.65 | BN12: 151530.04 | BO12: 161892.96 | BP12: 160861.25 | BQ12: 152949.85 | BR12: 149128.34 | BS12: 133872.01 | BT12: 124789.19 | BU12: 120856.1 | BV12: 110894.41
... A277: Caranx | B277: Jacks | C277: Medium reef assoc. fish (30 - 89 cm) | D277: Perch-likes | E277: 0 | F277: 0 | G277: 0 | H277: 0 | I277: 0 | J277: 0 | K277: 0 | L277: 0 | M277: 0 | N277: 0 | O277: 0 | P277: 0 | Q277: 0 | R277: 0 | S277: 0 | T277: 0 | U277: 0 | V277: 0 | W277: 0 | X277: 0 | Y277: 0 | Z277: 0 | AA277: 0 | AB277: 0 | AC277: 0 | AD277: 0 | AE277: 0 | AF277: 0 | AG277: 0 | AH277: 0 | AI277: 0 | AJ277: 0 | AK277: 0 | AL277: 0 | AM277: 0 | AN277: 0 | AO277: 0 | AP277: 0 | AQ277: 0 | AR277: 0 | AS277: 0 | AT277: 0 | AU277: 0 | AV277: 0 | AW277: 0 | AX277: 0 | AY277: 0 | AZ277: 0 | BA277: 0 | BB277: 0 | BC277: 0 | BD277: 0 | BE277: 0 | BF277: 0 | BG277: 0 | BH277: 0 | BI277: 0 | BJ277: 0 | BK277: 0 | BL277: 0 | BM277: 0 | BN277: 0 | BO277: 0 | BP277: 0 | BQ277: 0 | BR277: 0 | BS277: 0 | BT277: 0 | BU277: 0.008 | BV277: 0

Sheet Taxon-Group Map
A1: Which Ecopath group each catch taxon belongs to, and on what evidence.
A2: Several groups separated by | means the taxon spans them and its catch is apportioned; the weights used are in the next two columns.
A4: taxon | B4: common_name | C4: SAU functional group | D4: SAU commercial group | E4: Ecopath group | F4: weights | G4: weight basis | H4: confidence | I4: evidence | J4: catch tonnes | K4: % of catch | L4: explanation
A5: Marine fishes not identified | B5: Marine fishes nei | C5: Medium demersals (30 - 89 cm) | D5: Other fishes & inverts | E5: Benthivores | Piscivores | Planktivores/piscivores | Benthivores/piscivores | Omnivores | F5: 0.214 | 0.285 | 0.167 | 0.266 | 0.068 | G5: catch_composition | H5: medium | I5: composite_split | J5: 36591787 | K5: 12.9398 | L5: Unidentified finfish record classed by Sea Around Us as Medium demersals (30 - 89 cm); apportioned across the model's five multi-species guilds whose listed members are medium demersal or benthopelagic fish. Planktivores is excluded on size (every species Supplementary Table S1 lists there is under 30 cm) and Planktivores/Benthivores on habitat (its listed members are pelagic). Weighted by the catch composition of the identified taxa on those five groups.
A6: Sardinops sagax | B6: South American pilchard | C6: Medium pelagics (30 - 89 cm) | D6: Herring-likes | E6: Planktivores | H6: medium | I6: habitat_size_guild | J6: 25918314 | K6: 9.1654 | L6: Sea Around Us reports Northwest Pacific Sardinops (the Japanese pilchard) under this name; it is a small obligate filter-feeding planktivore. Supplementary Table S1 places the analogous clupeid Sardinella aurita in Planktivores.
A7: Trichiurus lepturus | B7: Largehead hairtail | C7: Large benthopelagics (>=90 cm) | D7: Perch-likes | E7: Hairtails | H7: high | I7: explicit_member | J7: 18967269 | K7: 6.7073 | L7: Supplementary Table S1 defines Hairtails as the single species Trichiurus lepturus; this record is that species.
A8: Engraulis japonicus | B8: Japanese anchovy | C8: Small pelagics (<30 cm) | D8: Anchovies | E8: Planktivores | H8: medium | I8: habitat_size_guild | J8: 16805259 | K8: 5.9428 | L8: Obligate zooplanktivorous anchovy under 30 cm. Supplementary Table S1 places four engraulids (Thryssa dussumieri, T. vitrirostris, T. kammalensis, Stolephorus commersonnii) in Planktivores; the family is not confined to that group (Setipinna tenuifilis sits in Planktivores/Benthivores), so this is a guild judgement rather than containment.
A9: Scomber japonicus | B9: Pacific chub mackerel | C9: Medium pelagics (30 - 89 cm) | D9: Perch-likes | E9: Planktivores/Benthivores | H9: high | I9: explicit_member | J9: 12477396 | K9: 4.4123 | L9: Supplementary Table S1 lists Scomber japonicus under Planktivores/Benthivores; this record is that species.
A10: Scomber | B10: Chub mackerels | C10: Medium pelagics (30 - 89 cm) | D10: Perch-likes | E10: Planktivores/Benthivores | H10: high | I10: taxonomic_containment | J10: 9556263 | K10: 3.3794 | L10: Supplementary Table S1 lists Scomber japonicus in Planktivores/Benthivores; this genus-level record is that genus, and S. japonicus is the East China Sea Scomber stock.
A11: Cololabis saira | B11: Pacific saury | C11: Medium pelagics (30 - 89 cm) | D11: Other fishes & inverts | E11: Planktivores | H11: medium | I11: habitat_size_guild | J11: 8328661.5 | K11: 2.9452 | L11: Pacific saury is an epipelagic zooplanktivore feeding on copepods and euphausiids, matching the model's plankton-feeding guild; Supplementary Table S1 gives Planktivores a correspondingly mixed roster of small pelagic and mesopelagic filter feeders.
A12: Mollusca | B12: Clams, seasnails, squids, octopuses | C12: Other demersal invertebrates | D12: Molluscs | E12: Mollusks | H12: medium | I12: habitat_size_guild | J12: 7501648.3 | K12: 2.6528 | L12: Phylum-level record, but Sea Around Us classes it Other demersal invertebrates with a trophic level of 2.10, which matches the benthic filter feeders of the Mollusks group ('Bivalves' Supplementary Table S1, model TL 2.17) and not the model's separate Cephalopods group (TL 2.82-2.96), whose catch this dataset reports under its own labels.
A13: Miscellaneous marine crustaceans | B13: Marine crabs, shrimps, lobsters nei | C13: Shrimps | D13: Crustaceans | E13: Shrimps | Crabs | F13: 0.748 | 0.252 | G13: catch_composition | H13: medium | I13: composite_split | J13: 6656949.1 | K13: 2.3541 | L13: Aggregate crustacean landing classed by Sea Around Us as Shrimps; the model's only two harvested crustacean compartments are Shrimps (13 penaeid, sergestid and caridean species Supplementary Table S1) and Crabs (six portunids). Benthic Crustaceans is excluded because Supplementary Table S1 defines it as Gammaridea and Cumacea, which the fishery does not land. Apportioned by the catch composition of the identified crustaceans in this LME.
A14: Larimichthys polyactis | B14: Yellow croaker | C14: Medium benthopelagics (30 - 89 cm) | D14: Perch-likes | E14: Small yellow croakers | H14: high | I14: explicit_member | J14: 6448339.5 | K14: 2.2803 | L14: Supplementary Table S1 defines Small yellow croakers as the single species Larimichthys polyactis.
A15: Acetes japonicus | B15: Akiami paste shrimp | C15: Shrimps | D15: Crustaceans | E15: Shrimps | H15: high | I15: taxonomic_containment | J15: 5391927.7 | K15: 1.9067 | L15: Supplementary Table S1 lists Acetes chinensis under Shrimps; this record is another species of that listed genus.
A16: Todarodes pacificus | B16: Japanese flying squid | C16: Cephalopods | D16: Other fishes & inverts | E16: Cephalopods | H16: high | I16: taxonomic_containment | J16: 5085314.8 | K16: 1.7983 | L16: Japanese flying squid, an ommastrephid fall inside the model's Cephalopods group, whose members Supplementary Table S1 gives as ten squid, cuttlefish and octopus species (Uroteuthis edulis, Sepia esculenta, Octopus ocellatus, Ommastrephes bartrami and others).
A17: Sciaenidae | B17: Drums, croakers | C17: Medium demersals (30 - 89 cm) | D17: Perch-likes | E17: Benthivores | Piscivores | Benthivores/piscivores | Omnivores | Large yellow croakers | Small yellow croakers | F17: 0.219 | 0.292 | 0.272 | 0.070 | 0.036 | 0.111 | G17: catch_composition | H17: medium | I17: composite_split | J17: 5013098.6 | K17: 1.7728 | L17: Family-level record. Supplementary Table S1 distributes the model's sciaenids across six groups: Johnius belangerii and J. distinctus in Benthivores, Pennahia argentata in Piscivores, Atrobucca nibe and Miichthys miiuy in Benthivores/piscivores, Nibea albiflora and Collichthys lucidus in Omnivores, Larimichthys crocea and L. polyactis in their own single-species groups. Apportioned by the catch composition of the identified taxa on those groups.
A18: Stephanolepis cirrhifer | B18: Threadsail filefish | C18: Small demersals (<30 cm) | D18: Other fishes & inverts | E18: Benthivores | H18: medium | I18: habitat_size_guild | J18: 4888905 | K18: 1.7288 | L18: Threadsail filefish is a small demersal picker on benthic invertebrates; Supplementary Table S1 places the analogous small demersal invertebrate feeders, including the tetraodontiform Diodon holocanthus and the apogonid Ostorhinchus angustatus, in Benthivores.
A19: Pectinidae | B19: Scallops | C19: Other demersal invertebrates | D19: Molluscs | E19: Mollusks | H19: high | I19: explicit_member | J19: 4644809.2 | K19: 1.6425 | L19: Supplementary Table S1 defines the model's Mollusks group as 'Bivalves'; this record is a bivalve.
A20: Scyphozoa | B20: True jellyfishes | C20: Jellyfish | D20: Other fishes & inverts | E20: Other invertebrates | H20: high | I20: explicit_member | J20: 4334965 | K20: 1.533 | L20: Supplementary Table S1 defines the model's Other invertebrates group as 'Cnidaria'. True jellyfishes are scyphozoan cnidarians and this is the model's only compartment for them.
A21: Pleuronectidae | B21: Righteye flounders | C21: Small to medium flatfishes (<90 cm) | D21: Flatfishes | E21: Benthivores | H21: medium | I21: habitat_size_guild | J21: 3661117.1 | K21: 1.2947 | L21: Righteye flounders are demersal feeders on polychaetes, small crustaceans and bivalves, matching the Benthivores definition of Supplementary Table S1 (Parapercis sexfasciata, Acanthocepola limbata, Uranoscopus japonicus, Johnius spp.).
A22: Muraenesox cinereus | B22: Daggertooth pike conger | C22: Large demersals (>=90 cm) | D22: Other fishes & inverts | E22: Piscivores | H22: high | I22: explicit_member | J22: 3486912 | K22: 1.2331 | L22: Supplementary Table S1 lists Muraenesox cinereus under Piscivores.
A23: Pennahia argentata | B23: Silver croaker | C23: Medium benthopelagics (30 - 89 cm) | D23: Perch-likes | E23: Benthivores/piscivores | H23: high | I23: explicit_member | J23: 3365329.4 | K23: 1.1901 | L23: Supplementary Table S1 lists this species twice, as 'Pennahia argentata' under Piscivores and as 'Pennahia argentatus' under Benthivores/piscivores. The paper's discussion resolves the duplication by naming 'benthivores/piscivores (Pennahia argentatus and Nemipterus virgatus)', and the species' diet of shrimps, crabs and small fish matches that guild. This corrects an inherited assignment to Piscivores.
A24: Gadus macrocephalus | B24: Pacific cod | C24: Large demersals (>=90 cm) | D24: Cod-likes | E24: Benthivores/piscivores | H24: low | I24: analogue | J24: 3276610.1 | K24: 1.1587 | L24: Pacific cod is a large demersal generalist taking crabs, shrimps, polychaetes and fish, functionally the model's mixed benthivore-piscivore guild (Nemipterus virgatus, Miichthys miiuy, Atrobucca nibe). No gadid appears in Supplementary Table S1 and the species reaches only the northern margin of the East China Sea, so this is analogy, not the paper.
A25: Monacanthidae | B25: Filefishes | C25: Medium reef assoc. fish (30 - 89 cm) | D25: Other fishes & inverts | E25: Benthivores | Planktivores/piscivores | F25: 0.561 | 0.439 | G25: catch_composition | H25: medium | I25: composite_split | J25: 3089551.1 | K25: 1.0925 | L25: Family-level filefish record. Supplementary Table S1 places the one monacanthid in the model, Aluterus monoceros, in Planktivores/piscivores; the filefish that dominates East China Sea landings, Stephanolepis cirrhifer, is a small benthic invertebrate feeder matching the Benthivores definition, whose listed members include the analogous tetraodontiform Diodon holocanthus. Apportioned by catch composition.
A26: Pampus | B26: Silver pomfrets | C26: Medium benthopelagics (30 - 89 cm) | D26: Perch-likes | E26: Planktivores/piscivores | H26: high | I26: taxonomic_containment | J26: 2910778.1 | K26: 1.0293 | L26: Supplementary Table S1 lists Pampus chinensis and Pampus argenteus in Planktivores/piscivores; this genus-level record is that genus.
A27: Bivalvia | B27: Clams | C27: Other demersal invertebrates | D27: Molluscs | E27: Mollusks | H27: high | I27: explicit_member | J27: 2883416.1 | K27: 1.0197 | L27: Supplementary Table S1 defines the model's Mollusks group as 'Bivalves'; this record is a bivalve.
A28: Trachysalambria curvirostris | B28: Southern rough shrimp | C28: Shrimps | D28: Crustaceans | E28: Shrimps | H28: high | I28: synonym | J28: 2850108.3 | K28: 1.0079 | L28: Supplementary Table S1 lists 'Trachypenaeus curvirostris' under Shrimps, the historical combination of this species.
A29: Nemipterus | B29: Threadfin breams | C29: Small demersals (<30 cm) | D29: Perch-likes | E29: Benthivores/piscivores | H29: high | I29: taxonomic_containment | J29: 2808444.1 | K29: 0.9931 | L29: Supplementary Table S1 lists Nemipterus virgatus in Benthivores/piscivores; this genus-level record is that genus.
A30: Scomberomorus | B30: Spanish mackerels | C30: Large pelagics (>=90 cm) | D30: Perch-likes | E30: Piscivores | H30: high | I30: taxonomic_containment | J30: 2797567.3 | K30: 0.9893 | L30: Supplementary Table S1 lists Scomberomorus niphonius and S. guttatus in Piscivores; this genus-level record is that genus.
A31: Portunus trituberculatus | B31: Gazami crab | C31: Lobsters, crabs | D31: Crustaceans | E31: Crabs | H31: high | I31: explicit_member | J31: 2665671.8 | K31: 0.9427 | L31: Supplementary Table S1 lists Portunus trituberculatus under Crabs.
A32: Octopoda | B32: Octopuses, argonauts | C32: Cephalopods | D32: Other fishes & inverts | E32: Cephalopods | H32: high | I32: taxonomic_containment | J32: 2576878 | K32: 0.9113 | L32: Octopuses fall inside the model's Cephalopods group, whose members Supplementary Table S1 gives as ten squid, cuttlefish and octopus species (Uroteuthis edulis, Sepia esculenta, Octopus ocellatus, Ommastrephes bartrami and others).
A33: Sepiida | B33: Cuttlefishes, bobtail squids | C33: Cephalopods | D33: Other fishes & inverts | E33: Cephalopods | H33: high | I33: taxonomic_containment | J33: 2151524 | K33: 0.7608 | L33: Cuttlefishes and bobtail squids fall inside the model's Cephalopods group, whose members Supplementary Table S1 gives as ten squid, cuttlefish and octopus species (Uroteuthis edulis, Sepia esculenta, Octopus ocellatus, Ommastrephes bartrami and others).
A34: Larimichthys crocea | B34: Large yellow croaker | C34: Medium benthopelagics (30 - 89 cm) | D34: Perch-likes | E34: Large yellow croakers | H34: high | I34: explicit_member | J34: 2056876.1 | K34: 0.7274 | L34: Supplementary Table S1 defines Large yellow croakers as the single species Larimichthys crocea.
A35: Scomberomorus niphonius | B35: Japanese Spanish mackerel | C35: Large pelagics (>=90 cm) | D35: Perch-likes | E35: Piscivores | H35: high | I35: explicit_member | J35: 2034325.9 | K35: 0.7194 | L35: Supplementary Table S1 lists Scomberomorus niphonius under Piscivores; the paper's discussion names it as the group's exemplar.
A36: Planiliza haematocheilus | B36: So-iny mullet | C36: Medium demersals (30 - 89 cm) | D36: Perch-likes | E36: Benthivores | H36: low | I36: analogue | J36: 1954164.4 | K36: 0.691 | L36: So-iny mullet feeds on benthic diatoms, detritus and meiofauna. The model has no herbivore or detritivore fish compartment, so Benthivores, its only bottom-feeding guild, is the closest available home; the mismatch in diet is real and a reviewer may prefer to leave mullets unresolved.
A37: Teuthida | B37: Squids | C37: Cephalopods | D37: Other fishes & inverts | E37: Cephalopods | H37: high | I37: taxonomic_containment | J37: 1877837.9 | K37: 0.6641 | L37: Squids fall inside the model's Cephalopods group, whose members Supplementary Table S1 gives as ten squid, cuttlefish and octopus species (Uroteuthis edulis, Sepia esculenta, Octopus ocellatus, Ommastrephes bartrami and others).
... A39: Oncorhynchus | B39: Salmons, trouts | C39: Large benthopelagics (>=90 cm) | D39: Salmon, smelts, etc | E39: Planktivores/piscivores | H39: low | I39: analogue | J39: 1837237.1 | K39: 0.6497 | L39: At sea Pacific salmon feed on euphausiids, amphipods, squid and small fish, which is the mixed plankton-and-fish guild the model defines with Decapterus maruadsi and Trachurus japonicus. The model has no anadromous or subarctic compartment and no salmonid appears in Supplementary Table S1, and salmon reach the East China Sea only at its northern margin, so this is an analogue placement a reviewer may prefer to leave unresolved.
A40: Carangidae | B40: Jacks, pompanos | C40: Medium pelagics (30 - 89 cm) | D40: Perch-likes | E40: Planktivores/piscivores | Omnivores | F40: 0.711 | 0.289 | G40: catch_composition | H40: medium | I40: composite_split | J40: 1801294.3 | K40: 0.637 | L40: Family-level record. Supplementary Table S1 places the model's carangids in exactly two groups: Decapterus maruadsi, Trachurus japonicus and Parastromateus niger in Planktivores/piscivores, and Caranx sexfasciatus in Omnivores. Apportioned by the catch composition of the identified carangids in this LME.
A41: Psenopsis anomala | B41: Pacific rudderfish | C41: Small benthopelagics (<30 cm) | D41: Perch-likes | E41: Planktivores/Benthivores | Planktivores/piscivores | F41: 0.500 | 0.500 | G41: equal | H41: low | I41: composite_split | J41: 1596611.3 | K41: 0.5646 | L41: Supplementary Table S1 lists this exact species twice, once under Planktivores/Benthivores and once under Planktivores/piscivores, and gives no basis for preferring either; the candidate set is therefore exact but the split is arbitrary, so equal weights are used.
A42: Squillidae | B42: Squilla mantis shrimps | C42: Shrimps | D42: Crustaceans | E42: Shrimps | H42: medium | I42: analogue | J42: 1512499 | K42: 0.5349 | L42: Mantis shrimps are stomatopods, not decapods, and appear nowhere in Supplementary Table S1, but Sea Around Us classes them under Shrimps and the East China Sea trawl fishery lands them with the shrimp catch; the model has no other compartment of comparable size and habitat (Benthic Crustaceans is defined as Gammaridea and Cumacea).
...

Sheet SPPR
A1: Specific PPR per taxon — LME_047, model 47_1_East_China_Sea_(1997)
A2: sppr_simple is the trophic-chain estimate (1/TE)^(TL-1) at TE=0.1, applied to the taxon's own trophic level and needing no model.
A3: The remaining columns are this model's SPPR for the taxon's group, one per method. Blank means the method did not resolve, never zero.
A4: taxon | B4: trophic_level | C4: sppr_simple | D4: Ecopath group | E4: SPPR_1986 | F4: SPPR_1995_TE0.1 | G4: SPPR_1995_TEmean | H4: Ulanowicz_globalTEmean | I4: Ulanowicz_TE | J4: EwE_TE_noEE | K4: EwE_TE_EE | L4: SPPR_2015 | M4: new_TE_noEEfix | N4: new_TE_EEfix | O4: new_GE | P4: new_WithEgestion | Q4: sym_TE_asPP | R4: sym_TE_asDC | S4: sym_GE_asPP | T4: sym_GE_asDC | U4: sym_WithEgestion_asPP | V4: sym_WithEgestion_asDC | W4: MC_new_GE | X4: MC_new_TE_EEfix
A5: Marine fishes not identified | B5: 3.28 | C5: 190.54607 | D5: Benthivores | Piscivores | Planktivores/piscivores | Benthivores/piscivores | Omnivores | E5: 0 | F5: 166.96155 | G5: 2.045106 | H5: 2.060755 | I5: 186.1695 | J5: 192.68038 | K5: 114.31695 | L5: 287.67699 | M5: 287.67699 | N5: 291.90815 | O5: 34.836971 | P5: 19.545313 | Q5: 291.90815 | R5: 287.67699 | S5: 34.836971 | T5: 34.836971 | U5: 19.545313 | V5: 19.545313 | W5: 35.81931 | X5: 216.24497
A6: Sardinops sagax | B6: 2.84 | C6: 69.183097 | D6: Planktivores | E6: 0 | F6: 100.99764 | G6: 1.93677 | H6: 1.93149 | I6: 53.479795 | J6: 53.479795 | K6: 53.372836 | L6: 51.741399 | M6: 51.741399 | N6: 52.283119 | O6: 17.749881 | P6: 11.404035 | Q6: 52.283119 | R6: 51.741399 | S6: 17.749881 | T6: 17.749881 | U6: 11.404035 | V6: 11.404035 | W6: 17.839302 | X6: 54.129601
A7: Trichiurus lepturus | B7: 4.42 | C7: 2630.268 | D7: Hairtails | E7: 0 | F7: 137.30084 | G7: 2.023855 | H7: 1.935295 | I7: 245.6862 | J7: 262.94829 | K7: 262.4224 | L7: 395.11592 | M7: 395.11592 | N7: 400.56763 | O7: 71.211755 | P7: 35.749118 | Q7: 400.56763 | R7: 395.11592 | S7: 71.211755 | T7: 71.211755 | U7: 35.749118 | V7: 35.749118 | W7: 71.925944 | X7: 401.69818
A8: Engraulis japonicus | B8: 3.14 | C8: 138.03843 | D8: Planktivores | E8: 0 | F8: 100.99764 | G8: 1.93677 | H8: 1.93149 | I8: 53.479795 | J8: 53.479795 | K8: 53.372836 | L8: 51.741399 | M8: 51.741399 | N8: 52.283119 | O8: 17.749881 | P8: 11.404035 | Q8: 52.283119 | R8: 51.741399 | S8: 17.749881 | T8: 17.749881 | U8: 11.404035 | V8: 11.404035 | W8: 17.839302 | X8: 54.129601
A9: Scomber japonicus | B9: 3.38 | C9: 239.88329 | D9: Planktivores/Benthivores | E9: 0 | F9: 90.847833 | G9: 1.907611 | H9: 1.91205 | I9: 124.27116 | J9: 124.27116 | K9: 113.83239 | L9: 118.84011 | M9: 118.84011 | N9: 120.05467 | O9: 37.420523 | P9: 24.182504 | Q9: 120.05467 | R9: 118.84011 | S9: 37.420523 | T9: 37.420523 | U9: 24.182504 | V9: 24.182504 | W9: 38.102317 | X9: 122.24189
A10: Scomber | B10: 3.65 | C10: 446.68359 | D10: Planktivores/Benthivores | E10: 0 | F10: 90.847833 | G10: 1.907611 | H10: 1.91205 | I10: 124.27116 | J10: 124.27116 | K10: 113.83239 | L10: 118.84011 | M10: 118.84011 | N10: 120.05467 | O10: 37.420523 | P10: 24.182504 | Q10: 120.05467 | R10: 118.84011 | S10: 37.420523 | T10: 37.420523 | U10: 24.182504 | V10: 24.182504 | W10: 38.102317 | X10: 122.24189
A11: Cololabis saira | B11: 3.71 | C11: 512.86138 | D11: Planktivores | E11: 0 | F11: 100.99764 | G11: 1.93677 | H11: 1.93149 | I11: 53.479795 | J11: 53.479795 | K11: 53.372836 | L11: 51.741399 | M11: 51.741399 | N11: 52.283119 | O11: 17.749881 | P11: 11.404035 | Q11: 52.283119 | R11: 51.741399 | S11: 17.749881 | T11: 17.749881 | U11: 11.404035 | V11: 11.404035 | W11: 17.839302 | X11: 54.129601
A12: Mollusca | B12: 2.1 | C12: 12.589254 | D12: Mollusks | E12: 0 | F12: 14.497407 | G12: 1.466668 | H12: 1.466497 | I12: 17.850747 | J12: 17.850747 | K12: 5.355224 | L12: 17.186608 | M12: 17.186608 | N12: 17.598965 | O12: 3.995111 | P12: 2.967513 | Q12: 17.598965 | R12: 17.186608 | S12: 3.995111 | T12: 3.995111 | U12: 2.967513 | V12: 2.967513 | W12: 3.990277 | X12: 17.941416
A13: Miscellaneous marine crustaceans | B13: 2.7 | C13: 50.118723 | D13: Shrimps | Crabs | E13: 0 | F13: 20.706252 | G13: 1.54349 | H13: 1.562479 | I13: 14.308705 | J13: 14.308705 | K13: 14.042094 | L13: 13.196282 | M13: 13.196282 | N13: 13.444431 | O13: 7.849897 | P13: 5.562855 | Q13: 13.444431 | R13: 13.196282 | S13: 7.849897 | T13: 7.849897 | U13: 5.562855 | V13: 5.562855 | W13: 7.985273 | X13: 13.913077
A14: Larimichthys polyactis | B14: 3.64 | C14: 436.51583 | D14: Small yellow croakers | E14: 0 | F14: 133.41623 | G14: 2.015553 | H14: 2.043652 | I14: 272.24519 | J14: 278.64023 | K14: 62.972692 | L14: 308.69894 | M14: 308.69894 | N14: 312.82813 | O14: 15.479061 | P14: 8.820708 | Q14: 312.82813 | R14: 308.69894 | S14: 15.479061 | T14: 15.479061 | U14: 8.820708 | V14: 8.820708 | W14: 15.817561 | X14: 303.12945
A15: Acetes japonicus | B15: 2.54 | C15: 34.673685 | D15: Shrimps | E15: 0 | F15: 20.606299 | G15: 1.542427 | H15: 1.561295 | I15: 15.075177 | J15: 15.075177 | K15: 15.060102 | L15: 13.927162 | M15: 13.927162 | N15: 14.183251 | O15: 7.969433 | P15: 5.681336 | Q15: 14.183251 | R15: 13.927162 | S15: 7.969433 | T15: 7.969433 | U15: 5.681336 | V15: 5.681336 | W15: 8.136905 | X15: 14.885026
A16: Todarodes pacificus | B16: 4.28 | C16: 1905.4607 | D16: Cephalopods | E16: 0 | F16: 65.929169 | G16: 1.821994 | H16: 1.839433 | I16: 38.382342 | J16: 38.382342 | K16: 37.768225 | L16: 36.734327 | M16: 36.734327 | N16: 37.111337 | O16: 12.794003 | P16: 8.242232 | Q16: 37.111337 | R16: 36.734327 | S16: 12.794003 | T16: 12.794003 | U16: 8.242232 | V16: 8.242232 | W16: 12.757448 | X16: 38.53303
... A114: Muraenesocidae | B114: 3.9 | C114: 794.32823 | D114: Piscivores | E114: 0 | F114: 304.389 | G114: 2.268309 | H114: 2.300314 | I114: 249.25988 | J114: 251.42874 | K114: 202.1487 | L114: 282.597 | M114: 282.597 | N114: 286.03317 | O114: 49.797649 | P114: 25.643377 | Q114: 286.03317 | R114: 282.597 | S114: 49.797649 | T114: 49.797649 | U114: 25.643377 | V114: 25.643377 | W114: 51.082514 | X114: 274.51894
A115: Squalidae | D115: Sharks | E115: 0 | F115: 1154.7441 | G115: 2.745621 | H115: 2.742397 | I115: 0 | J115: 152.58385 | K115: 0 | L115: 0 | M115: 0 | N115: 0 | O115: 205.19967 | P115: 93.831501 | Q115: 0 | R115: 0 | S115: 205.19967 | T115: 205.19967 | U115: 93.831501 | V115: 93.831501 | W115: 205.69541 | X115: 0
A116: Seriola lalandi | D116: Piscivores | E116: 0 | F116: 304.389 | G116: 2.268309 | H116: 2.300314 | I116: 249.25988 | J116: 251.42874 | K116: 202.1487 | L116: 282.597 | M116: 282.597 | N116: 286.03317 | O116: 49.797649 | P116: 25.643377 | Q116: 286.03317 | R116: 282.597 | S116: 49.797649 | T116: 49.797649 | U116: 25.643377 | V116: 25.643377 | W116: 51.082514 | X116: 274.51894
A117: Portunidae | B117: 3.56 | C117: 363.07806 | D117: Crabs | E117: 0 | F117: 21.002175 | G117: 1.546636 | H117: 1.565985 | I117: 12.039474 | J117: 12.039474 | K117: 11.028158 | L117: 11.032425 | M117: 11.032425 | N117: 11.257068 | O117: 7.495998 | P117: 5.212079 | Q117: 11.257068 | R117: 11.032425 | S117: 7.495998 | T117: 7.495998 | U117: 5.212079 | V117: 5.212079 | W117: 7.53635 | X117: 11.035506
A118: Pagrus auratus | B118: 3.59 | C118: 389.04514 | D118: Omnivores | E118: 0 | F118: 131.22146 | G118: 2.01077 | H118: 2.036134 | I118: 66.044357 | J118: 68.255823 | K118: 68.187568 | L118: 72.544996 | M118: 72.544996 | N118: 73.572832 | O118: 17.500018 | P118: 10.032554 | Q118: 73.572832 | R118: 72.544996 | S118: 17.500018 | T118: 17.500018 | U118: 10.032554 | V118: 10.032554 | W118: 17.704629 | X118: 72.854687
A119: Thunnus obesus | B119: 4.49 | C119: 3090.2954 | D119: Piscivores | E119: 0 | F119: 304.389 | G119: 2.268309 | H119: 2.300314 | I119: 249.25988 | J119: 251.42874 | K119: 202.1487 | L119: 282.597 | M119: 282.597 | N119: 286.03317 | O119: 49.797649 | P119: 25.643377 | Q119: 286.03317 | R119: 282.597 | S119: 49.797649 | T119: 49.797649 | U119: 25.643377 | V119: 25.643377 | W119: 51.082514 | X119: 274.51894
A120: Haemulidae | B120: 3.36 | C120: 229.08677 | D120: Benthivores | E120: 0 | F120: 67.814783 | G120: 1.829368 | H120: 1.84033 | I120: 33.988491 | J120: 35.780255 | K120: 35.601354 | L120: 385.22884 | M120: 385.22884 | N120: 391.588 | O120: 16.66963 | P120: 9.97388 | Q120: 391.588 | R120: 385.22884 | S120: 16.66963 | T120: 16.66963 | U120: 9.97388 | V120: 9.97388 | W120: 17.246706 | X120: 42.474741
A121: Gastropoda | B121: 3.06 | C121: 114.81536 | D121: Mollusks | E121: 0 | F121: 14.497407 | G121: 1.466668 | H121: 1.466497 | I121: 17.850747 | J121: 17.850747 | K121: 5.355224 | L121: 17.186608 | M121: 17.186608 | N121: 17.598965 | O121: 3.995111 | P121: 2.967513 | Q121: 17.598965 | R121: 17.186608 | S121: 3.995111 | T121: 3.995111 | U121: 2.967513 | V121: 2.967513 | W121: 3.990277 | X121: 17.941416
A122: Holothuroidea | B122: 2 | C122: 10 | D122: Echinoderms | E122: 0 | F122: 14.362944 | G122: 1.464712 | H122: 1.389744 | I122: 47.528559 | J122: 47.528559 | K122: 8.650198 | L122: 98169.82 | M122: 98169.82 | N122: 99766.368 | O122: 7.082345 | P122: 4.85352 | Q122: 99766.368 | R122: 98169.82 | S122: 7.082345 | T122: 7.082345 | U122: 4.85352 | V122: 4.85352 | W122: 7.237529 | X122: 1019.755
A123: Penaeus japonicus | B123: 2.7 | C123: 50.118723 | D123: Shrimps | E123: 0 | F123: 20.606299 | G123: 1.542427 | H123: 1.561295 | I123: 15.075177 | J123: 15.075177 | K123: 15.060102 | L123: 13.927162 | M123: 13.927162 | N123: 14.183251 | O123: 7.969433 | P123: 5.681336 | Q123: 14.183251 | R123: 13.927162 | S123: 7.969433 | T123: 7.969433 | U123: 5.681336 | V123: 5.681336 | W123: 8.136905 | X123: 14.885026
A124: Mytilidae | B124: 2 | C124: 10 | D124: Mollusks | E124: 0 | F124: 14.497407 | G124: 1.466668 | H124: 1.466497 | I124: 17.850747 | J124: 17.850747 | K124: 5.355224 | L124: 17.186608 | M124: 17.186608 | N124: 17.598965 | O124: 3.995111 | P124: 2.967513 | Q124: 17.598965 | R124: 17.186608 | S124: 3.995111 | T124: 3.995111 | U124: 2.967513 | V124: 2.967513 | W124: 3.990277 | X124: 17.941416
A125: Penaeidae | B125: 3.31 | C125: 204.17379 | D125: Shrimps | E125: 0 | F125: 20.606299 | G125: 1.542427 | H125: 1.561295 | I125: 15.075177 | J125: 15.075177 | K125: 15.060102 | L125: 13.927162 | M125: 13.927162 | N125: 14.183251 | O125: 7.969433 | P125: 5.681336 | Q125: 14.183251 | R125: 13.927162 | S125: 7.969433 | T125: 7.969433 | U125: 5.681336 | V125: 5.681336 | W125: 8.136905 | X125: 14.885026
A126: Trichiuridae | B126: 4.15 | C126: 1412.5375 | D126: Hairtails | E126: 0 | F126: 137.30084 | G126: 2.023855 | H126: 1.935295 | I126: 245.6862 | J126: 262.94829 | K126: 262.4224 | L126: 395.11592 | M126: 395.11592 | N126: 400.56763 | O126: 71.211755 | P126: 35.749118 | Q126: 400.56763 | R126: 395.11592 | S126: 71.211755 | T126: 71.211755 | U126: 35.749118 | V126: 35.749118 | W126: 71.925944 | X126: 401.69818
A127: Parastromateus niger | B127: 2.93 | C127: 85.113804 | D127: Planktivores/piscivores | E127: 0 | F127: 123.07779 | G127: 1.992402 | H127: 1.97781 | I127: 560.29931 | J127: 592.27268 | K127: 209.07226 | L127: 660.16691 | M127: 660.16691 | N127: 670.16553 | O127: 72.857719 | P127: 43.071646 | Q127: 670.16553 | R127: 660.16691 | S127: 72.857719 | T127: 72.857719 | U127: 43.071646 | V127: 43.071646 | W127: 75.193746 | X127: 683.80424
A128: Miichthys miiuy | B128: 3.5 | C128: 316.22777 | D128: Benthivores/piscivores | E128: 0 | F128: 136.12006 | G128: 2.021353 | H128: 2.039787 | I128: 36.046055 | J128: 36.076344 | K128: 35.535199 | L128: 34.759886 | M128: 34.759886 | N128: 35.313702 | O128: 13.890783 | P128: 8.31974 | Q128: 35.313702 | R128: 34.759886 | S128: 13.890783 | T128: 13.890783 | U128: 8.31974 | V128: 8.31974 | W128: 14.220855 | X128: 35.767132
... A131: Gadus chalcogrammus | B131: 3.57 | C131: 371.53523 | D131: Planktivores/piscivores | E131: 0 | F131: 123.07779 | G131: 1.992402 | H131: 1.97781 | I131: 560.29931 | J131: 592.27268 | K131: 209.07226 | L131: 660.16691 | M131: 660.16691 | N131: 670.16553 | O131: 72.857719 | P131: 43.071646 | Q131: 670.16553 | R131: 660.16691 | S131: 72.857719 | T131: 72.857719 | U131: 43.071646 | V131: 43.071646 | W131: 75.193746 | X131: 683.80424
A132: Branchiostegus japonicus | D132: Benthivores/piscivores | E132: 0 | F132: 136.12006 | G132: 2.021353 | H132: 2.039787 | I132: 36.046055 | J132: 36.076344 | K132: 35.535199 | L132: 34.759886 | M132: 34.759886 | N132: 35.313702 | O132: 13.890783 | P132: 8.31974 | Q132: 35.313702 | R132: 34.759886 | S132: 13.890783 | T132: 13.890783 | U132: 8.31974 | V132: 8.31974 | W132: 14.220855 | X132: 35.767132
A133: Meretrix lusoria | B133: 2 | C133: 10 | D133: Mollusks | E133: 0 | F133: 14.497407 | G133: 1.466668 | H133: 1.466497 | I133: 17.850747 | J133: 17.850747 | K133: 5.355224 | L133: 17.186608 | M133: 17.186608 | N133: 17.598965 | O133: 3.995111 | P133: 2.967513 | Q133: 17.598965 | R133: 17.186608 | S133: 3.995111 | T133: 3.995111 | U133: 2.967513 | V133: 2.967513 | W133: 3.990277 | X133: 17.941416
A134: Gadidae | B134: 3.84 | C134: 691.83097 | D134: Benthivores/piscivores | Planktivores/piscivores | E134: 0 | F134: 131.07721 | G134: 2.010159 | H134: 2.015823 | I134: 238.7508 | J134: 251.13202 | K134: 102.63404 | L134: 276.57617 | M134: 276.57617 | N134: 280.78185 | O134: 36.690599 | P134: 21.756712 | Q134: 280.78185 | R134: 276.57617 | S134: 36.690599 | T134: 36.690599 | U134: 21.756712 | V134: 21.756712 | W134: 37.796282 | X134: 286.33343
A135: Scomberomorus guttatus | B135: 4.28 | C135: 1905.4607 | D135: Piscivores | E135: 0 | F135: 304.389 | G135: 2.268309 | H135: 2.300314 | I135: 249.25988 | J135: 251.42874 | K135: 202.1487 | L135: 282.597 | M135: 282.597 | N135: 286.03317 | O135: 49.797649 | P135: 25.643377 | Q135: 286.03317 | R135: 282.597 | S135: 49.797649 | T135: 49.797649 | U135: 25.643377 | V135: 25.643377 | W135: 51.082514 | X135: 274.51894
A136: Tegillarca granosa | B136: 2 | C136: 10 | D136: Mollusks | E136: 0 | F136: 14.497407 | G136: 1.466668 | H136: 1.466497 | I136: 17.850747 | J136: 17.850747 | K136: 5.355224 | L136: 17.186608 | M136: 17.186608 | N136: 17.598965 | O136: 3.995111 | P136: 2.967513 | Q136: 17.598965 | R136: 17.186608 | S136: 3.995111 | T136: 3.995111 | U136: 2.967513 | V136: 2.967513 | W136: 3.990277 | X136: 17.941416
A137: Menidae | B137: 3.45 | C137: 281.83829 | D137: Planktivores/piscivores | E137: 0 | F137: 123.07779 | G137: 1.992402 | H137: 1.97781 | I137: 560.29931 | J137: 592.27268 | K137: 209.07226 | L137: 660.16691 | M137: 660.16691 | N137: 670.16553 | O137: 72.857719 | P137: 43.071646 | Q137: 670.16553 | R137: 660.16691 | S137: 72.857719 | T137: 72.857719 | U137: 43.071646 | V137: 43.071646 | W137: 75.193746 | X137: 683.80424
A138: Scorpaenidae | B138: 3.92 | C138: 831.76377 | D138: Benthivores/piscivores | E138: 0 | F138: 136.12006 | G138: 2.021353 | H138: 2.039787 | I138: 36.046055 | J138: 36.076344 | K138: 35.535199 | L138: 34.759886 | M138: 34.759886 | N138: 35.313702 | O138: 13.890783 | P138: 8.31974 | Q138: 35.313702 | R138: 34.759886 | S138: 13.890783 | T138: 13.890783 | U138: 8.31974 | V138: 8.31974 | W138: 14.220855 | X138: 35.767132
A139: Ommastrephidae | B139: 4.09 | C139: 1230.2688 | D139: Cephalopods | E139: 0 | F139: 65.929169 | G139: 1.821994 | H139: 1.839433 | I139: 38.382342 | J139: 38.382342 | K139: 37.768225 | L139: 36.734327 | M139: 36.734327 | N139: 37.111337 | O139: 12.794003 | P139: 8.242232 | Q139: 37.111337 | R139: 36.734327 | S139: 12.794003 | T139: 12.794003 | U139: 8.242232 | V139: 8.242232 | W139: 12.757448 | X139: 38.53303
...

Sheet PPR by method
A1: Total PPR by method and year — every taxon summed, tonnes wet weight equivalent of primary production.
A2: Rows are methods. The first is the simple trophic-chain estimate, which needs no model and covers every taxon; the rest are this model's.
A3: Methods are not alternatives to be averaged. They rest on different assumptions and the spread between them is the result.
A4: The two grey rows aggregate the catch to a group before exponentiating, which understates the total: SPPR is convex in trophic level, so they measure the Jensen effect rather than the PPR.
A5: method | B5: status | C5: 1950 | D5: 1951 | E5: 1952 | F5: 1953 | G5: 1954 | H5: 1955 | I5: 1956 | J5: 1957 | K5: 1958 | L5: 1959 | M5: 1960 | N5: 1961 | O5: 1962 | P5: 1963 | Q5: 1964 | R5: 1965 | S5: 1966 | T5: 1967 | U5: 1968 | V5: 1969 | W5: 1970 | X5: 1971 | Y5: 1972 | Z5: 1973 | AA5: 1974 | AB5: 1975 | AC5: 1976 | AD5: 1977 | AE5: 1978 | AF5: 1979 | AG5: 1980 | AH5: 1981 | AI5: 1982 | AJ5: 1983 | AK5: 1984 | AL5: 1985 | AM5: 1986 | AN5: 1987 | AO5: 1988 | AP5: 1989 | AQ5: 1990 | AR5: 1991 | AS5: 1992 | AT5: 1993 | AU5: 1994 | AV5: 1995 | AW5: 1996 | AX5: 1997 | AY5: 1998 | AZ5: 1999 | BA5: 2000 | BB5: 2001 | BC5: 2002 | BD5: 2003 | BE5: 2004 | BF5: 2005 | BG5: 2006 | BH5: 2007 | BI5: 2008 | BJ5: 2009 | BK5: 2010 | BL5: 2011 | BM5: 2012 | BN5: 2013 | BO5: 2014 | BP5: 2015 | BQ5: 2016 | BR5: 2017 | BS5: 2018 | BT5: 2019
A6: simple trophic chain, per taxon | B6: ok | C6: 6.4809035e+08 | D6: 7.2409106e+08 | E6: 8.0191284e+08 | F6: 7.9965053e+08 | G6: 8.8618455e+08 | H6: 9.86329e+08 | I6: 1.0846661e+09 | J6: 1.1569409e+09 | K6: 1.1885565e+09 | L6: 1.2421763e+09 | M6: 1.2555335e+09 | N6: 1.3086496e+09 | O6: 1.3449101e+09 | P6: 1.3576798e+09 | Q6: 1.3121335e+09 | R6: 1.3772753e+09 | S6: 1.4209166e+09 | T6: 1.466873e+09 | U6: 1.5130688e+09 | V6: 1.4984966e+09 | W6: 1.5109945e+09 | X6: 1.563567e+09 | Y6: 1.7685121e+09 | Z6: 1.8919594e+09 | AA6: 1.9977517e+09 | AB6: 1.900571e+09 | AC6: 1.8474153e+09 | AD6: 1.8629024e+09 | AE6: 1.8950452e+09 | AF6: 1.9708417e+09 | AG6: 2.0228746e+09 | AH6: 2.0918772e+09 | AI6: 2.1123021e+09 | AJ6: 2.0669491e+09 | AK6: 2.2321036e+09 | AL6: 2.1320456e+09 | AM6: 2.2124219e+09 | AN6: 2.2875615e+09 | AO6: 2.3185635e+09 | AP6: 2.4857678e+09 | AQ6: 2.5982563e+09 | AR6: 2.8353512e+09 | AS6: 2.7637676e+09 | AT6: 2.8218579e+09 | AU6: 3.3177913e+09 | AV6: 3.8089986e+09 | AW6: 3.4606631e+09 | AX6: 3.3668558e+09 | AY6: 3.6498226e+09 | AZ6: 3.4382848e+09 | BA6: 3.4439826e+09 | BB6: 3.4243474e+09 | BC6: 3.3831316e+09 | BD6: 3.2758677e+09 | BE6: 3.6265932e+09 | BF6: 3.4453564e+09 | BG6: 3.6161911e+09 | BH6: 3.5794555e+09 | BI6: 3.6697494e+09 | BJ6: 3.5245139e+09 | BK6: 3.525244e+09 | BL6: 3.9134233e+09 | BM6: 3.9553331e+09 | BN6: 3.8274505e+09 | BO6: 4.1531119e+09 | BP6: 3.806433e+09 | BQ6: 3.653287e+09 | BR6: 3.5204568e+09 | BS6: 3.4330083e+09 | BT6: 3.3966449e+09
A7: simple, aggregated to SAU functional group | B7: Jensen comparison, not a PPR estimate | C7: 5.0602905e+08 | D7: 5.5845006e+08 | E7: 6.2463882e+08 | F7: 6.1299965e+08 | G7: 6.9871071e+08 | H7: 7.743209e+08 | I7: 8.6615895e+08 | J7: 9.3160917e+08 | K7: 9.6754432e+08 | L7: 1.00946e+09 | M7: 1.0362456e+09 | N7: 1.0809169e+09 | O7: 1.1290128e+09 | P7: 1.1309574e+09 | Q7: 1.1113999e+09 | R7: 1.1641183e+09 | S7: 1.205388e+09 | T7: 1.2420627e+09 | U7: 1.2879779e+09 | V7: 1.2614205e+09 | W7: 1.3010454e+09 | X7: 1.3356592e+09 | Y7: 1.5457452e+09 | Z7: 1.6258633e+09 | AA7: 1.7330697e+09 | AB7: 1.5806161e+09 | AC7: 1.5252243e+09 | AD7: 1.4926938e+09 | AE7: 1.5543068e+09 | AF7: 1.5846331e+09 | AG7: 1.6477661e+09 | AH7: 1.7207019e+09 | AI7: 1.7536328e+09 | AJ7: 1.7049169e+09 | AK7: 1.8450045e+09 | AL7: 1.7411487e+09 | AM7: 1.8340744e+09 | AN7: 1.9132259e+09 | AO7: 1.928256e+09 | AP7: 2.0858752e+09 | AQ7: 2.2016448e+09 | AR7: 2.4203876e+09 | AS7: 2.3433449e+09 | AT7: 2.4063214e+09 | AU7: 2.8877948e+09 | AV7: 3.1785864e+09 | AW7: 2.8931195e+09 | AX7: 2.77747e+09 | AY7: 3.0701229e+09 | AZ7: 2.8434012e+09 | BA7: 2.8764373e+09 | BB7: 2.8299786e+09 | BC7: 2.811358e+09 | BD7: 2.6344049e+09 | BE7: 2.8952463e+09 | BF7: 2.824483e+09 | BG7: 3.0216925e+09 | BH7: 3.0077081e+09 | BI7: 3.0948169e+09 | BJ7: 2.9253057e+09 | BK7: 2.9223396e+09 | BL7: 3.227518e+09 | BM7: 3.2771812e+09 | BN7: 3.1577149e+09 | BO7: 3.4134611e+09 | BP7: 3.0967889e+09 | BQ7: 2.9829771e+09 | BR7: 2.8757683e+09 | BS7: 2.8150441e+09 | BT7: 2.7843513e+09
A8: simple, aggregated to SAU commercial group | B8: Jensen comparison, not a PPR estimate | C8: 4.543533e+08 | D8: 4.8928473e+08 | E8: 5.4679952e+08 | F8: 5.4282076e+08 | G8: 6.0985634e+08 | H8: 6.838931e+08 | I8: 7.44375e+08 | J8: 8.0844286e+08 | K8: 8.3994603e+08 | L8: 8.7688718e+08 | M8: 8.6935901e+08 | N8: 9.1268668e+08 | O8: 9.4289338e+08 | P8: 9.2775057e+08 | Q8: 8.9683974e+08 | R8: 9.4376476e+08 | S8: 9.8057146e+08 | T8: 1.0213535e+09 | U8: 1.0594683e+09 | V8: 1.0474879e+09 | W8: 1.0592592e+09 | X8: 1.092576e+09 | Y8: 1.2231477e+09 | Z8: 1.324601e+09 | AA8: 1.3870205e+09 | AB8: 1.3058479e+09 | AC8: 1.2669665e+09 | AD8: 1.2945326e+09 | AE8: 1.3071117e+09 | AF8: 1.3349303e+09 | AG8: 1.3686618e+09 | AH8: 1.4053421e+09 | AI8: 1.4279744e+09 | AJ8: 1.3959055e+09 | AK8: 1.4948911e+09 | AL8: 1.450197e+09 | AM8: 1.5196285e+09 | AN8: 1.5506365e+09 | AO8: 1.5500611e+09 | AP8: 1.6383902e+09 | AQ8: 1.7031625e+09 | AR8: 1.835105e+09 | AS8: 1.7888044e+09 | AT8: 1.8435001e+09 | AU8: 2.0947899e+09 | AV8: 2.3741355e+09 | AW8: 2.1955605e+09 | AX8: 2.1553511e+09 | AY8: 2.2886362e+09 | AZ8: 2.1354269e+09 | BA8: 2.1745858e+09 | BB8: 2.1207715e+09 | BC8: 2.0926723e+09 | BD8: 1.932198e+09 | BE8: 2.0898559e+09 | BF8: 2.0087394e+09 | BG8: 2.0922788e+09 | BH8: 2.0867548e+09 | BI8: 2.1510669e+09 | BJ8: 2.071757e+09 | BK8: 2.0535972e+09 | BL8: 2.3409475e+09 | BM8: 2.3830623e+09 | BN8: 2.3041813e+09 | BO8: 2.4699612e+09 | BP8: 2.27007e+09 | BQ8: 2.1813162e+09 | BR8: 2.0770747e+09 | BS8: 2.0688605e+09 | BT8: 2.0160114e+09
A9: SPPR_1986 | B9: returned zero for every mapped group - check the method upstream | C9: 0 | D9: 0 | E9: 0 | F9: 0 | G9: 0 | H9: 0 | I9: 0 | J9: 0 | K9: 0 | L9: 0 | M9: 0 | N9: 0 | O9: 0 | P9: 0 | Q9: 0 | R9: 0 | S9: 0 | T9: 0 | U9: 0 | V9: 0 | W9: 0 | X9: 0 | Y9: 0 | Z9: 0 | AA9: 0 | AB9: 0 | AC9: 0 | AD9: 0 | AE9: 0 | AF9: 0 | AG9: 0 | AH9: 0 | AI9: 0 | AJ9: 0 | AK9: 0 | AL9: 0 | AM9: 0 | AN9: 0 | AO9: 0 | AP9: 0 | AQ9: 0 | AR9: 0 | AS9: 0 | AT9: 0 | AU9: 0 | AV9: 0 | AW9: 0 | AX9: 0 | AY9: 0 | AZ9: 0 | BA9: 0 | BB9: 0 | BC9: 0 | BD9: 0 | BE9: 0 | BF9: 0 | BG9: 0 | BH9: 0 | BI9: 0 | BJ9: 0 | BK9: 0 | BL9: 0 | BM9: 0 | BN9: 0 | BO9: 0 | BP9: 0 | BQ9: 0 | BR9: 0 | BS9: 0 | BT9: 0
A10: SPPR_1995_TE0.1 | B10: ok | C10: 1.5689411e+08 | D10: 1.6848528e+08 | E10: 1.8441935e+08 | F10: 1.8337818e+08 | G10: 1.9673664e+08 | H10: 2.0723898e+08 | I10: 2.2618625e+08 | J10: 2.3206851e+08 | K10: 2.3820436e+08 | L10: 2.3300408e+08 | M10: 2.4184319e+08 | N10: 2.3877462e+08 | O10: 2.5060159e+08 | P10: 2.3962792e+08 | Q10: 2.3253226e+08 | R10: 2.487696e+08 | S10: 2.5730191e+08 | T10: 2.5789913e+08 | U10: 2.6652723e+08 | V10: 2.7102067e+08 | W10: 2.8931376e+08 | X10: 2.9745794e+08 | Y10: 3.1916849e+08 | Z10: 3.5275844e+08 | AA10: 3.7686914e+08 | AB10: 3.7317781e+08 | AC10: 3.8183431e+08 | AD10: 4.1692342e+08 | AE10: 4.4063857e+08 | AF10: 4.4255566e+08 | AG10: 4.547043e+08 | AH10: 4.9274138e+08 | AI10: 4.9952538e+08 | AJ10: 5.1276076e+08 | AK10: 5.5935542e+08 | AL10: 5.4596784e+08 | AM10: 5.9126878e+08 | AN10: 5.8998202e+08 | AO10: 6.1826664e+08 | AP10: 6.1082006e+08 | AQ10: 6.1756434e+08 | AR10: 5.8511155e+08 | AS10: 5.4798527e+08 | AT10: 5.4641867e+08 | AU10: 5.6430877e+08 | AV10: 5.960131e+08 | AW10: 5.8206013e+08 | AX10: 5.9724152e+08 | AY10: 6.1012215e+08 | AZ10: 5.7159511e+08 | BA10: 5.6491057e+08 | BB10: 5.7390599e+08 | BC10: 5.6398726e+08 | BD10: 5.9105251e+08 | BE10: 6.14036e+08 | BF10: 6.0145549e+08 | BG10: 6.1447109e+08 | BH10: 6.0976288e+08 | BI10: 6.3512272e+08 | BJ10: 6.2133767e+08 | BK10: 6.2810826e+08 | BL10: 7.0501825e+08 | BM10: 7.1230294e+08 | BN10: 7.0426124e+08 | BO10: 7.4311155e+08 | BP10: 6.8587863e+08 | BQ10: 6.650818e+08 | BR10: 6.4047218e+08 | BS10: 6.29619e+08 | BT10: 6.5134559e+08
A11: SPPR_1995_TEmean | B11: ok | C11: 2248755.4 | D11: 2437576 | E11: 2593143.6 | F11: 2643839.8 | G11: 2845065.6 | H11: 2997217.6 | I11: 3273985.2 | J11: 3477329.2 | K11: 3568141.6 | L11: 3546957.3 | M11: 3645076.2 | N11: 3783362.2 | O11: 3913911.3 | P11: 3753410.6 | Q11: 3720131.3 | R11: 3969951 | S11: 4094923.1 | T11: 4157725.5 | U11: 4388897.9 | V11: 4478790.8 | W11: 4731013.8 | X11: 4842479 | Y11: 5126587 | Z11: 5706365.7 | AA11: 6075781.6 | AB11: 6265172.8 | AC11: 6496680.6 | AD11: 7171009.5 | AE11: 7736593.3 | AF11: 7672048 | AG11: 7798203.7 | AH11: 8436150.4 | AI11: 8674523.9 | AJ11: 9121109.1 | AK11: 9904341.9 | AL11: 9727448 | AM11: 10661718 | AN11: 10531474 | AO11: 11129521 | AP11: 10827191 | AQ11: 10810077 | AR11: 9991253.1 | AS11: 9405158.3 | AT11: 9567972.3 | AU11: 9871834.6 | AV11: 10358780 | AW11: 9955905.8 | AX11: 10330181 | AY11: 10361009 | AZ11: 9852273.8 | BA11: 9597581.7 | BB11: 9749930.8 | BC11: 9517646.3 | BD11: 10023137 | BE11: 10298979 | BF11: 10180309 | BG11: 10211904 | BH11: 10036535 | BI11: 10453415 | BJ11: 10129129 | BK11: 10251328 | BL11: 11200546 | BM11: 11330664 | BN11: 11145152 | BO11: 11914976 | BP11: 11024395 | BQ11: 10634962 | BR11: 10346084 | BS11: 10213458 | BT11: 10737691
