Workbook

Sheet Summary
A1: LME_013 — Humboldt Current
A2: Ecopath model: 13_2_Northern_Humboldt_Current_(1995-1998)
A3: Northern Humboldt model only. Selection does not override failed SPPR configurations. Northern Humboldt Current, 1995-1998: source audit
A5: region type | B5: LME
A6: latitude | B6: -44.05031
A7: longitude | B7: -73.05294
A8: catch years | B8: 1950-2019
A9: taxa in catch | B9: 218
A10: taxa apportioned across groups | B10: 18
A11: taxa unresolved | B11: 48
A12: catch tonnage on a named group, % | B12: 98.2
A13: SPPR methods | B13: 20
A14: methods flagged as unusable | B14: 6
A15: headline method below | B15: new_TE_noEEfix
A17: year | B17: catch_tonnes | C17: ppr_simple | D17: ppr_new_TE_noEEfix | E17: ppr_simple / NPP % | F17: ppr_new_TE_noEEfix / NPP %
A18: 1950 | B18: 212918.96 | C18: 2.6683935e+08 | D18: 1.4779014e+08 | E18: 4.6922 | F18: 2.5988
A19: 1951 | B19: 261140.88 | C19: 3.3732702e+08 | D19: 1.5759582e+08 | E19: 5.9317 | F19: 2.7712
A20: 1952 | B20: 300323.82 | C20: 3.9471552e+08 | D20: 1.9008143e+08 | E20: 6.9408 | F20: 3.3425
A21: 1953 | B21: 310451.16 | C21: 3.4738331e+08 | D21: 1.662113e+08 | E21: 6.1085 | F21: 2.9227
A22: 1954 | B22: 334077.41 | C22: 3.7143913e+08 | D22: 2.1120996e+08 | E22: 6.5315 | F22: 3.714
A23: 1955 | B23: 436073.83 | C23: 5.2078429e+08 | D23: 2.2524543e+08 | E23: 9.1577 | F23: 3.9608
A24: 1956 | B24: 484327.48 | C24: 5.2295353e+08 | D24: 2.4309147e+08 | E24: 9.1958 | F24: 4.2746
A25: 1957 | B25: 676783.96 | C25: 4.4905999e+08 | D25: 2.4540346e+08 | E25: 7.8964 | F25: 4.3153
A26: 1958 | B26: 1146316.7 | C26: 4.9763083e+08 | D26: 2.9650555e+08 | E26: 8.7505 | F26: 5.2139
A27: 1959 | B27: 2540138.3 | C27: 6.1824572e+08 | D27: 4.0819256e+08 | E27: 10.8715 | F27: 7.1778
A28: 1960 | B28: 4388998.5 | C28: 7.8733261e+08 | D28: 5.5163375e+08 | E28: 13.8447 | F28: 9.7001
A29: 1961 | B29: 6614336.8 | C29: 8.9759123e+08 | D29: 6.3461237e+08 | E29: 15.7836 | F29: 11.1593
... A87: 2019 | B87: 7390380.7 | C87: 2.6120525e+09 | D87: 3.6299878e+09 | E87: 45.9313 | F87: 63.831
A88: PPR/NPP converts wet-weight PP to carbon at 9:1; NPP is the fixed 2019 ensemble median.

Sheet Catch
A1: taxon | B1: common_name | C1: functional_group | D1: commercial_group | E1: 1950 | F1: 1951 | G1: 1952 | H1: 1953 | I1: 1954 | J1: 1955 | K1: 1956 | L1: 1957 | M1: 1958 | N1: 1959 | O1: 1960 | P1: 1961 | Q1: 1962 | R1: 1963 | S1: 1964 | T1: 1965 | U1: 1966 | V1: 1967 | W1: 1968 | X1: 1969 | Y1: 1970 | Z1: 1971 | AA1: 1972 | AB1: 1973 | AC1: 1974 | AD1: 1975 | AE1: 1976 | AF1: 1977 | AG1: 1978 | AH1: 1979 | AI1: 1980 | AJ1: 1981 | AK1: 1982 | AL1: 1983 | AM1: 1984 | AN1: 1985 | AO1: 1986 | AP1: 1987 | AQ1: 1988 | AR1: 1989 | AS1: 1990 | AT1: 1991 | AU1: 1992 | AV1: 1993 | AW1: 1994 | AX1: 1995 | AY1: 1996 | AZ1: 1997 | BA1: 1998 | BB1: 1999 | BC1: 2000 | BD1: 2001 | BE1: 2002 | BF1: 2003 | BG1: 2004 | BH1: 2005 | BI1: 2006 | BJ1: 2007 | BK1: 2008 | BL1: 2009 | BM1: 2010 | BN1: 2011 | BO1: 2012 | BP1: 2013 | BQ1: 2014 | BR1: 2015 | BS1: 2016 | BT1: 2017 | BU1: 2018 | BV1: 2019
A2: Engraulis ringens | B2: Anchoveta | C2: Small pelagics (<30 cm) | D2: Anchovies | E2: 13051.364 | F2: 27823.604 | G2: 33693.703 | H2: 55415.306 | I2: 62075.321 | J2: 77481.406 | K2: 137184.41 | L2: 352466.38 | M2: 795065.71 | N2: 2163651.1 | O2: 3965688.3 | P2: 6198660 | Q2: 8359449.5 | R2: 8622669.4 | S2: 12072139 | T2: 9331412.8 | U2: 11778956 | V2: 13200387 | W2: 14133397 | X2: 12018897 | Y2: 16787916 | Z2: 14108560 | AA2: 5606277.9 | AB2: 1870263.6 | AC2: 5001848 | AD2: 4068389.1 | AE2: 4991739.6 | AF2: 1001487.9 | AG2: 1930131.6 | AH2: 1670798 | AI2: 1017621.9 | AJ2: 1835779.9 | AK2: 2320019.3 | AL2: 399735.41 | AM2: 354461.02 | AN2: 1322382.4 | AO2: 5809116.4 | AP2: 3347143.4 | AQ2: 4237965.2 | AR2: 6329552.5 | AS2: 4437669.2 | AT2: 4760994.8 | AU2: 7377564.9 | AV2: 10024073 | AW2: 15080468 | AX2: 10136795 | AY2: 10865490 | AZ2: 9013175.6 | BA2: 2061385.6 | BB2: 10477273 | BC2: 13968435 | BD2: 8855660.3 | BE2: 11895176 | BF2: 7477569.8 | BG2: 13187989 | BH2: 12630739 | BI2: 8265312.3 | BJ2: 8954899 | BK2: 8730006.8 | BL2: 8046932.7 | BM2: 4906342.9 | BN2: 10511532 | BO2: 5762970.9 | BP2: 6761447.3 | BQ2: 3935545.2 | BR2: 4660546.8 | BS2: 3515005.5 | BT2: 4161342.2 | BU2: 7419198.3 | BV2: 4598511.9
A3: Sardinops sagax | B3: South American pilchard | C3: Medium pelagics (30 - 89 cm) | D3: Herring-likes | E3: 2334.138 | F3: 3946.11 | G3: 4102.227 | H3: 4396.81 | I3: 4218.527 | J3: 6002.518 | K3: 6469.426 | L3: 5813.352 | M3: 7827.616 | N3: 11794.215 | O3: 15810.182 | P3: 17187.03 | Q3: 19121.794 | R3: 26669.556 | S3: 48836.606 | T3: 29834.855 | U3: 50389.506 | V3: 39775.021 | W3: 47088.552 | X3: 37409.098 | Y3: 43099.219 | Z3: 63846.186 | AA3: 36815.694 | AB3: 218399.89 | AC3: 543715.64 | AD3: 500052.28 | AE3: 908533.95 | AF3: 2268966.5 | AG3: 2945273.6 | AH3: 3598953.2 | AI3: 3476313.4 | AJ3: 3018014.6 | AK3: 5314038.5 | AL3: 3848562 | AM3: 5778927.1 | AN3: 6248878.2 | AO3: 4639499.6 | AP3: 5029278.1 | AQ3: 5541786.6 | AR3: 4655341.1 | AS3: 4748000.8 | AT3: 4740591.1 | AU3: 3493354.7 | AV3: 2124506.5 | AW3: 1937681.8 | AX3: 1646594.9 | AY3: 1424754.2 | AZ3: 799325.09 | BA3: 1122981.8 | BB3: 467204.1 | BC3: 374605.96 | BD3: 246404.88 | BE3: 23282.802 | BF3: 174954.85 | BG3: 198734.06 | BH3: 138215.46 | BI3: 82185.603 | BJ3: 63166.898 | BK3: 27581.843 | BL3: 30823.882 | BM3: 70636.811 | BN3: 196066.17 | BO3: 180.699 | BP3: 6270.739 | BQ3: 905.666 | BR3: 1343.788 | BS3: 3389.82 | BT3: 3003.996 | BU3: 4118.18 | BV3: 3986.145
A4: Trachurus murphyi | B4: Chilean jack mackerel | C4: Medium pelagics (30 - 89 cm) | D4: Perch-likes | E4: 2723.76 | F4: 3465.039 | G4: 4422.72 | H4: 4474.124 | I4: 4970.276 | J4: 6193.638 | K4: 6319.594 | L4: 6510.126 | M4: 2450.776 | N4: 7570.675 | O4: 12753.718 | P4: 14651.75 | Q4: 17502.747 | R4: 27769.284 | S4: 39553.442 | T4: 29417.177 | U4: 53814.265 | V4: 50750.604 | W4: 56778.359 | X4: 45642.611 | Y4: 126430.62 | Z4: 177890.91 | AA4: 112268.2 | AB4: 161421.48 | AC4: 347283.99 | AD4: 486051.32 | AE4: 374019.44 | AF4: 1147803.7 | AG4: 1419845.4 | AH4: 696140.13 | AI4: 638322.97 | AJ4: 1210916.3 | AK4: 1603737.1 | AL4: 1862878.7 | AM4: 1743324.3 | AN4: 1650575.9 | AO4: 1497512 | AP4: 1884123.1 | AQ4: 2388587.2 | AR4: 2766412.6 | AS4: 2826446.6 | AT4: 2884212.1 | AU4: 2550677.4 | AV4: 2433474 | AW4: 3044146 | AX4: 3517467.7 | AY4: 3267803.8 | AZ4: 2750969.9 | BA4: 1571500.4 | BB4: 1050807.7 | BC4: 1215598.5 | BD4: 2026079.2 | BE4: 1278299.2 | BF4: 1382379 | BG4: 1436217.3 | BH4: 1274674.4 | BI4: 1442104.1 | BJ4: 1333610.7 | BK4: 949116.28 | BL4: 795871.42 | BM4: 488531.48 | BN4: 803964.17 | BO4: 659320.27 | BP4: 524678.64 | BQ4: 543025.38 | BR4: 257066.04 | BS4: 348666.21 | BT4: 339030.05 | BU4: 465932.18 | BV4: 580714.21
A5: Clupeidae | B5: Herrings, sardines, menhadens | C5: Small pelagics (<30 cm) | D5: Herring-likes | E5: 8519.935 | F5: 5688.111 | G5: 6966.255 | H5: 17075.344 | I5: 16272.28 | J5: 23944.014 | K5: 11018.514 | L5: 18556.822 | M5: 16471.058 | N5: 36360.091 | O5: 30229.56 | P5: 32058.269 | Q5: 26966.459 | R5: 41694.913 | S5: 61241.837 | T5: 53411.18 | U5: 85660.666 | V5: 132567.35 | W5: 120043.19 | X5: 132750.27 | Y5: 82865.073 | Z5: 186179.06 | AA5: 129768.56 | AB5: 137692.11 | AC5: 368943.35 | AD5: 104566.78 | AE5: 69658.746 | AF5: 70731.487 | AG5: 138839.36 | AH5: 86606.11 | AI5: 106008.09 | AJ5: 126297.1 | AK5: 210674.79 | AL5: 146104.64 | AM5: 159152.98 | AN5: 160563.2 | AO5: 178832.91 | AP5: 151587.99 | AQ5: 154586.13 | AR5: 322806.26 | AS5: 400433.23 | AT5: 680676.74 | AU5: 590272.41 | AV5: 235503.2 | AW5: 315947.53 | AX5: 177646.89 | AY5: 560906.11 | AZ5: 460162.77 | BA5: 361660.73 | BB5: 759253.05 | BC5: 628568.63 | BD5: 444886.19 | BE5: 591941.24 | BF5: 427112.13 | BG5: 510482.87 | BH5: 393535.06 | BI5: 482027.81 | BJ5: 318056.06 | BK5: 757819.74 | BL5: 816424.32 | BM5: 758107.05 | BN5: 615377.43 | BO5: 429685.08 | BP5: 242.096 | BQ5: 159240.57 | BR5: 72164.357 | BS5: 290851.05 | BT5: 13286.096 | BU5: 16674.25 | BV5: 18060.134
A6: Dosidicus gigas | B6: Jumbo flying squid | C6: Cephalopods | D6: Other fishes & inverts | E6: 18.598 | F6: 11.746 | G6: 29.366 | H6: 19.577 | I6: 35.229 | J6: 17.619 | K6: 47.964 | L6: 109.592 | M6: 178.141 | N6: 271.142 | O6: 404.265 | P6: 589.485 | Q6: 3590.237 | R6: 4056.639 | S6: 4637.752 | T6: 897.227 | U6: 1081.133 | V6: 2183.367 | W6: 1976.037 | X6: 1926.228 | Y6: 2314.499 | Z6: 2364.943 | AA6: 973.396 | AB6: 3234.415 | AC6: 3708.553 | AD6: 2232.172 | AE6: 3612.455 | AF6: 6060.031 | AG6: 8338.934 | AH6: 3565.222 | AI6: 3883.272 | AJ6: 1793.358 | AK6: 2248.427 | AL6: 857.456 | AM6: 2237.948 | AN6: 1693.773 | AO6: 2720.516 | AP6: 1349.107 | AQ6: 3699.622 | AR6: 6929.448 | AS6: 14077.28 | AT6: 91784.006 | AU6: 136478.3 | AV6: 176654.94 | AW6: 247110.18 | AX6: 134154.41 | AY6: 41623.42 | AZ6: 36808.91 | BA6: 9091.155 | BB6: 110593.3 | BC6: 163537.35 | BD6: 196311.39 | BE6: 288792.26 | BF6: 485973.05 | BG6: 655155.81 | BH6: 745654.73 | BI6: 857240.54 | BJ6: 651864.16 | BK6: 855230.95 | BL6: 635411.92 | BM6: 622147.38 | BN6: 766836.47 | BO6: 859867.84 | BP6: 772406.59 | BQ6: 971546.41 | BR6: 914203.22 | BS6: 683829.47 | BT6: 607661.31 | BU6: 695433.58 | BV6: 759913.37
A7: Scomber japonicus | B7: Pacific chub mackerel | C7: Medium pelagics (30 - 89 cm) | D7: Perch-likes | E7: 2519.096 | F7: 1205.012 | G7: 3613.153 | H7: 2080.839 | I7: 3831.469 | J7: 1406.159 | K7: 3998.361 | L7: 9304.071 | M7: 13622.897 | N7: 10164.09 | O7: 9933.496 | P7: 12362.652 | Q7: 14061.024 | R7: 8355.323 | S7: 2114.839 | T7: 4024.266 | U7: 7991.551 | V7: 14101.629 | W7: 7586.286 | X7: 7587.313 | Y7: 9264.229 | Z7: 10633.926 | AA7: 9154.979 | AB7: 69217.025 | AC7: 67633.451 | AD7: 25286.448 | AE7: 139801.66 | AF7: 317905.3 | AG7: 465091.13 | AH7: 214245.05 | AI7: 163393.02 | AJ7: 144478.81 | AK7: 58701.524 | AL7: 41698.719 | AM7: 204953.8 | AN7: 80830.56 | AO7: 43448.412 | AP7: 57549.484 | AQ7: 54800.932 | AR7: 93253.599 | AS7: 293978.92 | AT7: 220779.52 | AU7: 89354.908 | AV7: 123471.53 | AW7: 72724.616 | AX7: 152030.84 | AY7: 192008.29 | AZ7: 417487.2 | BA7: 486493.41 | BB7: 662729.79 | BC7: 167480.35 | BD7: 533922.44 | BE7: 51169.298 | BF7: 644862.6 | BG7: 616558.41 | BH7: 323932.18 | BI7: 460406.61 | BJ7: 349908.18 | BK7: 225325.6 | BL7: 268144.39 | BM7: 115404.41 | BN7: 74243.564 | BO7: 195133.85 | BP7: 106665.17 | BQ7: 391410.44 | BR7: 101771.27 | BS7: 240034.14 | BT7: 187987.2 | BU7: 137659.57 | BV7: 147607.05
A8: Marine fishes not identified | B8: Marine fishes nei | C8: Medium demersals (30 - 89 cm) | D8: Other fishes & inverts | E8: 11265.589 | F8: 13020.736 | G8: 14159.799 | H8: 12346.07 | I8: 15933.829 | J8: 17913.988 | K8: 16148.9 | L8: 16495.312 | M8: 19046.473 | N8: 18638.906 | O8: 20500.125 | P8: 15272.512 | Q8: 72407.426 | R8: 629990.93 | S8: 921868.46 | T8: 16681.662 | U8: 42394.093 | V8: 47348.101 | W8: 27978.246 | X8: 20265.245 | Y8: 70814.217 | Z8: 19227.468 | AA8: 34583.043 | AB8: 225307.46 | AC8: 52326.634 | AD8: 81363.335 | AE8: 52483.07 | AF8: 116367.81 | AG8: 120698.01 | AH8: 62073.512 | AI8: 63196.186 | AJ8: 53308.948 | AK8: 47569.749 | AL8: 84722.382 | AM8: 76479.318 | AN8: 65700.66 | AO8: 133274.53 | AP8: 69337.516 | AQ8: 63362.517 | AR8: 157861.04 | AS8: 178124.86 | AT8: 135906.34 | AU8: 90708.752 | AV8: 111968.14 | AW8: 73080.305 | AX8: 133343.82 | AY8: 120665.2 | AZ8: 163744.98 | BA8: 474518.38 | BB8: 243513.07 | BC8: 156559.29 | BD8: 207438.76 | BE8: 100188.43 | BF8: 118422.75 | BG8: 134033.1 | BH8: 238351.58 | BI8: 206503.61 | BJ8: 217743.38 | BK8: 208879.97 | BL8: 210040.77 | BM8: 172020.25 | BN8: 194353.78 | BO8: 177195.93 | BP8: 215767.16 | BQ8: 206401.85 | BR8: 116792.39 | BS8: 136733.77 | BT8: 70543.657 | BU8: 72245.071 | BV8: 172560.57
A9: Merluccius peruanus | B9: Peruvian hake | C9: Medium bathydemersals (30 - 89 cm) | D9: Cod-likes | E9: 0 | F9: 0 | G9: 0 | H9: 24.522 | I9: 11.77 | J9: 16.675 | K9: 6.866 | L9: 12.751 | M9: 17.655 | N9: 0 | O9: 0 | P9: 0 | Q9: 0 | R9: 0 | S9: 0 | T9: 1269.402 | U9: 673.54 | V9: 23179.52 | W9: 21148.182 | X9: 18074.624 | Y9: 20335.073 | Z9: 32134.822 | AA9: 14879.165 | AB9: 156891.56 | AC9: 129061.3 | AD9: 100224.03 | AE9: 109557.78 | AF9: 126051.27 | AG9: 358310.14 | AH9: 109711.1 | AI9: 188085.78 | AJ9: 81783.425 | AK9: 31269.462 | AL9: 6886.501 | AM9: 14288.186 | AN9: 21683.922 | AO9: 45965.416 | AP9: 37793.877 | AQ9: 93074.31 | AR9: 103862.26 | AS9: 150235.76 | AT9: 86116.299 | AU9: 35895.346 | AV9: 104724.6 | AW9: 160177.14 | AX9: 213887.49 | AY9: 277426.82 | AZ9: 210074.55 | BA9: 97268.295 | BB9: 43967.441 | BC9: 98551.443 | BD9: 148191.61 | BE9: 54855.927 | BF9: 9167.804 | BG9: 46225.962 | BH9: 37039.053 | BI9: 35379.871 | BJ9: 37690.158 | BK9: 41287.558 | BL9: 54994.1 | BM9: 48794.589 | BN9: 44547.236 | BO9: 39820.635 | BP9: 65074.846 | BQ9: 76505.182 | BR9: 67910.595 | BS9: 86697.842 | BT9: 95190.469 | BU9: 90240.838 | BV9: 63732.511
A10: Merluccius gayi | B10: South Pacific hake | C10: Medium bathydemersals (30 - 89 cm) | D10: Cod-likes | E10: 35174.91 | F10: 45901.178 | G10: 69336.091 | H10: 65978.318 | I10: 56807.325 | J10: 87504.77 | K10: 74439.066 | L10: 72073.579 | M10: 69686.807 | N10: 67413.118 | O10: 74658.713 | P10: 70752.132 | Q10: 87250.865 | R10: 94733.107 | S10: 67977.392 | T10: 96751.182 | U10: 86913.429 | V10: 72780.759 | W10: 117932.71 | X10: 73631.696 | Y10: 97344.331 | Z10: 61002.102 | AA10: 88096.882 | AB10: 81225.2 | AC10: 40512.836 | AD10: 58797.901 | AE10: 28944.562 | AF10: 66971.332 | AG10: 67370.832 | AH10: 32734.489 | AI10: 31683.015 | AJ10: 37020.523 | AK10: 35418.337 | AL10: 51134.626 | AM10: 39225.787 | AN10: 35480.357 | AO10: 34221.953 | AP10: 117994.95 | AQ10: 56700.854 | AR10: 74578.643 | AS10: 103528.37 | AT10: 76752.442 | AU10: 73487.296 | AV10: 72598.291 | AW10: 80562.068 | AX10: 88193.871 | AY10: 96717.574 | AZ10: 85518.465 | BA10: 70545.44 | BB10: 83235.587 | BC10: 71638.674 | BD10: 97806.802 | BE10: 30004.709 | BF10: 91964.084 | BG10: 63456.297 | BH10: 44837.79 | BI10: 44385.357 | BJ10: 42374.729 | BK10: 40659.394 | BL10: 40295.873 | BM10: 40195.176 | BN10: 70263.68 | BO10: 65711.418 | BP10: 46952.246 | BQ10: 48063.782 | BR10: 20822.398 | BS10: 22122.227 | BT10: 23997.435 | BU10: 25183.916 | BV10: 28557.488
A11: Macruronus magellanicus | B11: Patagonian grenadier | C11: Large benthopelagics (>=90 cm) | D11: Cod-likes | E11: 0 | F11: 0 | G11: 0 | H11: 0 | I11: 0 | J11: 0 | K11: 0 | L11: 0 | M11: 0 | N11: 0 | O11: 0 | P11: 0 | Q11: 0 | R11: 0 | S11: 0 | T11: 0 | U11: 0 | V11: 0 | W11: 0 | X11: 0 | Y11: 0 | Z11: 0 | AA11: 0 | AB11: 0 | AC11: 0 | AD11: 0 | AE11: 0 | AF11: 0 | AG11: 35.487 | AH11: 293.484 | AI11: 17609.979 | AJ11: 22697.988 | AK11: 17663.688 | AL11: 21585.436 | AM11: 25691.33 | AN11: 1703.356 | AO11: 35564.274 | AP11: 35714.852 | AQ11: 202967.93 | AR11: 218092.88 | AS11: 122766.33 | AT11: 157960.39 | AU11: 205557.49 | AV11: 79202.226 | AW11: 77984.172 | AX11: 198277.95 | AY11: 360089.11 | AZ11: 68555.291 | BA11: 339696.79 | BB11: 297227.98 | BC11: 86682.224 | BD11: 155452.35 | BE11: 6181.38 | BF11: 82382.591 | BG11: 68265.643 | BH11: 76492.777 | BI11: 70417.857 | BJ11: 61091.598 | BK11: 70557.885 | BL11: 75231.564 | BM11: 71289.676 | BN11: 0 | BO11: 0 | BP11: 0 | BQ11: 0 | BR11: 9776.518 | BS11: 8967.537 | BT11: 3656.492 | BU11: 3854.962 | BV11: 2182.201
A12: Sarda chiliensis | B12: Eastern Pacific bonito | C12: Medium pelagics (30 - 89 cm) | D12: Tuna & billfishes | E12: 44696.628 | F12: 62305.13 | G12: 64336.802 | H12: 52525.374 | I12: 64432.691 | J12: 89602.275 | K12: 98460.855 | L12: 68139.098 | M12: 78136.981 | N12: 94760.862 | O12: 110505.38 | P12: 121592.76 | Q12: 103476.3 | R12: 104305.23 | S12: 97316.076 | T12: 83229.517 | U12: 94821.061 | V12: 81473.06 | W12: 65896.961 | X12: 75877.501 | Y12: 69704.475 | Z12: 83675.266 | AA12: 126011.06 | AB12: 43836.304 | AC12: 10834.793 | AD12: 5861.023 | AE12: 5189.303 | AF12: 13031.17 | AG12: 10920.406 | AH12: 10410.432 | AI12: 10825.342 | AJ12: 13358.227 | AK12: 25308.045 | AL12: 31519.98 | AM12: 32111.488 | AN12: 11300.567 | AO12: 5854.531 | AP12: 21739.573 | AQ12: 38590.11 | AR12: 29572.427 | AS12: 44581.962 | AT12: 28896.305 | AU12: 39422.438 | AV12: 41871.814 | AW12: 35204.476 | AX12: 31753.06 | AY12: 25849.265 | AZ12: 19890.902 | BA12: 6510.872 | BB12: 1534.966 | BC12: 539.913 | BD12: 1467.918 | BE12: 988.638 | BF12: 2469.446 | BG12: 1658.338 | BH12: 3397 | BI12: 14500.112 | BJ12: 10522.728 | BK12: 46611.658 | BL12: 33881.481 | BM12: 14824.778 | BN12: 16143.383 | BO12: 26736.237 | BP12: 42359.607 | BQ12: 45705.083 | BR12: 107182.21 | BS12: 90844.043 | BT12: 111900.85 | BU12: 91096.552 | BV12: 91729.877
... A124: Tegula atra | B124: Smooth black trochid | C124: Other demersal invertebrates | D124: Molluscs | E124: 0 | F124: 0 | G124: 0 | H124: 0 | I124: 0 | J124: 0 | K124: 0 | L124: 0 | M124: 0 | N124: 0 | O124: 0 | P124: 0 | Q124: 0 | R124: 0 | S124: 0 | T124: 0 | U124: 0 | V124: 0 | W124: 0 | X124: 0 | Y124: 0 | Z124: 0 | AA124: 0 | AB124: 0 | AC124: 0 | AD124: 0 | AE124: 0 | AF124: 0 | AG124: 0 | AH124: 0 | AI124: 0 | AJ124: 0 | AK124: 0 | AL124: 0 | AM124: 0 | AN124: 0 | AO124: 0 | AP124: 0 | AQ124: 0 | AR124: 0 | AS124: 0 | AT124: 0 | AU124: 0 | AV124: 0 | AW124: 0 | AX124: 0 | AY124: 0 | AZ124: 0 | BA124: 0 | BB124: 0 | BC124: 0 | BD124: 0 | BE124: 0 | BF124: 0 | BG124: 0 | BH124: 0 | BI124: 0 | BJ124: 0 | BK124: 0 | BL124: 0 | BM124: 0 | BN124: 236.39 | BO124: 3525.516 | BP124: 22.343 | BQ124: 618.68 | BR124: 47.018 | BS124: 64.115 | BT124: 34.416 | BU124: 34.475 | BV124: 24.211
A125: Fissurella latimarginata | C125: Other demersal invertebrates | D125: Molluscs | E125: 0 | F125: 0 | G125: 0 | H125: 0 | I125: 0 | J125: 0 | K125: 0 | L125: 0 | M125: 0 | N125: 0 | O125: 0 | P125: 0 | Q125: 0 | R125: 0 | S125: 0 | T125: 0 | U125: 0 | V125: 0 | W125: 0 | X125: 0 | Y125: 0 | Z125: 0 | AA125: 0 | AB125: 0 | AC125: 0 | AD125: 0 | AE125: 0 | AF125: 0 | AG125: 0 | AH125: 0 | AI125: 0 | AJ125: 0 | AK125: 0 | AL125: 0 | AM125: 0 | AN125: 0 | AO125: 0 | AP125: 0 | AQ125: 0 | AR125: 0 | AS125: 0 | AT125: 0 | AU125: 0 | AV125: 0 | AW125: 0 | AX125: 0 | AY125: 0 | AZ125: 0 | BA125: 0 | BB125: 0 | BC125: 0 | BD125: 0 | BE125: 0 | BF125: 0 | BG125: 0 | BH125: 0 | BI125: 0 | BJ125: 0 | BK125: 0 | BL125: 0 | BM125: 0 | BN125: 110.707 | BO125: 596.413 | BP125: 245.915 | BQ125: 732.074 | BR125: 656.412 | BS125: 744.295 | BT125: 615.669 | BU125: 484.61 | BV125: 274.479
A126: Athyonidium chilensis | B126: Burrowing shaggy sea cucumber | C126: Other demersal invertebrates | D126: Other fishes & inverts | E126: 0 | F126: 0 | G126: 0 | H126: 0 | I126: 0 | J126: 0 | K126: 0 | L126: 0 | M126: 0 | N126: 0 | O126: 0 | P126: 0 | Q126: 0 | R126: 0 | S126: 0 | T126: 0 | U126: 0 | V126: 0 | W126: 0 | X126: 0 | Y126: 0 | Z126: 0 | AA126: 0 | AB126: 0 | AC126: 0 | AD126: 0 | AE126: 0 | AF126: 0 | AG126: 0 | AH126: 0 | AI126: 0 | AJ126: 0 | AK126: 0 | AL126: 0 | AM126: 0 | AN126: 0 | AO126: 0 | AP126: 0 | AQ126: 0 | AR126: 0 | AS126: 0 | AT126: 0 | AU126: 0 | AV126: 0 | AW126: 0 | AX126: 0 | AY126: 0 | AZ126: 0 | BA126: 0 | BB126: 0 | BC126: 0 | BD126: 0 | BE126: 0 | BF126: 0 | BG126: 0 | BH126: 0 | BI126: 0 | BJ126: 0 | BK126: 0 | BL126: 0 | BM126: 0 | BN126: 382.992 | BO126: 1792.14 | BP126: 40.865 | BQ126: 142.345 | BR126: 0 | BS126: 222.584 | BT126: 441.922 | BU126: 911.395 | BV126: 246.587
A127: Paralichthys | B127: Paralichthyid flounders | C127: Small to medium flatfishes (<90 cm) | D127: Flatfishes | E127: 0 | F127: 0 | G127: 0 | H127: 0 | I127: 0 | J127: 0 | K127: 0 | L127: 0 | M127: 0 | N127: 0 | O127: 0 | P127: 0 | Q127: 0 | R127: 0 | S127: 0 | T127: 0 | U127: 0 | V127: 0 | W127: 0 | X127: 0 | Y127: 0 | Z127: 0 | AA127: 0 | AB127: 0 | AC127: 0 | AD127: 0 | AE127: 0 | AF127: 0 | AG127: 0 | AH127: 0 | AI127: 0 | AJ127: 0 | AK127: 0 | AL127: 0 | AM127: 0 | AN127: 0 | AO127: 0 | AP127: 0 | AQ127: 0 | AR127: 0 | AS127: 0 | AT127: 0 | AU127: 0 | AV127: 0 | AW127: 0 | AX127: 0 | AY127: 0 | AZ127: 0 | BA127: 0 | BB127: 0 | BC127: 0 | BD127: 0 | BE127: 3.644 | BF127: 31.704 | BG127: 0 | BH127: 9.828 | BI127: 0 | BJ127: 0 | BK127: 39.753 | BL127: 0 | BM127: 27.532 | BN127: 654.494 | BO127: 0 | BP127: 0 | BQ127: 3210.917 | BR127: 0 | BS127: 0 | BT127: 12.412 | BU127: 5.729 | BV127: 2.864
A128: Fissurella cumingi | B128: keyhole limpet | C128: Other demersal invertebrates | D128: Molluscs | E128: 0 | F128: 0 | G128: 0 | H128: 0 | I128: 0 | J128: 0 | K128: 0 | L128: 0 | M128: 0 | N128: 0 | O128: 0 | P128: 0 | Q128: 0 | R128: 0 | S128: 0 | T128: 0 | U128: 0 | V128: 0 | W128: 0 | X128: 0 | Y128: 0 | Z128: 0 | AA128: 0 | AB128: 0 | AC128: 0 | AD128: 0 | AE128: 0 | AF128: 0 | AG128: 0 | AH128: 0 | AI128: 0 | AJ128: 0 | AK128: 0 | AL128: 0 | AM128: 0 | AN128: 0 | AO128: 0 | AP128: 0 | AQ128: 0 | AR128: 0 | AS128: 0 | AT128: 0 | AU128: 0 | AV128: 0 | AW128: 0 | AX128: 0 | AY128: 0 | AZ128: 0 | BA128: 0 | BB128: 0 | BC128: 0 | BD128: 0 | BE128: 0 | BF128: 0 | BG128: 0 | BH128: 0 | BI128: 0 | BJ128: 0 | BK128: 0 | BL128: 0 | BM128: 0 | BN128: 31.169 | BO128: 3483.209 | BP128: 13.552 | BQ128: 13.326 | BR128: 44.288 | BS128: 16.203 | BT128: 7.716 | BU128: 25.652 | BV128: 15.938
A129: Penaeus californiensis | B129: Yellowleg shrimp | C129: Shrimps | D129: Crustaceans | E129: 0 | F129: 0 | G129: 0 | H129: 0 | I129: 0 | J129: 0 | K129: 0 | L129: 0 | M129: 0 | N129: 0 | O129: 0 | P129: 0 | Q129: 0 | R129: 0 | S129: 0 | T129: 0 | U129: 0 | V129: 0 | W129: 0 | X129: 0 | Y129: 0 | Z129: 0 | AA129: 0 | AB129: 0 | AC129: 0 | AD129: 0 | AE129: 0 | AF129: 0 | AG129: 0 | AH129: 0 | AI129: 0 | AJ129: 0 | AK129: 0 | AL129: 0 | AM129: 0 | AN129: 0 | AO129: 0 | AP129: 0 | AQ129: 0 | AR129: 0 | AS129: 0 | AT129: 0 | AU129: 0 | AV129: 0 | AW129: 0 | AX129: 0 | AY129: 0 | AZ129: 0 | BA129: 0 | BB129: 0 | BC129: 0 | BD129: 0 | BE129: 0 | BF129: 0 | BG129: 0 | BH129: 0 | BI129: 0 | BJ129: 0 | BK129: 0 | BL129: 0 | BM129: 0 | BN129: 0 | BO129: 0 | BP129: 0 | BQ129: 0 | BR129: 0 | BS129: 0 | BT129: 0 | BU129: 0 | BV129: 2903.747
A130: Ovalipes trimaculatus | B130: Rowing crab | C130: Lobsters, crabs | D130: Crustaceans | E130: 0 | F130: 0 | G130: 0 | H130: 0 | I130: 0 | J130: 0 | K130: 0 | L130: 0 | M130: 0 | N130: 0 | O130: 0 | P130: 0 | Q130: 0 | R130: 0 | S130: 0 | T130: 0 | U130: 0 | V130: 0 | W130: 0 | X130: 0 | Y130: 0 | Z130: 0 | AA130: 0 | AB130: 0 | AC130: 0 | AD130: 0 | AE130: 0 | AF130: 0 | AG130: 0 | AH130: 0 | AI130: 0 | AJ130: 0 | AK130: 0 | AL130: 0 | AM130: 0 | AN130: 0 | AO130: 0 | AP130: 0 | AQ130: 0 | AR130: 0 | AS130: 0 | AT130: 0 | AU130: 0 | AV130: 0 | AW130: 0 | AX130: 0 | AY130: 0 | AZ130: 0 | BA130: 0 | BB130: 0 | BC130: 0 | BD130: 0 | BE130: 0 | BF130: 0 | BG130: 0 | BH130: 0 | BI130: 0 | BJ130: 0 | BK130: 0 | BL130: 0 | BM130: 0 | BN130: 530.878 | BO130: 1364.314 | BP130: 59.211 | BQ130: 73.116 | BR130: 197.369 | BS130: 195.224 | BT130: 89.125 | BU130: 201.477 | BV130: 165.706
A131: Galeorhinus galeus | B131: Tope shark | C131: Large sharks (>=90 cm) | D131: Sharks & rays | E131: 32.611 | F131: 26.089 | G131: 29.815 | H131: 4.659 | I131: 5.59 | J131: 40.996 | K131: 35.406 | L131: 15.839 | M131: 13.976 | N131: 18.635 | O131: 7.454 | P131: 27.952 | Q131: 3.727 | R131: 5.59 | S131: 45.655 | T131: 52.177 | U131: 29.815 | V131: 22.362 | W131: 20.498 | X131: 16.771 | Y131: 24.225 | Z131: 8.386 | AA131: 8.386 | AB131: 22.362 | AC131: 16.771 | AD131: 9.317 | AE131: 16.771 | AF131: 5.59 | AG131: 61.494 | AH131: 50.24 | AI131: 307.992 | AJ131: 33.947 | AK131: 11.049 | AL131: 4.659 | AM131: 0 | AN131: 0 | AO131: 41.928 | AP131: 57.009 | AQ131: 59.747 | AR131: 50.808 | AS131: 23.293 | AT131: 10.249 | AU131: 46.03 | AV131: 86.784 | AW131: 66.153 | AX131: 20.498 | AY131: 47.518 | AZ131: 28.884 | BA131: 49.382 | BB131: 17.703 | BC131: 53.109 | BD131: 45.958 | BE131: 51.245 | BF131: 24.225 | BG131: 47.518 | BH131: 47.518 | BI131: 32.611 | BJ131: 42.86 | BK131: 16.771 | BL131: 39.474 | BM131: 18.635 | BN131: 102.69 | BO131: 59.611 | BP131: 66.927 | BQ131: 126.102 | BR131: 43.791 | BS131: 65.221 | BT131: 45.655 | BU131: 34.474 | BV131: 24.011
A132: Thunnus alalunga | B132: Albacore | C132: Large pelagics (>=90 cm) | D132: Tuna & billfishes | E132: 0 | F132: 0 | G132: 0 | H132: 0 | I132: 27.213 | J132: 0.285 | K132: 0 | L132: 0.219 | M132: 0 | N132: 0.041 | O132: 0.306 | P132: 0.534 | Q132: 0.613 | R132: 2.397 | S132: 0.79 | T132: 0.25 | U132: 0 | V132: 113.712 | W132: 25.269 | X132: 53.298 | Y132: 46.168 | Z132: 0.217 | AA132: 0.367 | AB132: 0.322 | AC132: 0.567 | AD132: 0.496 | AE132: 15.078 | AF132: 31.961 | AG132: 3.614 | AH132: 16.859 | AI132: 72.651 | AJ132: 43.173 | AK132: 2.4 | AL132: 2.432 | AM132: 28.883 | AN132: 203.898 | AO132: 0.128 | AP132: 3.777 | AQ132: 0 | AR132: 108.468 | AS132: 384.095 | AT132: 213.824 | AU132: 25.044 | AV132: 64.309 | AW132: 28.267 | AX132: 50.444 | AY132: 60.41 | AZ132: 16.316 | BA132: 81.596 | BB132: 18.13 | BC132: 8.854 | BD132: 107.819 | BE132: 9.207 | BF132: 44.188 | BG132: 78.166 | BH132: 24.342 | BI132: 26.161 | BJ132: 55.882 | BK132: 16.425 | BL132: 48.317 | BM132: 7.588 | BN132: 4.597 | BO132: 9.406 | BP132: 6.249 | BQ132: 20.287 | BR132: 57.133 | BS132: 53.448 | BT132: 138.527 | BU132: 69.163 | BV132: 40.396
A133: Carangidae | B133: Jacks, pompanos | C133: Medium pelagics (30 - 89 cm) | D133: Perch-likes | E133: 0 | F133: 0 | G133: 0 | H133: 0 | I133: 0 | J133: 0 | K133: 0 | L133: 0 | M133: 0 | N133: 0.173 | O133: 14.008 | P133: 14.718 | Q133: 36.174 | R133: 40.631 | S133: 87.841 | T133: 126.103 | U133: 98.573 | V133: 224.529 | W133: 40.993 | X133: 18.55 | Y133: 11.46 | Z133: 14.065 | AA133: 7.278 | AB133: 37.235 | AC133: 3.985 | AD133: 0 | AE133: 121.214 | AF133: 7.716 | AG133: 2.973 | AH133: 5.665 | AI133: 22.51 | AJ133: 0.539 | AK133: 1.258 | AL133: 71.743 | AM133: 0.484 | AN133: 1.286 | AO133: 0 | AP133: 0 | AQ133: 16.083 | AR133: 0.173 | AS133: 0.011 | AT133: 2.807 | AU133: 75.115 | AV133: 173.031 | AW133: 74.974 | AX133: 18.95 | AY133: 23.848 | AZ133: 14.466 | BA133: 87.194 | BB133: 16.585 | BC133: 1.141 | BD133: 71.667 | BE133: 8.095 | BF133: 23.913 | BG133: 23.081 | BH133: 75.187 | BI133: 24.534 | BJ133: 34.823 | BK133: 20.432 | BL133: 40.023 | BM133: 10.045 | BN133: 24.474 | BO133: 17.393 | BP133: 11.27 | BQ133: 20.539 | BR133: 83.817 | BS133: 91.012 | BT133: 228.764 | BU133: 39.29 | BV133: 139.912
A134: Miscellaneous marine crustaceans | B134: Marine crabs, shrimps, lobsters nei | C134: Shrimps | D134: Crustaceans | E134: 0 | F134: 0 | G134: 0 | H134: 0 | I134: 0 | J134: 0 | K134: 0 | L134: 0 | M134: 0 | N134: 0 | O134: 0 | P134: 0 | Q134: 0 | R134: 0 | S134: 0 | T134: 0 | U134: 0 | V134: 0 | W134: 0 | X134: 0 | Y134: 0 | Z134: 0 | AA134: 0 | AB134: 0 | AC134: 0 | AD134: 0 | AE134: 0 | AF134: 0 | AG134: 0 | AH134: 0 | AI134: 0 | AJ134: 0 | AK134: 0 | AL134: 275.595 | AM134: 1.168 | AN134: 0 | AO134: 1.168 | AP134: 0 | AQ134: 0 | AR134: 0 | AS134: 5.862 | AT134: 0 | AU134: 179.615 | AV134: 27.285 | AW134: 1.191 | AX134: 0 | AY134: 1.2 | AZ134: 0 | BA134: 1.209 | BB134: 68.647 | BC134: 100.989 | BD134: 0 | BE134: 0 | BF134: 0 | BG134: 0 | BH134: 373.818 | BI134: 0 | BJ134: 1.251 | BK134: 17.581 | BL134: 291.165 | BM134: 1110.748 | BN134: 0 | BO134: 2.238 | BP134: 15.668 | BQ134: 0 | BR134: 0 | BS134: 0 | BT134: 0 | BU134: 0 | BV134: 23.851
A135: Enteroctopus megalocyathus | B135: Patagonian giant octopus | C135: Cephalopods | D135: Other fishes & inverts | E135: 0 | F135: 0 | G135: 0 | H135: 0 | I135: 0 | J135: 0 | K135: 0 | L135: 0 | M135: 0 | N135: 0 | O135: 0 | P135: 0 | Q135: 0 | R135: 0 | S135: 0 | T135: 0 | U135: 0 | V135: 0 | W135: 0 | X135: 0 | Y135: 0 | Z135: 0 | AA135: 0 | AB135: 0 | AC135: 0 | AD135: 0 | AE135: 0 | AF135: 0 | AG135: 0 | AH135: 0 | AI135: 0 | AJ135: 0 | AK135: 0 | AL135: 0 | AM135: 0 | AN135: 0 | AO135: 0 | AP135: 0 | AQ135: 0 | AR135: 0 | AS135: 0 | AT135: 0 | AU135: 0 | AV135: 0 | AW135: 0 | AX135: 0 | AY135: 0 | AZ135: 0 | BA135: 0 | BB135: 0 | BC135: 0 | BD135: 0 | BE135: 0 | BF135: 0 | BG135: 0 | BH135: 0 | BI135: 0 | BJ135: 0 | BK135: 0 | BL135: 0 | BM135: 0 | BN135: 0 | BO135: 0 | BP135: 0 | BQ135: 0 | BR135: 0 | BS135: 0 | BT135: 713.992 | BU135: 572.165 | BV135: 801.419
A136: Istiophoridae | B136: Billfishes | C136: Large pelagics (>=90 cm) | D136: Tuna & billfishes | E136: 0 | F136: 0 | G136: 0 | H136: 0 | I136: 0.08 | J136: 0.124 | K136: 0 | L136: 0.299 | M136: 0 | N136: 0 | O136: 0 | P136: 0 | Q136: 0 | R136: 0 | S136: 0 | T136: 0 | U136: 0 | V136: 112.007 | W136: 0 | X136: 18.426 | Y136: 11.399 | Z136: 0 | AA136: 6.388 | AB136: 18.479 | AC136: 1.864 | AD136: 0 | AE136: 39.537 | AF136: 4.113 | AG136: 1.287 | AH136: 2.546 | AI136: 11.053 | AJ136: 0 | AK136: 0 | AL136: 9.813 | AM136: 0.003 | AN136: 0 | AO136: 0 | AP136: 0.19 | AQ136: 6.764 | AR136: 0.005 | AS136: 11.332 | AT136: 5.685 | AU136: 53.956 | AV136: 135.915 | AW136: 39.342 | AX136: 22.508 | AY136: 19.541 | AZ136: 1.219 | BA136: 44.034 | BB136: 8.171 | BC136: 1.135 | BD136: 7.974 | BE136: 17.394 | BF136: 20.266 | BG136: 11.848 | BH136: 50.003 | BI136: 32.05 | BJ136: 54.062 | BK136: 308.631 | BL136: 41.077 | BM136: 302.132 | BN136: 114.698 | BO136: 69.892 | BP136: 32.104 | BQ136: 2.989 | BR136: 42.763 | BS136: 52.911 | BT136: 134.191 | BU136: 20.457 | BV136: 110.549
A137: Chrysaora plocamia | B137: South American sea nettle | C137: Jellyfish | D137: Other fishes & inverts | E137: 0 | F137: 0 | G137: 0 | H137: 0 | I137: 0 | J137: 0 | K137: 0 | L137: 0 | M137: 0 | N137: 0 | O137: 0 | P137: 0 | Q137: 0 | R137: 0 | S137: 0 | T137: 0 | U137: 0 | V137: 0 | W137: 0 | X137: 0 | Y137: 0 | Z137: 0 | AA137: 0 | AB137: 0 | AC137: 0 | AD137: 0 | AE137: 0 | AF137: 0 | AG137: 0 | AH137: 0 | AI137: 0 | AJ137: 0 | AK137: 0 | AL137: 0 | AM137: 0 | AN137: 0 | AO137: 0 | AP137: 0 | AQ137: 0 | AR137: 0 | AS137: 0 | AT137: 0 | AU137: 0 | AV137: 0 | AW137: 0 | AX137: 0 | AY137: 0 | AZ137: 0 | BA137: 0 | BB137: 0 | BC137: 0 | BD137: 0 | BE137: 0 | BF137: 0 | BG137: 0 | BH137: 0 | BI137: 0 | BJ137: 0 | BK137: 0 | BL137: 0 | BM137: 0 | BN137: 0 | BO137: 0 | BP137: 0 | BQ137: 0 | BR137: 0 | BS137: 1029.939 | BT137: 908.076 | BU137: 0 | BV137: 0
... A219: Caulolatilus princeps | B219: Ocean whitefish | C219: Medium reef assoc. fish (30 - 89 cm) | D219: Perch-likes | E219: 0 | F219: 0 | G219: 0 | H219: 0 | I219: 0 | J219: 0 | K219: 0 | L219: 0 | M219: 0 | N219: 0 | O219: 0 | P219: 0 | Q219: 0 | R219: 0 | S219: 0 | T219: 0 | U219: 0 | V219: 0 | W219: 0 | X219: 0 | Y219: 0 | Z219: 0 | AA219: 0 | AB219: 0 | AC219: 0 | AD219: 0 | AE219: 0 | AF219: 0 | AG219: 0 | AH219: 0 | AI219: 0 | AJ219: 0 | AK219: 0 | AL219: 0 | AM219: 0 | AN219: 0 | AO219: 0 | AP219: 0 | AQ219: 0 | AR219: 0 | AS219: 0 | AT219: 0 | AU219: 0 | AV219: 0 | AW219: 0 | AX219: 0 | AY219: 0 | AZ219: 0 | BA219: 0 | BB219: 0 | BC219: 0 | BD219: 0 | BE219: 0 | BF219: 0 | BG219: 0 | BH219: 0 | BI219: 0 | BJ219: 0 | BK219: 0 | BL219: 0 | BM219: 0 | BN219: 0 | BO219: 0 | BP219: 0 | BQ219: 0 | BR219: 0 | BS219: 0 | BT219: 0 | BU219: 0 | BV219: 0.081

Sheet Taxon-Group Map
A1: Which Ecopath group each catch taxon belongs to, and on what evidence.
A2: Several groups separated by | means the taxon spans them and its catch is apportioned; the weights used are in the next two columns.
A4: taxon | B4: common_name | C4: SAU functional group | D4: SAU commercial group | E4: Ecopath group | F4: weights | G4: weight basis | H4: confidence | I4: evidence | J4: catch tonnes | K4: % of catch | L4: explanation
A5: Engraulis ringens | B5: Anchoveta | C5: Small pelagics (<30 cm) | D5: Anchovies | E5: Anchovy | H5: high | I5: explicit_member | J5: 4.2989081e+08 | K5: 63.4058 | L5: Focal model adopts Tam et al. (2008) pp.353-354 membership (Chiaverano 2018 p.30); Engraulis ringens matches the printed species or recorded synonym. Peruvian hake spans three source size classes and uses fixed model catch weights.
A6: Sardinops sagax | B6: South American pilchard | C6: Medium pelagics (30 - 89 cm) | D6: Herring-likes | E6: Sardine | H6: high | I6: explicit_member | J6: 83222176 | K6: 12.2747 | L6: Focal model adopts Tam et al. (2008) pp.353-354 membership (Chiaverano 2018 p.30); Sardinops sagax matches the printed species or recorded synonym. Peruvian hake spans three source size classes and uses fixed model catch weights.
A7: Trachurus murphyi | B7: Chilean jack mackerel | C7: Medium pelagics (30 - 89 cm) | D7: Perch-likes | E7: Horse mackerel | H7: high | I7: inherited_model | J7: 66735664 | K7: 9.843 | L7: Focal model adopts Tam et al. (2008) pp.353-354 membership (Chiaverano 2018 p.30); Trachurus murphyi matches the printed species or recorded synonym. Peruvian hake spans three source size classes and uses fixed model catch weights.
A8: Clupeidae | B8: Herrings, sardines, menhadens | C8: Small pelagics (<30 cm) | D8: Herring-likes | E8: Sardine | Other small pelagic fish | F8: 0.965 | 0.035 | G8: explicit | H8: medium | I8: composite_split | J8: 16256966 | K8: 2.3978 | L8: Clupeidae spans the dedicated Sardinops sardine stock and other small planktivorous pelagics. Family-specific catch weights use identified Sardinops versus other clupeids, not all pelagic catch.
A9: Dosidicus gigas | B9: Jumbo flying squid | C9: Cephalopods | D9: Other fishes & inverts | E9: Jumbo squid | H9: high | I9: inherited_model | J9: 14273293 | K9: 2.1052 | L9: Focal model adopts Tam et al. (2008) pp.353-354 membership (Chiaverano 2018 p.30); Dosidicus gigas matches the printed species or recorded synonym. Peruvian hake spans three source size classes and uses fixed model catch weights.
A10: Scomber japonicus | B10: Pacific chub mackerel | C10: Medium pelagics (30 - 89 cm) | D10: Perch-likes | E10: Chub mackerel | H10: high | I10: inherited_model | J10: 10461891 | K10: 1.5431 | L10: Focal model adopts Tam et al. (2008) pp.353-354 membership (Chiaverano 2018 p.30); Scomber japonicus matches the printed species or recorded synonym. Peruvian hake spans three source size classes and uses fixed model catch weights.
A11: Marine fishes not identified | B11: Marine fishes nei | C11: Medium demersals (30 - 89 cm) | D11: Other fishes & inverts | E11: Small demersal fish | Medium demersal fish | Medium sciaenids | F11: 0.227 | 0.497 | 0.276 | G11: catch_composition | H11: low | I11: composite_split | J11: 8678083.7 | K11: 1.28 | L11: Analyst residual-catch composite, SAU Medium demersals (30 - 89 cm). Candidate residual groups are constrained by source habitat and Table E feeding guilds; dedicated stocks are excluded. Catch-composition weights are estimated, not a source species list.
A12: Merluccius peruanus | B12: Peruvian hake | C12: Medium bathydemersals (30 - 89 cm) | D12: Cod-likes | E12: Large hake | Medium hake | Small hake | F12: 0.037 | 0.038 | 0.925 | G12: model_catch | H12: medium | I12: composite_split | J12: 4467956.8 | K12: 0.659 | L12: Focal model adopts Tam et al. (2008) pp.353-354 membership (Chiaverano 2018 p.30); Merluccius peruanus matches the printed species or recorded synonym. Peruvian hake spans three source size classes and uses fixed model catch weights.
A13: Merluccius gayi | B13: South Pacific hake | C13: Medium bathydemersals (30 - 89 cm) | D13: Cod-likes | E13: Unresolved | H13: unresolved | I13: none | J13: 4414589.5 | K13: 0.6511 | L13: This is a southern/offshore demersal stock, not the explicitly modelled northern Peruvian hake Merluccius peruanus; the northern model has no corresponding named stock compartment.
A14: Macruronus magellanicus | B14: Patagonian grenadier | C14: Large benthopelagics (>=90 cm) | D14: Cod-likes | E14: Unresolved | H14: unresolved | I14: none | J14: 3359421.7 | K14: 0.4955 | L14: This is a southern/offshore demersal stock, not the explicitly modelled northern Peruvian hake Merluccius peruanus; the northern model has no corresponding named stock compartment.
A15: Sarda chiliensis | B15: Eastern Pacific bonito | C15: Medium pelagics (30 - 89 cm) | D15: Tuna & billfishes | E15: Other large pelagic fish | H15: high | I15: inherited_model | J15: 3285621 | K15: 0.4846 | L15: Focal model adopts Tam et al. (2008) pp.353-354 membership (Chiaverano 2018 p.30); Sarda chiliensis matches the printed species or recorded synonym. Peruvian hake spans three source size classes and uses fixed model catch weights.
A16: Normanichthys crockeri | B16: Mote sculpin | C16: Small demersals (<30 cm) | D16: Scorpionfishes | E16: Other small pelagic fish | H16: low | I16: analogue | J16: 1986528.6 | K16: 0.293 | L16: Analyst small schooling planktivorous/pelagic analogue to source Other small pelagic fish; the species is not in the source member list, and its SAU demersal/size class may differ.
A17: Loxechinus albus | B17: Chilean sea urchin | C17: Other demersal invertebrates | D17: Other fishes & inverts | E17: Macrobenthos | H17: medium | I17: taxonomic_containment | J17: 1756286.8 | K17: 0.259 | L17: Taxonomic/habitat containment in the single Macrobenthos pool, Tam (2008) p.353; no species list documents this exact taxon. Applying the northern pool to LME-wide benthic catches is an area transfer.
A18: Merluccius australis | B18: Southern hake | C18: Large benthopelagics (>=90 cm) | D18: Cod-likes | E18: Unresolved | H18: unresolved | I18: none | J18: 1545604.4 | K18: 0.228 | L18: This is a southern/offshore demersal stock, not the explicitly modelled northern Peruvian hake Merluccius peruanus; the northern model has no corresponding named stock compartment.
A19: Ethmidium maculatum | B19: Pacific menhaden | C19: Small pelagics (<30 cm) | D19: Herring-likes | E19: Other small pelagic fish | H19: medium | I19: analogue | J19: 1420567.9 | K19: 0.2095 | L19: Other small planktivorous clupeiform, compared with source Anchoa nasus (Tam 2008 p.353); distinct from the named Sardinops and Engraulis stocks. This is an ecological extension to LME-wide catches.
A20: Aulacomya atra | B20: Chilean ribbed mussel | C20: Other demersal invertebrates | D20: Molluscs | E20: Macrobenthos | H20: medium | I20: taxonomic_containment | J20: 1411623.6 | K20: 0.2082 | L20: Taxonomic/habitat containment in the single Macrobenthos pool, Tam (2008) p.353; no species list documents this exact taxon. Applying the northern pool to LME-wide benthic catches is an area transfer.
A21: Anchoa nasus | B21: Longnose anchovy | C21: Small pelagics (<30 cm) | D21: Anchovies | E21: Other small pelagic fish | H21: high | I21: inherited_model | J21: 1388525.9 | K21: 0.2048 | L21: Focal model adopts Tam et al. (2008) pp.353-354 membership (Chiaverano 2018 p.30); Anchoa nasus matches the printed species or recorded synonym. Peruvian hake spans three source size classes and uses fixed model catch weights.
A22: Strangomera bentincki | B22: Araucanian herring | C22: Small pelagics (<30 cm) | D22: Herring-likes | E22: Other small pelagic fish | H22: medium | I22: analogue | J22: 1335495.3 | K22: 0.197 | L22: Other small planktivorous clupeiform, compared with source Anchoa nasus (Tam 2008 p.353); distinct from the named Sardinops and Engraulis stocks. This is an ecological extension to LME-wide catches.
A23: Coryphaena hippurus | B23: Common dolphinfish | C23: Large pelagics (>=90 cm) | D23: Perch-likes | E23: Other large pelagic fish | H23: high | I23: inherited_model | J23: 1116395.3 | K23: 0.1647 | L23: Focal model adopts Tam et al. (2008) pp.353-354 membership (Chiaverano 2018 p.30); Coryphaena hippurus matches the printed species or recorded synonym. Peruvian hake spans three source size classes and uses fixed model catch weights.
A24: Grimothea monodon | B24: Squat Lobster | C24: Lobsters, crabs | D24: Crustaceans | E24: Macrobenthos | H24: medium | I24: taxonomic_containment | J24: 1085796.1 | K24: 0.1601 | L24: Taxonomic/habitat containment in the single Macrobenthos pool, Tam (2008) p.353; no species list documents this exact taxon. Applying the northern pool to LME-wide benthic catches is an area transfer.
... A36: Mesodesma donacium | B36: Macha clam | C36: Other demersal invertebrates | D36: Molluscs | E36: Macrobenthos | H36: medium | I36: taxonomic_containment | J36: 562635.74 | K36: 0.083 | L36: Taxonomic/habitat containment in the single Macrobenthos pool, Tam (2008) p.353; no species list documents this exact taxon. Applying the northern pool to LME-wide benthic catches is an area transfer.
A37: Sciaenidae | B37: Drums, croakers | C37: Medium demersals (30 - 89 cm) | D37: Perch-likes | E37: Small demersal fish | Medium sciaenids | F37: 0.451 | 0.549 | G37: catch_composition | H37: low | I37: composite_split | J37: 549931.3 | K37: 0.0811 | L37: Analyst sciaenid extension: source explicitly separates Ctenosciaena into Small demersal fish and a Medium sciaenids pool (Tam 2008 p.353); the family label spans both, named medium croakers use the latter.
A38: Gastropoda | B38: Sea snails | C38: Other demersal invertebrates | D38: Molluscs | E38: Macrobenthos | H38: medium | I38: taxonomic_containment | J38: 545506.35 | K38: 0.0805 | L38: Taxonomic/habitat containment in the single Macrobenthos pool, Tam (2008) p.353; no species list documents this exact taxon. Applying the northern pool to LME-wide benthic catches is an area transfer.
A39: Penaeidae | B39: Commercial shrimps and prawns | C39: Shrimps | D39: Crustaceans | E39: Macrobenthos | H39: medium | I39: taxonomic_containment | J39: 473288.84 | K39: 0.0698 | L39: Taxonomic/habitat containment in the single Macrobenthos pool, Tam (2008) p.353; no species list documents this exact taxon. Applying the northern pool to LME-wide benthic catches is an area transfer.
A40: Mustelus whitneyi | B40: Humpback smooth-hound | C40: Small to medium sharks (<90 cm) | D40: Sharks & rays | E40: Benthic elasmobranchs | H40: medium | I40: analogue | J40: 434523.7 | K40: 0.0641 | L40: Analyst habitat/feeding inference to benthic elasmobranchs or, for oceanic Mobula, the remaining Chondrichthyans pool (Tam 2008 pp.353-354; Table E separates benthivores from apex fish).
A41: Concholepas concholepas | B41: False abalone | C41: Other demersal invertebrates | D41: Molluscs | E41: Macrobenthos | H41: medium | I41: taxonomic_containment | J41: 403348.04 | K41: 0.0595 | L41: Taxonomic/habitat containment in the single Macrobenthos pool, Tam (2008) p.353; no species list documents this exact taxon. Applying the northern pool to LME-wide benthic catches is an area transfer.
A42: Mytilus chilensis | B42: Chilean mussel | C42: Other demersal invertebrates | D42: Molluscs | E42: Macrobenthos | H42: medium | I42: taxonomic_containment | J42: 369069.11 | K42: 0.0544 | L42: Taxonomic/habitat containment in the single Macrobenthos pool, Tam (2008) p.353; no species list documents this exact taxon. Applying the northern pool to LME-wide benthic catches is an area transfer.
A43: Thunnus albacares | B43: Yellowfin tuna | C43: Large pelagics (>=90 cm) | D43: Tuna & billfishes | E43: Other large pelagic fish | H43: high | I43: inherited_model | J43: 354412.64 | K43: 0.0523 | L43: Focal model adopts Tam et al. (2008) pp.353-354 membership (Chiaverano 2018 p.30); Thunnus albacares matches the printed species or recorded synonym. Peruvian hake spans three source size classes and uses fixed model catch weights.
A44: Cynoscion analis | B44: Peruvian weakfish | C44: Medium demersals (30 - 89 cm) | D44: Perch-likes | E44: Medium sciaenids | H44: medium | I44: analogue | J44: 331555.39 | K44: 0.0489 | L44: Analyst sciaenid extension: source explicitly separates Ctenosciaena into Small demersal fish and a Medium sciaenids pool (Tam 2008 p.353); the family label spans both, named medium croakers use the latter.
A45: Paralonchurus peruanus | B45: Peruvian banded croaker | C45: Medium demersals (30 - 89 cm) | D45: Perch-likes | E45: Medium sciaenids | H45: medium | I45: analogue | J45: 315461.87 | K45: 0.0465 | L45: Analyst sciaenid extension: source explicitly separates Ctenosciaena into Small demersal fish and a Medium sciaenids pool (Tam 2008 p.353); the family label spans both, named medium croakers use the latter.
A46: Thyrsites atun | B46: Snoek | C46: Large benthopelagics (>=90 cm) | D46: Perch-likes | E46: Unresolved | H46: unresolved | I46: none | J46: 310792.73 | K46: 0.0458 | L46: No documented source member or sufficiently supported feeding-guild analogue established for Thyrsites atun; source size/habitat labels alone do not resolve its placement.
A47: Heterocarpus reedi | B47: Chilean nylon shrimp | C47: Shrimps | D47: Crustaceans | E47: Macrobenthos | H47: medium | I47: taxonomic_containment | J47: 302770.32 | K47: 0.0447 | L47: Taxonomic/habitat containment in the single Macrobenthos pool, Tam (2008) p.353; no species list documents this exact taxon. Applying the northern pool to LME-wide benthic catches is an area transfer.
A48: Paralabrax humeralis | B48: Peruvian rock seabass | C48: Medium benthopelagics (30 - 89 cm) | D48: Perch-likes | E48: Medium demersal fish | H48: high | I48: inherited_model | J48: 295221.93 | K48: 0.0435 | L48: Focal model adopts Tam et al. (2008) pp.353-354 membership (Chiaverano 2018 p.30); Paralabrax humeralis matches the printed species or recorded synonym. Peruvian hake spans three source size classes and uses fixed model catch weights.
A49: Genypterus blacodes | B49: Pink cusk-eel | C49: Large bathydemersals (>=90 cm) | D49: Other fishes & inverts | E49: Unresolved | H49: unresolved | I49: none | J49: 277009.56 | K49: 0.0409 | L49: Source names Conger without a member list; snake eels and cusk-eels cannot be declared members from a shared eel-like shape, and the relevant demersal trophic analogue is not established.
A50: Malacostraca | B50: Lobsters, crabs, shrimps, krill | C50: Shrimps | D50: Crustaceans | E50: Macrobenthos | H50: medium | I50: taxonomic_containment | J50: 253611.19 | K50: 0.0374 | L50: Taxonomic/habitat containment in the single Macrobenthos pool, Tam (2008) p.353; no species list documents this exact taxon. Applying the northern pool to LME-wide benthic catches is an area transfer.
A51: Scombridae | B51: Mackerels, tunas, bonitos | C51: Medium pelagics (30 - 89 cm) | D51: Perch-likes | E51: Chub mackerel | Other large pelagic fish | F51: 0.690 | 0.310 | G51: explicit | H51: medium | I51: composite_split | J51: 252141.7 | K51: 0.0372 | L51: Scombrid aggregate spans dedicated chub mackerel and other large pelagic predatory fishes including tuna/bonito (Tam 2008 p.353); fixed composition uses the identified scombrid genera.
A52: Cilus gilberti | B52: Corvina drum | C52: Medium demersals (30 - 89 cm) | D52: Perch-likes | E52: Medium sciaenids | H52: medium | I52: analogue | J52: 243847.38 | K52: 0.036 | L52: Analyst sciaenid extension: source explicitly separates Ctenosciaena into Small demersal fish and a Medium sciaenids pool (Tam 2008 p.353); the family label spans both, named medium croakers use the latter.
...

Sheet SPPR
A1: Specific PPR per taxon — LME_013, model 13_2_Northern_Humboldt_Current_(1995-1998)
A2: sppr_simple is the trophic-chain estimate (1/TE)^(TL-1) at TE=0.1, applied to the taxon's own trophic level and needing no model.
A3: All basal sources, including imports. Blank means unavailable, not zero. sppr_simple is an unpartitioned reference.
A4: taxon | B4: trophic_level | C4: sppr_simple | D4: Ecopath group | E4: SPPR_1986 | F4: SPPR_1995_TE0.1 | G4: SPPR_1995_TEmean | H4: Ulanowicz_globalTEmean | I4: Ulanowicz_TE | J4: EwE_TE_noEE | K4: EwE_TE_EE | L4: SPPR_2015 | M4: new_TE_noEEfix | N4: new_TE_EEfix | O4: new_GE | P4: new_WithEgestion | Q4: sym_TE_asPP | R4: sym_TE_asDC | S4: sym_GE_asPP | T4: sym_GE_asDC | U4: sym_WithEgestion_asPP | V4: sym_WithEgestion_asDC | W4: MC_new_GE | X4: MC_new_TE_EEfix
A5: Engraulis ringens | B5: 2.7 | C5: 50.118723 | D5: Anchovy | E5: 100.34153 | F5: 79.859919 | G5: 75.605829 | H5: 172.39955 | I5: 32.654082 | J5: 32.654082 | K5: 26.608094 | L5: 43.673175 | M5: 43.673175 | N5: 43.673175 | O5: -46.608493 | P5: -90.268379 | Q5: 43.673175 | S5: -46.608493 | U5: 60.488948 | V5: 62.511821 | W5: 1076.5692 | X5: 49.223524
A6: Sardinops sagax | B6: 2.84 | C6: 69.183097 | D6: Sardine | E6: 100.34153 | F6: 110.73429 | G6: 104.40818 | H6: 186.96821 | I6: 36.031758 | J6: 36.031758 | K6: 34.950931 | L6: 48.153928 | M6: 48.153928 | N6: 48.153928 | O6: -60.849913 | P6: -115.04459 | Q6: 48.153928 | S6: -60.849913 | U6: 76.494071 | V6: 79.064174 | W6: 1336.8994 | X6: 54.375213
A7: Trachurus murphyi | B7: 3.33 | C7: 213.79621 | D7: Horse mackerel | E7: 100.34153 | F7: 256.97282 | G7: 239.75661 | H7: 917.18332 | I7: 603.9568 | J7: 603.9568 | K7: 142.24214 | L7: 799.91534 | M7: 799.91534 | N7: 799.91534 | O7: -225.03293 | P7: -321.00704 | Q7: 799.91534 | S7: -225.03293 | U7: 207.8973 | V7: 217.28759 | W7: 4639.6422 | X7: 914.48772
A8: Clupeidae | B8: 3.16 | C8: 144.54398 | D8: Sardine | Other small pelagic fish | E8: 100.34153 | F8: 108.82847 | G8: 102.62695 | H8: 184.96506 | I8: 36.07268 | J8: 36.07268 | K8: 34.900076 | L8: 48.127026 | M8: 48.127026 | N8: 48.127026 | O8: -60.147512 | P8: -113.72204 | Q8: 48.127026 | S8: -60.147512 | U8: 75.819764 | V8: 78.45894 | W8: 1333.6096 | X8: 54.313577
A9: Dosidicus gigas | B9: 4.14 | C9: 1380.3843 | D9: Jumbo squid | E9: 100.34153 | F9: 702.78981 | G9: 647.51287 | H9: 1318.5109 | I9: 236.56512 | J9: 271.85235 | K9: 217.47602 | L9: 831.74504 | M9: 831.74504 | N9: 831.74504 | O9: -273.76655 | P9: -364.4994 | Q9: 831.74504 | S9: -273.76655 | U9: 230.76194 | V9: 241.86996 | W9: 5891.014 | X9: 1054.6803
A10: Scomber japonicus | B10: 3.38 | C10: 239.88329 | D10: Chub mackerel | E10: 100.34153 | F10: 367.10237 | G10: 340.98462 | H10: 1026.5545 | I10: 1462.5636 | J10: 1462.5636 | K10: 226.88376 | L10: 1951.049 | M10: 1951.049 | N10: 1951.049 | O10: -337.35519 | P10: -532.27037 | Q10: 1951.049 | S10: -337.35519 | U10: 354.11429 | V10: 369.11622 | W10: 7302.8387 | X10: 2206.173
A11: Marine fishes not identified | B11: 3.28 | C11: 190.54607 | D11: Small demersal fish | Medium demersal fish | Medium sciaenids | E11: 100.34153 | F11: 138.32652 | G11: 129.84254 | H11: 381.78767 | I11: 897.52225 | J11: 898.11132 | K11: 642.85006 | L11: 1416.6205 | M11: 1416.6205 | N11: 1416.6205 | O11: -245.91948 | P11: -623.52268 | Q11: 1416.6205 | S11: -245.91948 | U11: 331.68607 | V11: 405.12958 | W11: 4869.5491 | X11: 1676.9638
A12: Merluccius peruanus | B12: 4.4 | C12: 2511.8864 | D12: Large hake | Medium hake | Small hake | E12: 100.34153 | F12: 524.22383 | G12: 484.18145 | H12: 1951.6688 | I12: 1695.1503 | J12: 1706.3024 | K12: 1366.5856 | L12: 2528.8859 | M12: 2528.8859 | N12: 2528.8859 | O12: -389.06202 | P12: -543.52238 | Q12: 2528.8859 | S12: -389.06202 | U12: 335.38764 | V12: 368.88358 | W12: 7607.0988 | X12: 2964.0107
A13: Merluccius gayi | B13: 4.26 | C13: 1819.7009 | D13: Unresolved
A14: Macruronus magellanicus | B14: 3.93 | C14: 851.13804 | D14: Unresolved
A15: Sarda chiliensis | B15: 4.49 | C15: 3090.2954 | D15: Other large pelagic fish | E15: 100.34153 | F15: 721.56117 | G15: 664.58883 | H15: 1923.8805 | I15: 707.78626 | J15: 730.79575 | K15: 390.22479 | L15: 1280.1746 | M15: 1280.1746 | N15: 1280.1746 | O15: -479.79416 | P15: -709.96578 | Q15: 1280.1746 | S15: -479.79416 | U15: 483.37754 | V15: 503.88153 | W15: 10483.564 | X15: 1536.9808
A16: Normanichthys crockeri | B16: 2.75 | C16: 56.234133 | D16: Other small pelagic fish | E16: 100.34153 | F16: 55.911353 | G16: 53.169346 | H16: 129.34564 | I16: 37.208913 | J16: 37.208913 | K16: 33.488021 | L16: 47.38007 | M16: 47.38007 | N16: 47.38007 | O16: -40.644634 | P16: -77.000115 | Q16: 47.38007 | S16: -40.644634 | U16: 57.096937 | V16: 61.654006 | W16: 1242.2652 | X16: 52.602205
A17: Loxechinus albus | B17: 2 | C17: 10 | D17: Macrobenthos | E17: 100.34153 | F17: 10 | G17: 9.716344 | H17: 9.230527 | I17: 10.017358 | J17: 10.017358 | K17: 7.916667 | L17: 2.899495 | M17: 2.899495 | N17: 2.899495 | O17: -50.833365 | P17: -184.82507 | Q17: 2.899495 | S17: -50.833365 | U17: 91.528788 | V17: 116.69195 | W17: 929.62298 | X17: 3.093013
A18: Merluccius australis | B18: 4.45 | C18: 2818.3829 | D18: Unresolved
A19: Ethmidium maculatum | B19: 2.07 | C19: 11.748976 | D19: Other small pelagic fish | E19: 100.34153 | F19: 55.911353 | G19: 53.169346 | H19: 129.34564 | I19: 37.208913 | J19: 37.208913 | K19: 33.488021 | L19: 47.38007 | M19: 47.38007 | N19: 47.38007 | O19: -40.644634 | P19: -77.000115 | Q19: 47.38007 | S19: -40.644634 | U19: 57.096937 | V19: 61.654006 | W19: 1242.2652 | X19: 52.602205
A20: Aulacomya atra | B20: 2 | C20: 10 | D20: Macrobenthos | E20: 100.34153 | F20: 10 | G20: 9.716344 | H20: 9.230527 | I20: 10.017358 | J20: 10.017358 | K20: 7.916667 | L20: 2.899495 | M20: 2.899495 | N20: 2.899495 | O20: -50.833365 | P20: -184.82507 | Q20: 2.899495 | S20: -50.833365 | U20: 91.528788 | V20: 116.69195 | W20: 929.62298 | X20: 3.093013
A21: Anchoa nasus | B21: 3.4 | C21: 251.18864 | D21: Other small pelagic fish | E21: 100.34153 | F21: 55.911353 | G21: 53.169346 | H21: 129.34564 | I21: 37.208913 | J21: 37.208913 | K21: 33.488021 | L21: 47.38007 | M21: 47.38007 | N21: 47.38007 | O21: -40.644634 | P21: -77.000115 | Q21: 47.38007 | S21: -40.644634 | U21: 57.096937 | V21: 61.654006 | W21: 1242.2652 | X21: 52.602205
A22: Strangomera bentincki | B22: 2 | C22: 10 | D22: Other small pelagic fish | E22: 100.34153 | F22: 55.911353 | G22: 53.169346 | H22: 129.34564 | I22: 37.208913 | J22: 37.208913 | K22: 33.488021 | L22: 47.38007 | M22: 47.38007 | N22: 47.38007 | O22: -40.644634 | P22: -77.000115 | Q22: 47.38007 | S22: -40.644634 | U22: 57.096937 | V22: 61.654006 | W22: 1242.2652 | X22: 52.602205
A23: Coryphaena hippurus | B23: 4.37 | C23: 2344.2288 | D23: Other large pelagic fish | E23: 100.34153 | F23: 721.56117 | G23: 664.58883 | H23: 1923.8805 | I23: 707.78626 | J23: 730.79575 | K23: 390.22479 | L23: 1280.1746 | M23: 1280.1746 | N23: 1280.1746 | O23: -479.79416 | P23: -709.96578 | Q23: 1280.1746 | S23: -479.79416 | U23: 483.37754 | V23: 503.88153 | W23: 10483.564 | X23: 1536.9808
A24: Grimothea monodon | B24: 2.74 | C24: 54.954087 | D24: Macrobenthos | E24: 100.34153 | F24: 10 | G24: 9.716344 | H24: 9.230527 | I24: 10.017358 | J24: 10.017358 | K24: 7.916667 | L24: 2.899495 | M24: 2.899495 | N24: 2.899495 | O24: -50.833365 | P24: -184.82507 | Q24: 2.899495 | S24: -50.833365 | U24: 91.528788 | V24: 116.69195 | W24: 929.62298 | X24: 3.093013
A25: Cervimunida johni | B25: 2.6 | C25: 39.810717 | D25: Macrobenthos | E25: 100.34153 | F25: 10 | G25: 9.716344 | H25: 9.230527 | I25: 10.017358 | J25: 10.017358 | K25: 7.916667 | L25: 2.899495 | M25: 2.899495 | N25: 2.899495 | O25: -50.833365 | P25: -184.82507 | Q25: 2.899495 | S25: -50.833365 | U25: 91.528788 | V25: 116.69195 | W25: 929.62298 | X25: 3.093013
A26: Mugil cephalus | B26: 2.14 | C26: 13.803843 | D26: Medium demersal fish | E26: 100.34153 | F26: 150.44686 | G26: 141.30976 | H26: 345.60848 | I26: 95.134595 | J26: 95.680039 | K26: 78.472681 | L26: 85.358492 | M26: 85.358492 | N26: 85.358492 | O26: -290.0196 | P26: -770.35308 | Q26: 85.358492 | S26: -290.0196 | U26: 400.58621 | V26: 495.19252 | W26: 4943.2562 | X26: 95.427959
A27: Katsuwonus pelamis | B27: 4.43 | C27: 2691.5348 | D27: Other large pelagic fish | E27: 100.34153 | F27: 721.56117 | G27: 664.58883 | H27: 1923.8805 | I27: 707.78626 | J27: 730.79575 | K27: 390.22479 | L27: 1280.1746 | M27: 1280.1746 | N27: 1280.1746 | O27: -479.79416 | P27: -709.96578 | Q27: 1280.1746 | S27: -479.79416 | U27: 483.37754 | V27: 503.88153 | W27: 10483.564 | X27: 1536.9808
A28: Veneridae | D28: Macrobenthos | E28: 100.34153 | F28: 10 | G28: 9.716344 | H28: 9.230527 | I28: 10.017358 | J28: 10.017358 | K28: 7.916667 | L28: 2.899495 | M28: 2.899495 | N28: 2.899495 | O28: -50.833365 | P28: -184.82507 | Q28: 2.899495 | S28: -50.833365 | U28: 91.528788 | V28: 116.69195 | W28: 929.62298 | X28: 3.093013
A29: Argopecten purpuratus | B29: 2 | C29: 10 | D29: Macrobenthos | E29: 100.34153 | F29: 10 | G29: 9.716344 | H29: 9.230527 | I29: 10.017358 | J29: 10.017358 | K29: 7.916667 | L29: 2.899495 | M29: 2.899495 | N29: 2.899495 | O29: -50.833365 | P29: -184.82507 | Q29: 2.899495 | S29: -50.833365 | U29: 91.528788 | V29: 116.69195 | W29: 929.62298 | X29: 3.093013
A30: Doryteuthis gahi | B30: 3.2 | C30: 158.48932 | D30: Other cephalopods | E30: 100.34153 | F30: 133.99852 | G30: 126.04262 | H30: 240.46643 | I30: 9.809711 | J30: 9.809711 | K30: 9.319225 | L30: 13.826862 | M30: 13.826862 | N30: 13.826862 | O30: -21.746323 | P30: -52.393884 | Q30: 13.826862 | S30: -21.746323 | U30: 33.004478 | V30: 37.738157 | W30: 384.45606 | X30: 15.987649
A31: Odontesthes regia | B31: 4 | C31: 1000 | D31: Small demersal fish | E31: 100.34153 | F31: 28.840315 | G31: 27.653763 | H31: 83.334375 | I31: 22.319429 | J31: 22.319429 | K31: 16.302777 | L31: 27.460928 | M31: 27.460928 | N31: 27.460928 | O31: -14.110618 | P31: -36.828458 | Q31: 27.460928 | S31: -14.110618 | U31: 30.881292 | V31: 31.789849 | W31: 429.71383 | X31: 30.241866
A32: Brama australis | B32: 4.2 | C32: 1584.8932 | D32: Unresolved
A33: Seriolella | D33: Unresolved
A34: Prionotus stephanophrys | B34: 3.5 | C34: 316.22777 | D34: Sea robin | E34: 100.34153 | F34: 190.40816 | G34: 178.31837 | H34: 351.91557 | I34: 90.725031 | J34: 90.725031 | K34: 41.601385 | L34: 110.63707 | M34: 110.63707 | N34: 110.63707 | O34: -88.560252 | P34: -205.51698 | Q34: 110.63707 | S34: -88.560252 | U34: 122.57888 | V34: 136.60552 | W34: 1664.5087 | X34: 126.76771
A35: Bivalvia | B35: 2.23 | C35: 16.982437 | D35: Macrobenthos | E35: 100.34153 | F35: 10 | G35: 9.716344 | H35: 9.230527 | I35: 10.017358 | J35: 10.017358 | K35: 7.916667 | L35: 2.899495 | M35: 2.899495 | N35: 2.899495 | O35: -50.833365 | P35: -184.82507 | Q35: 2.899495 | S35: -50.833365 | U35: 91.528788 | V35: 116.69195 | W35: 929.62298 | X35: 3.093013
A36: Mesodesma donacium | B36: 2 | C36: 10 | D36: Macrobenthos | E36: 100.34153 | F36: 10 | G36: 9.716344 | H36: 9.230527 | I36: 10.017358 | J36: 10.017358 | K36: 7.916667 | L36: 2.899495 | M36: 2.899495 | N36: 2.899495 | O36: -50.833365 | P36: -184.82507 | Q36: 2.899495 | S36: -50.833365 | U36: 91.528788 | V36: 116.69195 | W36: 929.62298 | X36: 3.093013
A37: Sciaenidae | B37: 3.76 | C37: 575.43994 | D37: Small demersal fish | Medium sciaenids | E37: 100.34153 | F37: 126.35074 | G37: 118.51211 | H37: 417.53529 | I37: 1690.3387 | J37: 1690.9709 | K37: 1200.4953 | L37: 2732.0026 | M37: 2732.0026 | N37: 2732.0026 | O37: -202.34539 | P37: -478.44373 | Q37: 2732.0026 | S37: -202.34539 | U37: 263.60779 | V37: 316.14094 | W37: 4796.7212 | X37: 3239.6345
A38: Gastropoda | B38: 3.06 | C38: 114.81536 | D38: Macrobenthos | E38: 100.34153 | F38: 10 | G38: 9.716344 | H38: 9.230527 | I38: 10.017358 | J38: 10.017358 | K38: 7.916667 | L38: 2.899495 | M38: 2.899495 | N38: 2.899495 | O38: -50.833365 | P38: -184.82507 | Q38: 2.899495 | S38: -50.833365 | U38: 91.528788 | V38: 116.69195 | W38: 929.62298 | X38: 3.093013
A39: Penaeidae | B39: 3.31 | C39: 204.17379 | D39: Macrobenthos | E39: 100.34153 | F39: 10 | G39: 9.716344 | H39: 9.230527 | I39: 10.017358 | J39: 10.017358 | K39: 7.916667 | L39: 2.899495 | M39: 2.899495 | N39: 2.899495 | O39: -50.833365 | P39: -184.82507 | Q39: 2.899495 | S39: -50.833365 | U39: 91.528788 | V39: 116.69195 | W39: 929.62298 | X39: 3.093013
A40: Mustelus whitneyi | B40: 3.66 | C40: 457.08819 | D40: Benthic elasmobranchs | E40: 100.34153 | F40: 227.67211 | G40: 212.74056 | H40: 1454.4773 | I40: 5850.04 | J40: 5861.6113 | K40: 3861.1946 | L40: 7955.3551 | M40: 7955.3551 | N40: 7955.3551 | O40: -475.30423 | P40: -1034.6028 | Q40: 7955.3551 | S40: -475.30423 | U40: 558.60759 | V40: 673.42931 | W40: 8955.7697 | X40: 9372.1906
...

Sheet PPR by method
A1: Total PPR by method and year — every taxon summed, tonnes wet weight equivalent of primary production.
A2: All basal sources, including imports. The simple chain rows are unpartitioned references; model rows use this scope.
A3: Methods are not alternatives to be averaged. They rest on different assumptions and the spread between them is the result.
